Workbook

Sheet Inputs
B2: ASSUMPTIONS & INPUTS
B4: CORE FINANCIAL ASSUMPTIONS
B5: Tax Rate | C5: 0.22 | D5: Corporate tax rate (Indonesia)
B6: Discount Rate (Base Case) | C6: 0.1 | D6: Weighted Average Cost of Capital
B7: Inflation Rate | C7: 0.0406 | D7: Annual inflation rate for ESL analysis
B8: Salvage Value % | C8: 0.9 | D8: Expected salvage value as % of original cost
B10: DEPRECIATION USEFUL LIFE SCENARIOS (Months)
B11: Baseline Useful Life | C11: 480 | D11: 40 years (current accounting policy)
B12: Conservative Useful Life | C12: 480 | D12: 40 years (conservative scenario)
B13: Realistic Useful Life | C13: 600 | D13: 50 years (recommended scenario)
B14: Optimistic Useful Life | C14: 900 | D14: 75 years (optimistic scenario)
B16: SENSITIVITY ANALYSIS PARAMETERS
B17: Discount Rate - Low | C17: 0.08 | D17: Lower bound for sensitivity analysis
B18: Discount Rate - High | C18: 0.12 | D18: Upper bound for sensitivity analysis
B19: Tax Rate - Low | C19: 0.2 | D19: Lower tax rate scenario
B20: Tax Rate - High | C20: 0.25 | D20: Higher tax rate scenario
B22: UNIT CONVERSION CONSTANTS
B23: Billion Scaling Factor | C23: 1000000000 | D23: Convert IDR to billions (÷ by this)
B24: Months Per Year | C24: 12 | D24: Convert monthly to annual (× by this)
B26: MAINTENANCE COST ESCALATION PARAMETERS
B27: Base Annual Maintenance Cost (IDR) | C27: =AVERAGE('Maintenance History'!D4:D37) -> 43288824 | D27: Historical average maintenance cost
B28: Baseline Escalation Rate (0-40 yrs) | C28: 0.04 | D28: Standard inflation-driven maintenance growth
B29: Medium Escalation Rate (40-50 yrs) | C29: 0.08 | D29: Increased maintenance for aging assets
B30: High Escalation Rate (50+ yrs) | C30: 0.12 | D30: Significant maintenance for extended life

Sheet Depreciation_Scenario_Analysis
B2: ASSET LIFE EXTENSION ANALYSIS
B3: Depreciation Scenario Comparison: Building Assets
B5: ASSUMPTIONS
B6: Analysis Period: | C6: 2025 - 2034
B7: Asset Class: | C7: Buildings (Bangunan)
B8: Historical Depreciation Locked: | C8: Through December 31, 2024
B9: Tax Rate: | C9: {=Inputs!C5} -> 0.22
B11: SCENARIO DEFINITIONS
B12: Scenario | C12: Useful Life (Months) | D12: Useful Life (Years) | E12: Description | F12: Color Code
B13: Baseline (Current) | C13: {=Inputs!C11} -> 480 | D13: =C13/Inputs!$C$24 -> 40 | E13: Current accounting policy - 40 year life | F13: Black
B14: Conservative | C14: {=Inputs!C12} -> 480 | D14: =C14/Inputs!$C$24 -> 40 | E14: No change from current policy | F14: Orange
B15: Realistic (Recommended) | C15: {=Inputs!C13} -> 600 | D15: =C15/Inputs!$C$24 -> 50 | E15: Extended to 50 years - industry standard | F15: Yellow
B16: Optimistic | C16: {=Inputs!C14} -> 900 | D16: =C16/Inputs!$C$24 -> 75 | E16: Extended to 75 years - maximum estimate | F16: Green
B18: BUILDING ASSETS - DETAIL
B19: No. | C19: Asset Description | D19: Acquisition Date | E19: Original Cost (IDR) | F19: Current Life (Months) | G19: Accum Depre 2024 (IDR) | H19: NBV 2024 (IDR) | I19: Monthly Depre (Current) | J19: Months Used Through 2024
B20: 1 | C20: {='Asset Data Pullman'!D221} -> Pembangunan Hotel Pullman Mandalika | D20: {='Asset Data Pullman'!F221} -> 44569 | E20: {='Asset Data Pullman'!G221} -> 533254574462 | F20: {='Asset Data Pullman'!H221} -> 480 | G20: {='Asset Data Pullman'!P221} -> -32217463874 | H20: =IFERROR(E20+G20,0) -> 501037110588 | I20: {='Asset Data Pullman'!I221} -> 1110947030 | J20: =IFERROR(IF(I20=0,0,ABS(G20/I20)),0) -> 29
B21: 2 | C21: {='Asset Data Pullman'!D222} -> Pembebanan Pekerjaan Noise Treatment Cooling Tower, PO-2023000193, 293/KONTRAK/ITDC.05-PROC/X/2023, Hotel Pullman; PT.Indocell Prima, Tahap 1 (50%), Tahap 2 (45%), Tahap 3 (5%), Progress 100% (18-10-2023) [PULLMAN] | D21: {='Asset Data Pullman'!F222} -> 13/11/2023 | E21: {='Asset Data Pullman'!G222} -> 2032700816 | F21: {='Asset Data Pullman'!H222} -> 240 | G21: {='Asset Data Pullman'!P222} -> -118574214 | H21: =IFERROR(E21+G21,0) -> 1914126602 | I21: {='Asset Data Pullman'!I222} -> 8469587 | J21: =IFERROR(IF(I21=0,0,ABS(G21/I21)),0) -> 14
B22: 3 | C22: {='Asset Data Pullman'!D223} -> Pembebanan Pembangunan Pagar Pembatas Garden Villa Pullman Lombok Merunjani Mandalika Beach Resort; 281/kontrak/itdc.05-proc/VIII/2024; PO-2024000192; Mandalika | D22: {='Asset Data Pullman'!F223} -> 45638 | E22: {='Asset Data Pullman'!G223} -> 152295416 | F22: {='Asset Data Pullman'!H223} -> 360 | G22: {='Asset Data Pullman'!P223} -> -423043 | H22: =IFERROR(E22+G22,0) -> 151872373 | I22: {='Asset Data Pullman'!I223} -> 423043 | J22: =IFERROR(IF(I22=0,0,ABS(G22/I22)),0) -> 1
B23: 4 | C23: {='Asset Data Pullman'!D224} -> Aktivir ke aset tetap bangunan, Hotel Pullman Tranche A | D23: {='Asset Data Pullman'!F224} -> 31/12/2024 | E23: {='Asset Data Pullman'!G224} -> - | F23: {='Asset Data Pullman'!H224} -> 360 | G23: {='Asset Data Pullman'!P224} -> - | H23: =IFERROR(E23+G23,0) -> 0 | I23: {='Asset Data Pullman'!I224} -> - | J23: =IFERROR(IF(I23=0,0,ABS(G23/I23)),0) -> 0
B24: 5 | C24: {='Asset Data Pullman'!D225} -> Adjustment Reklasifikasi, Pekerjaan Noise Treatment Cooling Tower, PO-2023000193, 293/KONTRAK/ITDC.05-PROC/X/2023, Hotel Pullman; PT.Indocell Prima ex. 00204/MEM-HO/11/23, 00264/MEM-HO/11/23, UM, 20% | D24: {='Asset Data Pullman'!F225} -> 13/11/2023 | E24: {='Asset Data Pullman'!G225} -> 1397481811 | F24: {='Asset Data Pullman'!H225} -> 240 | G24: {='Asset Data Pullman'!P225} -> -81519772 | H24: =IFERROR(E24+G24,0) -> 1315962039 | I24: {='Asset Data Pullman'!I225} -> 5822841 | J24: =IFERROR(IF(I24=0,0,ABS(G24/I24)),0) -> 14
B25: 6 | C25: {='Asset Data Pullman'!D226} -> Koreksi Audit 2024 - Aktivir Pekerjaan Hotel Pullman | D25: {='Asset Data Pullman'!F226} -> 24/12/2022 | E25: {='Asset Data Pullman'!G226} -> 10895403600 | F25: {='Asset Data Pullman'!H226} -> 360 | G25: {='Asset Data Pullman'!P226} -> -363180120 | H25: =IFERROR(E25+G25,0) -> 10532223480 | I25: {='Asset Data Pullman'!I226} -> 30265010 | J25: =IFERROR(IF(I25=0,0,ABS(G25/I25)),0) -> 12
B26: 7 | C26: {='Asset Data Pullman'!D227} -> Koreksi Audit 2024 - MMN - Pembangunan Directory Road Signage Hotel Pullman di 3 Titik | D26: {='Asset Data Pullman'!F227} -> 30/11/2022 | E26: {='Asset Data Pullman'!G227} -> 224875357 | F26: {='Asset Data Pullman'!H227} -> 240 | G26: {='Asset Data Pullman'!P227} -> -24361497 | H26: =IFERROR(E26+G26,0) -> 200513860 | I26: {='Asset Data Pullman'!I227} -> 936981 | J26: =IFERROR(IF(I26=0,0,ABS(G26/I26)),0) -> 25.99999
B27: 8 | C27: {='Asset Data Pullman'!D228} -> Koreksi Audit 2024 - MMN - Aktivir Pengecoran Post Satpam Pullman | D27: {='Asset Data Pullman'!F228} -> 30/11/2023 | E27: {='Asset Data Pullman'!G228} -> 34000000 | F27: {='Asset Data Pullman'!H228} -> 240 | G27: {='Asset Data Pullman'!P228} -> -1841667 | H27: =IFERROR(E27+G27,0) -> 32158333 | I27: {='Asset Data Pullman'!I228} -> 141667 | J27: =IFERROR(IF(I27=0,0,ABS(G27/I27)),0) -> 12.999972
B28: 9 | C28: {='Asset Data Pullman'!D229} -> Koreksi Audit 2024 - MMN - Aktivir Pemasangan Ceilling Aluminium | D28: {='Asset Data Pullman'!F229} -> 30/07/2024 | E28: {='Asset Data Pullman'!G229} -> 184940000 | F28: {='Asset Data Pullman'!H229} -> 240 | G28: {='Asset Data Pullman'!P229} -> -4623500 | H28: =IFERROR(E28+G28,0) -> 180316500 | I28: {='Asset Data Pullman'!I229} -> 770583 | J28: =IFERROR(IF(I28=0,0,ABS(G28/I28)),0) -> 6.0000026
B29: 10 | C29: {='Asset Data Pullman'!D230} -> Noise Treatment Cooling Tower, PO-2023000193, 070125001664524771, Pekerjaan Noise Treatment Cooling Tower Pullman Lombok Merujani Mandalika Beach Resort No.293/KONTRAK/ITDC.05-PROC/X/2023, Tahap Retensi 5%, PT INDOCELL PRIMA, PO-2023000193, PULLMAN [A], 12-Jun-2025 | D29: {='Asset Data Pullman'!F230} -> 45997 | E29: {='Asset Data Pullman'!G230} -> 127043801 | F29: {='Asset Data Pullman'!H230} -> 240 | G29: {='Asset Data Pullman'!P230} -> - | H29: =IFERROR(E29+G29,0) -> 0 | I29: {='Asset Data Pullman'!I230} -> 529349 | J29: =IFERROR(IF(I29=0,0,ABS(G29/I29)),0) -> 0
B30: TOTAL | E30: =SUM(E20:E29) -> 548303315263 | G30: =SUM(G20:G29) -> -32811987687 | H30: =SUM(H20:H29) -> 515364283775 | I30: =SUM(I20:I29) -> 1158306091
B32: SCENARIO PROJECTIONS - REMAINING USEFUL LIFE & DEPRECIATION RATES
B33: Asset | C33: Baseline (480mo) | D33: 0 | E33: 0 | F33: Realistic (600mo) | G33: 0 | H33: 0 | I33: Optimistic (900mo) | J33: 0 | K33: 0
B34: 0 | C34: Remaining (mo) | D34: New Monthly | E34: Annual 2025 | F34: Remaining (mo) | G34: New Monthly | H34: Annual 2025 | I34: Remaining (mo) | J34: New Monthly | K34: Annual 2025
B35: {=B20} -> 1 | C35: =F20-J20 -> 451 | D35: {=I20} -> 1110947030 | E35: =D35*12 -> 13331364360 | F35: =$C$15-J20 -> 571 | G35: =IF(F35<=0,0,H20/F35) -> 8.7747305e+08 | H35: =G35*12 -> 1.0529677e+10 | I35: =$C$16-J20 -> 871 | J35: =IF(I35<=0,0,H20/I35) -> 5.7524353e+08 | K35: =J35*12 -> 6.9029223e+09
B36: {=B21} -> 2 | C36: =F21-J21 -> 226 | D36: {=I21} -> 8469587 | E36: =D36*12 -> 101635044 | F36: =$C$15-J21 -> 586 | G36: =IF(F36<=0,0,H21/F36) -> 3266427.6 | H36: =G36*12 -> 39197132 | I36: =$C$16-J21 -> 886 | J36: =IF(I36<=0,0,H21/I36) -> 2160413.8 | K36: =J36*12 -> 25924965
B37: {=B22} -> 3 | C37: =F22-J22 -> 359 | D37: {=I22} -> 423043 | E37: =D37*12 -> 5076516 | F37: =$C$15-J22 -> 599 | G37: =IF(F37<=0,0,H22/F37) -> 253543.19 | H37: =G37*12 -> 3042518.3 | I37: =$C$16-J22 -> 899 | J37: =IF(I37<=0,0,H22/I37) -> 168934.79 | K37: =J37*12 -> 2027217.4
B38: {=B23} -> 4 | C38: =F23-J23 -> 360 | D38: {=I23} -> - | E38: =IFERROR(D38*12,0) -> 0 | F38: =$C$15-J23 -> 600 | G38: =IF(F38<=0,0,H23/F38) -> 0 | H38: =G38*12 -> 0 | I38: =$C$16-J23 -> 900 | J38: =IF(I38<=0,0,H23/I38) -> 0 | K38: =J38*12 -> 0
B39: {=B24} -> 5 | C39: =F24-J24 -> 226 | D39: {=I24} -> 5822841 | E39: =D39*12 -> 69874092 | F39: =$C$15-J24 -> 586 | G39: =IF(F39<=0,0,H24/F39) -> 2245669 | H39: =G39*12 -> 26948028 | I39: =$C$16-J24 -> 886 | J39: =IF(I39<=0,0,H24/I39) -> 1485284.5 | K39: =J39*12 -> 17823414
B40: {=B25} -> 6 | C40: =F25-J25 -> 348 | D40: {=I25} -> 30265010 | E40: =D40*12 -> 363180120 | F40: =$C$15-J25 -> 588 | G40: =IF(F40<=0,0,H25/F40) -> 17911945 | H40: =G40*12 -> 2.1494334e+08 | I40: =$C$16-J25 -> 888 | J40: =IF(I40<=0,0,H25/I40) -> 11860612 | K40: =J40*12 -> 1.4232734e+08
B41: {=B26} -> 7 | C41: =F26-J26 -> 214.00001 | D41: {=I26} -> 936981 | E41: =D41*12 -> 11243772 | F41: =$C$15-J26 -> 574.00001 | G41: =IF(F41<=0,0,H26/F41) -> 349327.28 | H41: =G41*12 -> 4191927.3 | I41: =$C$16-J26 -> 874.00001 | J41: =IF(I41<=0,0,H26/I41) -> 229420.89 | K41: =J41*12 -> 2753050.7
B42: {=B27} -> 8 | C42: =F27-J27 -> 227.00003 | D42: {=I27} -> 141667 | E42: =D42*12 -> 1700004 | F42: =$C$15-J27 -> 587.00003 | G42: =IF(F42<=0,0,H27/F42) -> 54784.21 | H42: =G42*12 -> 657410.52 | I42: =$C$16-J27 -> 887.00003 | J42: =IF(I42<=0,0,H27/I42) -> 36255.166 | K42: =J42*12 -> 435061.99
B43: {=B28} -> 9 | C43: =F28-J28 -> 234 | D43: {=I28} -> 770583 | E43: =D43*12 -> 9246996 | F43: =$C$15-J28 -> 594 | G43: =IF(F43<=0,0,H28/F43) -> 303563.13 | H43: =G43*12 -> 3642757.6 | I43: =$C$16-J28 -> 894 | J43: =IF(I43<=0,0,H28/I43) -> 201696.31 | K43: =J43*12 -> 2420355.7
B44: {=B29} -> 10 | C44: =F29-J29 -> 240 | D44: {=I29} -> 529349 | E44: =D44*12 -> 6352188 | F44: =$C$15-J29 -> 600 | G44: =IF(F44<=0,0,H29/F44) -> 0 | H44: =G44*12 -> 0 | I44: =$C$16-J29 -> 900 | J44: =IF(I44<=0,0,H29/I44) -> 0 | K44: =J44*12 -> 0
B45: TOTAL | E45: =SUM(E35:E44) -> 13899673092 | H45: =SUM(H35:H44) -> 1.08223e+10 | K45: =SUM(K35:K44) -> 7.0966337e+09
...

Sheet Financial_Impact_Dashboard
B2: FINANCIAL IMPACT DASHBOARD
B3: Asset Life Extension - 10 Year P&L Impact Analysis
B5: Key Assumptions:
B6: Tax Rate: | C6: {=Inputs!$C$5} -> 0.22
B7: Total Building Assets (IDR): | C7: {=Depreciation_Scenario_Analysis!E30} -> 548303315263
B8: NBV at 2024 (IDR): | C8: {=Depreciation_Scenario_Analysis!H30} -> 515364283775
C9: {=Inputs!C5} -> 0.22
B10: ANNUAL DEPRECIATION EXPENSE BY SCENARIO (IDR Billions)
B11: Year | C11: 2025 | D11: 2026 | E11: 2027 | F11: 2028 | G11: 2029 | H11: 2030 | I11: 2031 | J11: 2032 | K11: 2033 | L11: 2034 | M11: Total | N11: Average
B12: Baseline (Current 40yr) | C12: =Depreciation_Scenario_Analysis!C49/Inputs!$C$23 -> 13.899673 | D12: =Depreciation_Scenario_Analysis!D49/Inputs!$C$23 -> 13.899673 | E12: =Depreciation_Scenario_Analysis!E49/Inputs!$C$23 -> 13.899673 | F12: =Depreciation_Scenario_Analysis!F49/Inputs!$C$23 -> 13.899673 | G12: =Depreciation_Scenario_Analysis!G49/Inputs!$C$23 -> 13.899673 | H12: =Depreciation_Scenario_Analysis!H49/Inputs!$C$23 -> 13.899673 | I12: =Depreciation_Scenario_Analysis!I49/Inputs!$C$23 -> 13.899673 | J12: =Depreciation_Scenario_Analysis!J49/Inputs!$C$23 -> 13.899673 | ... L12: =Depreciation_Scenario_Analysis!L49/Inputs!$C$23 -> 13.899673 | M12: =SUM(C12:L12) -> 138.99673 | N12: =AVERAGE(C12:L12) -> 13.899673
B13: Realistic (50yr) | C13: =Depreciation_Scenario_Analysis!C50/1000000000 -> 10.8223 | D13: =Depreciation_Scenario_Analysis!D50/Inputs!$C$23 -> 10.8223 | E13: =Depreciation_Scenario_Analysis!E50/Inputs!$C$23 -> 10.8223 | F13: =Depreciation_Scenario_Analysis!F50/Inputs!$C$23 -> 10.8223 | G13: =Depreciation_Scenario_Analysis!G50/Inputs!$C$23 -> 10.8223 | H13: =Depreciation_Scenario_Analysis!H50/Inputs!$C$23 -> 10.8223 | I13: =Depreciation_Scenario_Analysis!I50/Inputs!$C$23 -> 10.8223 | J13: =Depreciation_Scenario_Analysis!J50/Inputs!$C$23 -> 10.8223 | K13: =Depreciation_Scenario_Analysis!K50/Inputs!$C$23 -> 10.8223 | L13: =Depreciation_Scenario_Analysis!L50/Inputs!$C$23 -> 10.8223 | M13: =SUM(C13:L13) -> 108.223 | N13: =AVERAGE(C13:L13) -> 10.8223
B14: Optimistic (75yr) | C14: =Depreciation_Scenario_Analysis!C51/1000000000 -> 7.0966337 | D14: =Depreciation_Scenario_Analysis!D51/Inputs!$C$23 -> 7.0966337 | E14: =Depreciation_Scenario_Analysis!E51/Inputs!$C$23 -> 7.0966337 | F14: =Depreciation_Scenario_Analysis!F51/Inputs!$C$23 -> 7.0966337 | G14: =Depreciation_Scenario_Analysis!G51/Inputs!$C$23 -> 7.0966337 | H14: =Depreciation_Scenario_Analysis!H51/Inputs!$C$23 -> 7.0966337 | I14: =Depreciation_Scenario_Analysis!I51/Inputs!$C$23 -> 7.0966337 | J14: =Depreciation_Scenario_Analysis!J51/Inputs!$C$23 -> 7.0966337 | K14: =Depreciation_Scenario_Analysis!K51/Inputs!$C$23 -> 7.0966337 | L14: =Depreciation_Scenario_Analysis!L51/Inputs!$C$23 -> 7.0966337 | M14: =SUM(C14:L14) -> 70.966337 | N14: =AVERAGE(C14:L14) -> 7.0966337
B16: ANNUAL DEPRECIATION SAVINGS (IDR Billions)
B17: Year | C17: 2025 | D17: 2026 | E17: 2027 | F17: 2028 | G17: 2029 | H17: 2030 | I17: 2031 | J17: 2032 | K17: 2033 | L17: 2034 | M17: Total | N17: Average
B18: Realistic Scenario | C18: =C12-C13 -> 3.0773734 | D18: =D12-D13 -> 3.0773734 | E18: =E12-E13 -> 3.0773734 | F18: =F12-F13 -> 3.0773734 | G18: =G12-G13 -> 3.0773734 | H18: =H12-H13 -> 3.0773734 | I18: =I12-I13 -> 3.0773734 | J18: =J12-J13 -> 3.0773734 | ... L18: =L12-L13 -> 3.0773734 | M18: =SUM(C18:L18) -> 30.773734 | N18: =AVERAGE(C18:L18) -> 3.0773734
B19: Optimistic Scenario | C19: =C12-C14 -> 6.8030394 | D19: =D12-D14 -> 6.8030394 | E19: =E12-E14 -> 6.8030394 | F19: =F12-F14 -> 6.8030394 | G19: =G12-G14 -> 6.8030394 | H19: =H12-H14 -> 6.8030394 | I19: =I12-I14 -> 6.8030394 | J19: =J12-J14 -> 6.8030394 | ... L19: =L12-L14 -> 6.8030394 | M19: =SUM(C19:L19) -> 68.030394 | N19: =AVERAGE(C19:L19) -> 6.8030394
B21: EBITDA IMPACT (IDR Billions)
B22: Year | C22: 2025 | D22: 2026 | E22: 2027 | F22: 2028 | G22: 2029 | H22: 2030 | I22: 2031 | J22: 2032 | K22: 2033 | L22: 2034 | M22: Total | N22: Average
B23: Realistic - EBITDA Improvement | C23: {=C18} -> 3.0773734 | D23: {=D18} -> 3.0773734 | E23: {=E18} -> 3.0773734 | F23: {=F18} -> 3.0773734 | G23: {=G18} -> 3.0773734 | H23: {=H18} -> 3.0773734 | I23: {=I18} -> 3.0773734 | J23: {=J18} -> 3.0773734 | ... L23: {=L18} -> 3.0773734 | M23: =SUM(C23:L23) -> 30.773734 | N23: =AVERAGE(C23:L23) -> 3.0773734
B24: Optimistic - EBITDA Improvement | C24: {=C19} -> 6.8030394 | D24: {=D19} -> 6.8030394 | E24: {=E19} -> 6.8030394 | F24: {=F19} -> 6.8030394 | G24: {=G19} -> 6.8030394 | H24: {=H19} -> 6.8030394 | I24: {=I19} -> 6.8030394 | J24: {=J19} -> 6.8030394 | ... L24: {=L19} -> 6.8030394 | M24: =SUM(C24:L24) -> 68.030394 | N24: =AVERAGE(C24:L24) -> 6.8030394
B26: NET INCOME IMPACT (After Tax @ 22%) (IDR Billions)
B27: Year | C27: 2025 | D27: 2026 | E27: 2027 | F27: 2028 | G27: 2029 | H27: 2030 | I27: 2031 | J27: 2032 | K27: 2033 | L27: 2034 | M27: Total | N27: Average
B28: Realistic - Net Income Improvement | C28: =C18*(1-$C$6) -> 2.4003513 | D28: =D18*(1-$C$6) -> 2.4003513 | E28: =E18*(1-$C$6) -> 2.4003513 | F28: =F18*(1-$C$6) -> 2.4003513 | G28: =G18*(1-$C$6) -> 2.4003513 | H28: =H18*(1-$C$6) -> 2.4003513 | I28: =I18*(1-$C$6) -> 2.4003513 | J28: =J18*(1-$C$6) -> 2.4003513 | ... L28: =L18*(1-$C$6) -> 2.4003513 | M28: =SUM(C28:L28) -> 24.003513 | N28: =AVERAGE(C28:L28) -> 2.4003513
B29: Optimistic - Net Income Improvement | C29: =C19*(1-$C$6) -> 5.3063707 | D29: =D19*(1-$C$6) -> 5.3063707 | E29: =E19*(1-$C$6) -> 5.3063707 | F29: =F19*(1-$C$6) -> 5.3063707 | G29: =G19*(1-$C$6) -> 5.3063707 | H29: =H19*(1-$C$6) -> 5.3063707 | I29: =I19*(1-$C$6) -> 5.3063707 | J29: =J19*(1-$C$6) -> 5.3063707 | ... L29: =L19*(1-$C$6) -> 5.3063707 | M29: =SUM(C29:L29) -> 53.063707 | N29: =AVERAGE(C29:L29) -> 5.3063707
B31: CUMULATIVE SAVINGS (IDR Billions)
B32: Year | C32: 2025 | D32: 2026 | E32: 2027 | F32: 2028 | G32: 2029 | H32: 2030 | I32: 2031 | J32: 2032 | K32: 2033 | L32: 2034
B33: Realistic - Cumulative Depre Savings | C33: {=C18} -> 3.0773734 | D33: =C33+D18 -> 6.1547468 | E33: =D33+E18 -> 9.2321202 | F33: =E33+F18 -> 12.309494 | G33: =F33+G18 -> 15.386867 | H33: =G33+H18 -> 18.46424 | I33: =H33+I18 -> 21.541614 | J33: =I33+J18 -> 24.618987 | K33: =J33+K18 -> 27.696361 | L33: =K33+L18 -> 30.773734
B34: Optimistic - Cumulative Depre Savings | C34: {=C19} -> 6.8030394 | D34: =C34+D19 -> 13.606079 | E34: =D34+E19 -> 20.409118 | F34: =E34+F19 -> 27.212158 | G34: =F34+G19 -> 34.015197 | H34: =G34+H19 -> 40.818236 | I34: =H34+I19 -> 47.621276 | J34: =I34+J19 -> 54.424315 | K34: =J34+K19 -> 61.227354 | L34: =K34+L19 -> 68.030394
B36: KEY METRICS SUMMARY - 10 YEAR PERIOD
B37: Metric | C37: Baseline | D37: Realistic (50yr) | E37: Optimistic (75yr) | F37: Realistic Savings | G37: Optimistic Savings
B38: Total Depreciation (IDR Billions) | C38: {=M12} -> 138.99673 | D38: {=M13} -> 108.223 | E38: {=M14} -> 70.966337 | F38: {=M18} -> 30.773734 | G38: {=M19} -> 68.030394
B39: Average Annual Depreciation | C39: {=N12} -> 13.899673 | D39: {=N13} -> 10.8223 | E39: {=N14} -> 7.0966337 | F39: {=N18} -> 3.0773734 | G39: {=N19} -> 6.8030394
B40: Total EBITDA Improvement | C40: N/A | D40: {=M23} -> 30.773734 | E40: {=M24} -> 68.030394 | F40: {=D40} -> 30.773734 | G40: {=E40} -> 68.030394
C41: N/A | D41: {=M28} -> 24.003513 | E41: {=M29} -> 53.063707 | F41: {=D41} -> 24.003513 | G41: {=E41} -> 53.063707
C42: 0 | D42: =F38/C38 -> 0.22139898 | E42: =G38/C38 -> 0.4894388 | F42: {=D42} -> 0.22139898 | G42: {=E42} -> 0.4894388
B44: RECOMMENDED SCENARIO
B45: Realistic Scenario (50 Year Life Extension)
B46: Key Benefits:
B47: • Annual Depreciation Savings: | C47: {=N18} -> 3.0773734 | D47: IDR Billions/year
B48: • 10-Year EBITDA Improvement: | C48: {=M23} -> 30.773734 | D48: IDR Billions
...

Sheet Balance_Sheet_Impact
B2: BALANCE SHEET IMPACT ANALYSIS
B3: Net Book Value Projections & Fixed Assets Impact
B5: Building Assets - Net Book Value at Dec 31, 2024: | C5: {=Depreciation_Scenario_Analysis!H30} -> 515364283775
C6: {=Inputs!$C$5} -> 0.22
B7: NET BOOK VALUE PROJECTION - BUILDING ASSETS (IDR Billions)
B8: Year End | C8: 2024 | D8: 2025 | E8: 2026 | F8: 2027 | G8: 2028 | H8: 2029 | I8: 2030 | J8: 2031 | K8: 2032 | L8: 2033 | M8: 2034
B9: Baseline (Current 40yr) | C9: =C5/Inputs!$C$23 -> 515.36428 | D9: =C9-Financial_Impact_Dashboard!D12 -> 501.46461 | E9: =D9-Financial_Impact_Dashboard!E12 -> 487.56494 | F9: =E9-Financial_Impact_Dashboard!F12 -> 473.66526 | G9: =F9-Financial_Impact_Dashboard!G12 -> 459.76559 | H9: =G9-Financial_Impact_Dashboard!H12 -> 445.86592 | I9: =H9-Financial_Impact_Dashboard!I12 -> 431.96625 | J9: =I9-Financial_Impact_Dashboard!J12 -> 418.06657 | K9: =J9-Financial_Impact_Dashboard!K12 -> 404.1669 | ... M9: =L9-Financial_Impact_Dashboard!M12 -> 251.2705
B10: Realistic (50yr) | C10: =C5/Inputs!$C$23 -> 515.36428 | D10: =C10-Financial_Impact_Dashboard!D13 -> 504.54198 | E10: =D10-Financial_Impact_Dashboard!E13 -> 493.71968 | F10: =E10-Financial_Impact_Dashboard!F13 -> 482.89738 | G10: =F10-Financial_Impact_Dashboard!G13 -> 472.07509 | H10: =G10-Financial_Impact_Dashboard!H13 -> 461.25279 | I10: =H10-Financial_Impact_Dashboard!I13 -> 450.43049 | J10: =I10-Financial_Impact_Dashboard!J13 -> 439.60819 | K10: =J10-Financial_Impact_Dashboard!K13 -> 428.78589 | ... M10: =L10-Financial_Impact_Dashboard!M13 -> 309.74059
B11: Optimistic (75yr) | C11: =C5/Inputs!$C$23 -> 515.36428 | D11: =C11-Financial_Impact_Dashboard!D14 -> 508.26765 | E11: =D11-Financial_Impact_Dashboard!E14 -> 501.17102 | F11: =E11-Financial_Impact_Dashboard!F14 -> 494.07438 | G11: =F11-Financial_Impact_Dashboard!G14 -> 486.97775 | H11: =G11-Financial_Impact_Dashboard!H14 -> 479.88112 | I11: =H11-Financial_Impact_Dashboard!I14 -> 472.78448 | J11: =I11-Financial_Impact_Dashboard!J14 -> 465.68785 | K11: =J11-Financial_Impact_Dashboard!K14 -> 458.59121 | ... M11: =L11-Financial_Impact_Dashboard!M14 -> 380.52824
B13: NBV DIFFERENCE VS. BASELINE (IDR Billions)
B14: Year End | C14: 2024 | D14: 2025 | E14: 2026 | F14: 2027 | G14: 2028 | H14: 2029 | I14: 2030 | J14: 2031 | K14: 2032 | L14: 2033 | M14: 2034
B15: Realistic Scenario (Higher NBV) | C15: 0 | D15: =D10-D9 -> 3.0773734 | E15: =E10-E9 -> 6.1547468 | F15: =F10-F9 -> 9.2321202 | G15: =G10-G9 -> 12.309494 | H15: =H10-H9 -> 15.386867 | I15: =I10-I9 -> 18.46424 | J15: =J10-J9 -> 21.541614 | K15: =K10-K9 -> 24.618987 | ... M15: =M10-M9 -> 58.470095
B16: Optimistic Scenario (Higher NBV) | C16: 0 | D16: =D11-D9 -> 6.8030394 | E16: =E11-E9 -> 13.606079 | F16: =F11-F9 -> 20.409118 | G16: =G11-G9 -> 27.212158 | H16: =H11-H9 -> 34.015197 | I16: =I11-I9 -> 40.818236 | J16: =J11-J9 -> 47.621276 | K16: =K11-K9 -> 54.424315 | ... M16: =M11-M9 -> 129.25775
B18: IMPACT ON TOTAL FIXED ASSETS
B19: Total Fixed Assets at Dec 31, 2024: | C19: {=Financial_Statements!J106} -> 6307801908803
B20: Building Assets NBV: | C20: {=C5} -> 515364283775
B21: Other Assets NBV: | C21: =C19-C20 -> 5792437625028
B23: PROJECTED TOTAL FIXED ASSETS (IDR Billions)
B24: Scenario | D24: 2025 | E24: 2026 | F24: 2027 | G24: 2028 | H24: 2029 | I24: 2030 | J24: 2031 | K24: 2032 | L24: 2033 | M24: 2034
B25: Baseline (Current 40yr) | D25: =($C$21/Inputs!$C$23)+D9 -> 6293.9022 | E25: =($C$21/Inputs!$C$23)+E9 -> 6280.0026 | F25: =($C$21/Inputs!$C$23)+F9 -> 6266.1029 | G25: =($C$21/Inputs!$C$23)+G9 -> 6252.2032 | H25: =($C$21/Inputs!$C$23)+H9 -> 6238.3035 | I25: =($C$21/Inputs!$C$23)+I9 -> 6224.4039 | J25: =($C$21/Inputs!$C$23)+J9 -> 6210.5042 | K25: =($C$21/Inputs!$C$23)+K9 -> 6196.6045 | ... M25: =($C$21/Inputs!$C$23)+M9 -> 6043.7081
B26: Realistic (50yr) | D26: =($C$21/Inputs!$C$23)+D10 -> 6296.9796 | E26: =($C$21/Inputs!$C$23)+E10 -> 6286.1573 | F26: =($C$21/Inputs!$C$23)+F10 -> 6275.335 | G26: =($C$21/Inputs!$C$23)+G10 -> 6264.5127 | H26: =($C$21/Inputs!$C$23)+H10 -> 6253.6904 | I26: =($C$21/Inputs!$C$23)+I10 -> 6242.8681 | J26: =($C$21/Inputs!$C$23)+J10 -> 6232.0458 | K26: =($C$21/Inputs!$C$23)+K10 -> 6221.2235 | ... M26: =($C$21/Inputs!$C$23)+M10 -> 6102.1782
B27: Optimistic (75yr) | D27: =($C$21/Inputs!$C$23)+D11 -> 6300.7053 | E27: =($C$21/Inputs!$C$23)+E11 -> 6293.6086 | F27: =($C$21/Inputs!$C$23)+F11 -> 6286.512 | G27: =($C$21/Inputs!$C$23)+G11 -> 6279.4154 | H27: =($C$21/Inputs!$C$23)+H11 -> 6272.3187 | I27: =($C$21/Inputs!$C$23)+I11 -> 6265.2221 | J27: =-($C$21/Inputs!$C$23)+J11 -> -5326.7498 | K27: =($C$21/Inputs!$C$23)+K11 -> 6251.0288 | L27: =($C$21/Inputs!$C$23)+L11 -> 6243.9322 | M27: =($C$21/Inputs!$C$23)+M11 -> 6172.9659
B29: BALANCE SHEET SUMMARY - END OF 2034
B30: Metric | C30: Baseline | D30: Realistic (50yr) | E30: Optimistic (75yr) | F30: Realistic Impact | G30: Optimistic Impact
B31: Building Assets NBV (IDR Billions) | C31: {=M9} -> 251.2705 | D31: {=M10} -> 309.74059 | E31: {=M11} -> 380.52824 | F31: =D31-C31 -> 58.470095 | G31: =E31-C31 -> 129.25775
B32: Total Fixed Assets (IDR Billions) | C32: {=M25} -> 6043.7081 | D32: {=M26} -> 6102.1782 | E32: {=M27} -> 6172.9659 | F32: =D32-C32 -> 58.470095 | G32: =E32-C32 -> 129.25775
B33: % Building Assets of Total FA | C33: =C31/C32 -> 0.041575551 | D33: =D31/D32 -> 0.050759021 | E33: =E31/E32 -> 0.061644314 | F33: =D33-C33 -> 0.0091834696 | G33: =E33-C33 -> 0.020068763
B35: KEY OBSERVATIONS
B36: Impact of Asset Life Extension:
B37: 1. Higher Net Book Value: | C37: Extending asset life increases NBV by reducing annual depreciation
B38: 2. Stronger Balance Sheet: | C38: By 2034, Realistic scenario shows IDR 58.5 B higher NBV
B39: 3. Improved Asset Base: | C39: Higher asset values support better asset turnover ratios and financing capacity
B40: 4. No Cash Impact: | C40: This is an accounting change only - no actual cash expenditure required

Sheet Sensitivity_Analysis
B2: SENSITIVITY ANALYSIS
B3: Testing Key Assumptions & Variables
B5: KEY VARIABLES
B6: Variable | C6: Base Case | D6: Low | E6: High | F6: Current Value
B7: Useful Life - Realistic (months) | C7: 600 | D7: 540 | E7: 660 | F7: =Inputs!C13 -> 600
B8: Useful Life - Optimistic (months) | C8: 900 | D8: 750 | E8: 1050 | F8: {=Inputs!C14} -> 900
B9: Tax Rate | C9: {=Inputs!$C$5} -> 0.22 | D9: {=Inputs!C19} -> 0.2 | E9: =Inputs!C20 -> 0.25 | F9: {=Inputs!C5} -> 0.22
B10: Discount Rate (WACC) | C10: {=Inputs!C6} -> 0.1 | D10: {=Inputs!C17} -> 0.08 | E10: {=Inputs!C18} -> 0.12 | F10: {=Inputs!C6} -> 0.1
B12: NPV ANALYSIS - TAX SHIELD FROM DEPRECIATION SAVINGS
B13: Note: Lower depreciation reduces tax deductions, increasing tax payments
B14: Scenario | C14: 10-Year Depre Savings | D14: Tax Impact (22%) | E14: After-Tax Benefit | F14: NPV @ 10% | G14: NPV @ 8% | H14: NPV @ 12%
B15: Realistic (50yr) | C15: {=Financial_Impact_Dashboard!M18} -> 30.773734 | D15: =-C15*$F$9 -> -6.7702215 | E15: =C15+D15 -> 24.003513 | F15: =E15/$C$10*Inputs!C23*((1-(1+$C$10)^-10)/$C$10) -> 1.4749119e+12 | G15: =E15/$D$10*Inputs!C23*((1-(1+$D$10)^-10)/$D$10) -> 2.013319e+12 | H15: =E15/$E$10*Inputs!C23*((1-(1+$E$10)^-10)/$E$10) -> 1.13021e+12
B16: Optimistic (75yr) | C16: {=Financial_Impact_Dashboard!M19} -> 68.030394 | D16: =-C16*$F$9 -> -14.966687 | E16: =C16+D16 -> 53.063707 | F16: =E16/$C$10*Inputs!C23*((1-(1+$C$10)^-10)/$C$10) -> 3.2605351e+12 | G16: =E16/$D$10*Inputs!C23*((1-(1+$D$10)^-10)/$D$10) -> 4.4507724e+12 | H16: =E16/$E$10*Inputs!C23*((1-(1+$E$10)^-10)/$E$10) -> 2.4985148e+12
B18: SENSITIVITY TORNADO DIAGRAM - REALISTIC SCENARIO NPV
B19: Variable Tested | C19: Low Case NPV | D19: Base Case NPV | E19: High Case NPV | F19: Range
B20: Useful Life (540-660 months) | C20: Manual calc needed | D20: {=F15} -> 1.4749119e+12 | E20: Manual calc needed | F20: TBD
B21: Tax Rate (20%-25%) | C21: =(Financial_Impact_Dashboard!M18*(1-$D$9))/$C$10*1000000000*((1-(1+$C$10)^-10)/$C$10) -> 1.5127302e+12 | D21: {=F15} -> 1.4749119e+12 | E21: =(Financial_Impact_Dashboard!M18*(1-$E$9))/$C$10*Inputs!C23*((1-(1+$C$10)^-10)/$C$10) -> 1.4181846e+12 | F21: =E21-C21 -> -9.4545637e+10
B22: Discount Rate (8%-12%) | C22: {=G15} -> 2.013319e+12 | D22: {=F15} -> 1.4749119e+12 | E22: {=H15} -> 1.13021e+12 | F22: =C22-E22 -> 8.8310904e+11
B24: BREAKEVEN ANALYSIS
B25: Analysis: What minimum life extension creates material value?
B26: Materiality Threshold | C26: Target Annual Savings | D26: Required Life (est.)
B27: 1% of Total Depreciation | C27: =Financial_Impact_Dashboard!M12*0.01 -> 1.3899673 | D27: ~490 months (~41 years)
B28: 5% of Total Depreciation | C28: =Financial_Impact_Dashboard!M12*0.05 -> 6.9498365 | D28: ~520 months (~43 years)
B29: 10% of Total Depreciation | C29: =Financial_Impact_Dashboard!M12*0.1 -> 13.899673 | D29: ~540 months (~45 years)
B30: 20% (Realistic Scenario) | C30: {=Financial_Impact_Dashboard!M18} -> 30.773734 | D30: 600 months (50 years)
B32: KEY INSIGHTS
B33: 1. Most Sensitive Variable: | C33: Discount Rate has highest impact on NPV (+36% to -23% from base)
B34: 2. Tax Impact: | C34: 22% tax rate reduces gross savings by IDR 6.8B over 10 years (Realistic)
B35: 3. Breakeven Point: | C35: Material benefit achieved at ~45 year useful life (540 months)
B36: 4. Recommended Scenario: | C36: 50-year life provides 22.1% savings - strong business case
B37: 5. Conservative Approach: | C37: Even at 45 years (vs 40), still captures ~10% savings benefit
B39: SALVAGE VALUE SENSITIVITY ANALYSIS
B40: Impact of Different Salvage Value Assumptions on End-of-Life Economics
B42: Salvage Value Scenario | C42: 90% (Current) | D42: 70% (Conservative) | E42: 50% (Pessimistic) | F42: Range
B43: Original Building Cost (IDR B) | C43: =Depreciation_Scenario_Analysis!E30/Inputs!$C$23 -> 548.30332 | D43: {=C43} -> 548.30332 | E43: {=C43} -> 548.30332 | F43: N/A
B45: REALISTIC SCENARIO (50 Year Life)
B46: Expected Salvage Value (IDR B) | C46: =C43*0.9 -> 493.47298 | D46: =C43*0.7 -> 383.81232 | E46: =C43*0.5 -> 274.15166 | F46: =C46-E46 -> 219.32133
B47: Accumulated Depreciation (IDR B) | C47: =C43-C46 -> 54.830332 | D47: =D43-D46 -> 164.49099 | E47: =E43-E46 -> 274.15166 | F47: =C47-E47 -> -219.32133
B48: NBV at End of Life (50 yrs) | C48: {=C46} -> 493.47298 | D48: {=D46} -> 383.81232 | E48: {=E46} -> 274.15166 | F48: =C48-E48 -> 219.32133
B49: Gain/(Loss) on Disposal | C49: =C46-C48 -> 0 | D49: =D46-D48 -> 0 | E49: =E46-E48 -> 0 | F49: =C49-E49 -> 0
...

Sheet Historical_Integration
B2: HISTORICAL INTEGRATION & BRIDGE ANALYSIS
B3: Linking Historical Financials to Projected Scenarios
B5: HISTORICAL DEPRECIATION & AMORTIZATION EXPENSE (IDR Billions)
B6: Description | C6: 2018 | D6: 2019 | E6: 2020 | F6: 2021 | G6: 2022 | H6: 2023 | I6: 2024 | J6: CAGR
B7: Total Depreciation & Amortization | C7: =Financial_Statements!D228/1000000000 -> 15.192402 | D7: =Financial_Statements!E228/1000000000 -> 22.266167 | E7: =Financial_Statements!F228/1000000000 -> 29.544553 | F7: {=Inputs!C13} -> 600 | G7: =Financial_Statements!H228/1000000000 -> 128.55382 | H7: =Financial_Statements!I228/1000000000 -> 35.377483 | I7: =Financial_Statements!J228/1000000000 -> 37.583294 | J7: =(I7/C7)^(1/6)-1 -> 0.16295095
F8: {=Inputs!C14} -> 900
B9: Year-over-Year Growth | C9: {=Inputs!$C$5} -> 0.22 | D9: {=Inputs!C19} -> 0.2 | E9: {=Inputs!C20} -> 0.25 | F9: {=Inputs!C5} -> 0.22 | G9: =(G7-F7)/F7 -> -0.78574363 | H9: =(H7-G7)/G7 -> -0.72480411 | I9: =(I7-H7)/H7 -> 0.062350704
C10: {=Inputs!C6} -> 0.1 | D10: {=Inputs!C17} -> 0.08 | E10: {=Inputs!C18} -> 0.12 | F10: {=Inputs!C6} -> 0.1
B11: BRIDGE: 2024 ACTUAL → 2025 PROJECTED SCENARIOS
B12: Component | C12: 2024 Actual | D12: 2025 Baseline | E12: 2025 Realistic | F12: 2025 Optimistic | G12: Realistic vs 2024 | H12: Optimistic vs 2024
B13: Building Assets Depreciation | C13: {=Financial_Impact_Dashboard!C12} -> 13.899673 | D13: {=Financial_Impact_Dashboard!D12} -> 13.899673 | E13: {=Financial_Impact_Dashboard!D13} -> 10.8223 | F13: {=Financial_Impact_Dashboard!D14} -> 7.0966337 | G13: =E13-C13 -> -3.0773734 | H13: =F13-C13 -> -6.8030394
B14: Other Assets Depreciation (est.) | C14: =(I7-C13) -> 23.683621 | D14: {=C14} -> 23.683621 | E14: {=C14} -> 23.683621 | F14: {=C14} -> 23.683621 | G14: 0 | H14: 0
B15: Total Depreciation & Amortization | C15: =C13+C14 -> 37.583294 | D15: =D13+D14 -> 37.583294 | E15: =E13+E14 -> 34.50592 | F15: =F13+F14 -> 30.780254 | G15: =E15-C15 -> -3.0773734 | H15: =F15-C15 -> -6.8030394
B17: VARIANCE ANALYSIS - 2025 vs 2024
B18: Metric | C18: Baseline Change | D18: Realistic Change | E18: Optimistic Change
B19: Absolute Change (IDR Billions) | C19: =D15-C15 -> 0 | D19: =E15-C15 -> -3.0773734 | E19: =F15-C15 -> -6.8030394
B20: % Change vs 2024 | C20: =C19/C15 -> 0 | D20: =D19/C15 -> -0.081881418 | E20: =E19/C15 -> -0.18101232
B22: KEY OBSERVATIONS
B23: 1. Historical Growth: | C23: ="Depreciation grew at "&TEXT(J7,"0.0%")&" CAGR from 2018-2024" -> Depreciation grew at 16.3% CAGR from 2018-2024
B24: 2. 2025 Baseline Projection: | C24: Would increase by 0.0 B (continuing current policy)
B25: 3. Realistic Scenario Impact: | C25: Reduces 2025 depreciation by 3.1 B vs 2024
B26: 4. Implementation: | C26: Policy change effective Jan 1, 2025 - no retroactive adjustment needed

Sheet Asset Data Pullman
A1: No. | B1: Kategori | C1: Sub Kategori | D1: Deskripsi Aset | E1: Lokasi | F1: Tgl Perolehan | G1: Nilai Perolehan | H1: Masa Manfaat | I1: Depre / Bulan | J1: Alokasi Masa Manfaat Per Tahun | P1: Akm. Depre s/d 2024 | Q1: Beban Depre s/d Juli 2025 | R1: Akm. Depre s/d Juli 2025 | S1: Nilai Sisa Buku Per Juli 2025
J2: 2021 | K2: 2022 | L2: 2023 | M2: 2024 | N2: 2025 | O2: 2026
A3: 1 | B3: Aset Tetap | C3: Perlengkapan | D3: Koreksi Audit 2024 - MMN Meja Komputer untuk Operasional | E3: Pullman - Mandalika | F3: 30/07/2021 | G3: 2550000 | H3: 48 | I3: 53125 | J3: 5 | K3: 12 | L3: 12 | M3: 12 | N3: 7 | O3: 0 | P3: -2178125 | Q3: -371875 | R3: -2550000 | S3: -
A4: 2 | B4: Aset Tetap | C4: Perlengkapan | D4: Koreksi Audit 2024 - MMN Standing Light Portable 2 Cabang 50 Watt, 10 Unit | E4: Pullman - Mandalika | F4: 44840 | G4: 14500000 | H4: 48 | I4: 302083 | K4: 7 | L4: 12 | M4: 12 | N4: 12 | O4: 5 | P4: -9364583 | Q4: -2114583 | R4: -11479167 | S4: 3020833
A5: 3 | B5: Aset Tetap | C5: Perlengkapan | D5: Koreksi Audit 2024 - MMN Gas Welding Set For Refrigeration Pipe, 2 Unit | E5: Pullman - Mandalika | F5: 44840 | G5: 3700000 | H5: 48 | I5: 77083 | K5: 7 | L5: 12 | M5: 12 | N5: 12 | O5: 5 | P5: -2389583 | Q5: -539583 | R5: -2929167 | S5: 770833
A6: 4 | B6: Aset Tetap | C6: Perlengkapan | D6: Koreksi Audit 2024 - MMN Welding PPR Pipe 75mm-11mm, 2 Unit | E6: Pullman - Mandalika | F6: 44840 | G6: 6600000 | H6: 48 | I6: 137500 | K6: 7 | L6: 12 | M6: 12 | N6: 12 | O6: 5 | P6: -4262500 | Q6: -962500 | R6: -5225000 | S6: 1375000
A7: 5 | B7: Aset Tetap | C7: Perlengkapan | D7: Koreksi Audit 2024 - MMN Spot Light Portable 50 Watt, 10 Unit | E7: Pullman - Mandalika | F7: 44840 | G7: 7500000 | H7: 48 | I7: 156250 | K7: 7 | L7: 12 | M7: 12 | N7: 12 | O7: 5 | P7: -4843750 | Q7: -1093750 | R7: -5937500 | S7: 1562500
A8: 6 | B8: Aset Tetap | C8: Perlengkapan | D8: Koreksi Audit 2024 - MMN Welding PPR Pipe 20mm-63mm, 2 Unit | E8: Pullman - Mandalika | F8: 44840 | G8: 1600000 | H8: 48 | I8: 33333 | K8: 7 | L8: 12 | M8: 12 | N8: 12 | O8: 5 | P8: -1033333 | Q8: -233333 | R8: -1266667 | S8: 333333
A9: 7 | B9: Aset Tetap | C9: Perlengkapan | D9: Koreksi Audit 2024 - MMN Pembelian Standing, Signage Stainless Steel A3 | E9: Pullman - Mandalika | F9: 44904 | G9: 10200000 | H9: 48 | I9: 212500 | K9: 4 | L9: 12 | M9: 12 | N9: 12 | O9: 8 | P9: -5950000 | Q9: -1487500 | R9: -7437500 | S9: 2762500
A10: 8 | B10: Aset Tetap | C10: Perlengkapan | D10: Koreksi Audit 2024 - MMN DP 50% Pembelian Pool Towel Trolley | E10: Pullman - Mandalika | F10: 14/09/2022 | G10: - | H10: 48 | I10: - | K10: 4 | L10: 12 | M10: 12 | N10: 12 | O10: 8 | P10: - | Q10: - | R10: - | S10: -
A11: 9 | B11: Aset Tetap | C11: Perlengkapan | D11: Koreksi Audit 2024 - MMN Executive Slim Director Chair Black High | E11: Pullman - Mandalika | F11: 22/09/2022 | G11: 7237000 | H11: 48 | I11: 150771 | K11: 4 | L11: 12 | M11: 12 | N11: 12 | O11: 8 | P11: -4221583 | Q11: -1055396 | R11: -5276979 | S11: 1960021
A12: 10 | B12: Aset Tetap | C12: Perlengkapan | D12: Koreksi Audit 2024 - MMN Roes 163 Visitor Chair Black | E12: Pullman - Mandalika | F12: 22/09/2022 | G12: 5112000 | H12: 48 | I12: 106500 | K12: 4 | L12: 12 | M12: 12 | N12: 12 | O12: 8 | P12: -2982000 | Q12: -745500 | R12: -3727500 | S12: 1384500
A13: 11 | B13: Aset Tetap | C13: Perlengkapan | D13: Koreksi Audit 2024 - MMN Monthana 7M Manager Desk 160 L (U/3) | E13: Pullman - Mandalika | F13: 22/09/2022 | G13: 5800600 | H13: 48 | I13: 120846 | K13: 4 | L13: 12 | M13: 12 | N13: 12 | O13: 8 | P13: -3383683 | Q13: -845921 | R13: -4229604 | S13: 1570996
A14: 12 | B14: Aset Tetap | C14: Perlengkapan | D14: Koreksi Audit 2024 - MMN Monthana Staff Desk 1206 (U/3) | E14: Pullman - Mandalika | F14: 22/09/2022 | G14: 10674000 | H14: 48 | I14: 222375 | K14: 4 | L14: 12 | M14: 12 | N14: 12 | O14: 8 | P14: -6226500 | Q14: -1556625 | R14: -7783125 | S14: 2890875
A15: 13 | B15: Aset Tetap | C15: Perlengkapan | D15: Koreksi Audit 2024 - MMN Pembelian 10 Unit Towel Basket Rattan in Darkbrown Color | E15: Pullman - Mandalika | F15: 30/09/2022 | G15: 16816500 | H15: 48 | I15: 350344 | K15: 4 | L15: 12 | M15: 12 | N15: 12 | O15: 8 | P15: -9809625 | Q15: -2452406 | R15: -12262031 | S15: 4554469
A16: 14 | B16: Aset Tetap | C16: Perlengkapan | D16: Koreksi Audit 2024 - MMN Pembelian 1 Unit Stand Sign Maintenance, Sistem Roda Plus Rem Pengunci Bawah (Material Stainless Holo Frame Acrylic) | E16: Pullman - Mandalika | F16: 30/09/2022 | G16: 2750000 | H16: 48 | I16: 57292 | K16: 4 | L16: 12 | M16: 12 | N16: 12 | O16: 8 | P16: -1604167 | Q16: -401042 | R16: -2005208 | S16: 744792
A17: 15 | B17: Aset Tetap | C17: Perlengkapan | D17: Koreksi Audit 2024 - MMN Indoor Plant Aer Restaurant (Plus Maintenance) | E17: Pullman - Mandalika | F17: 44691 | G17: 5000000 | H17: 48 | I17: 104167 | K17: 3 | L17: 12 | M17: 12 | N17: 12 | O17: 9 | P17: -2812500 | Q17: -729167 | R17: -3541667 | S17: 1458333
A18: 16 | B18: Aset Tetap | C18: Perlengkapan | D18: Koreksi Audit 2024 - MMN Orchit Standing Setting (Plus Maintenance) | E18: Pullman - Mandalika | F18: 44691 | G18: 11000000 | H18: 48 | I18: 229167 | K18: 3 | L18: 12 | M18: 12 | N18: 12 | O18: 9 | P18: -6187500 | Q18: -1604167 | R18: -7791667 | S18: 3208333
A19: 17 | B19: Aset Tetap | C19: Perlengkapan | D19: Koreksi Audit 2024 - MMN Pembelian 4 Unit Scale Digital Tanita KD.2000 5Kg | E19: Pullman - Mandalika | F19: 44752 | G19: 6280000 | H19: 48 | I19: 130833 | K19: 3 | L19: 12 | M19: 12 | N19: 12 | O19: 9 | P19: -3532500 | Q19: -915833 | R19: -4448333 | S19: 1831667
A20: 18 | B20: Aset Tetap | C20: Perlengkapan | D20: Koreksi Audit 2024 - MMN Pembelian Sliding Flat Glass Freezer | E20: Pullman - Mandalika | F20: 44752 | G20: 4200000 | H20: 48 | I20: 87500 | K20: 3 | L20: 12 | M20: 12 | N20: 12 | O20: 9 | P20: -2362500 | Q20: -612500 | R20: -2975000 | S20: 1225000
A21: 19 | B21: Aset Tetap | C21: Perlengkapan | D21: Koreksi Audit 2024 - MMN Pembelian Digital Platform Scale 150KG W/Tera | E21: Pullman - Mandalika | F21: 17/10/2022 | G21: 2121210 | H21: 48 | I21: 44192 | K21: 3 | L21: 12 | M21: 12 | N21: 12 | O21: 9 | P21: -1193181 | Q21: -309343 | R21: -1502524 | S21: 618686
A22: 20 | B22: Aset Tetap | C22: Perlengkapan | D22: Koreksi Audit 2024 - MMN Pembelian Shure BLX14 / SM35 Wireless Headset System | E22: Pullman - Mandalika | F22: 28/10/2022 | G22: 43734000 | H22: 48 | I22: 911125 | K22: 3 | L22: 12 | M22: 12 | N22: 12 | O22: 9 | P22: -24600375 | Q22: -6377875 | R22: -30978250 | S22: 12755750
A23: 21 | B23: Aset Tetap | C23: Perlengkapan | D23: Koreksi Audit 2024 - MMN Pembelian 5 Unit Standing Signed untuk FnB | E23: Pullman - Mandalika | F23: 44662 | G23: 17500000 | H23: 48 | I23: 364583 | K23: 2 | L23: 12 | M23: 12 | N23: 12 | O23: 10 | P23: -9479167 | Q23: -2552083 | R23: -12031250 | S23: 5468750
A24: 22 | B24: Aset Tetap | C24: Perlengkapan | D24: Koreksi Audit 2024 - MMN Indoor Plant Aer Restaurant (Plus Maintenance) | E24: Pullman - Mandalika | F24: 44784 | G24: 5000000 | H24: 48 | I24: 104167 | K24: 2 | L24: 12 | M24: 12 | N24: 12 | O24: 10 | P24: -2708333 | Q24: -729167 | R24: -3437500 | S24: 1562500
A25: 23 | B25: Aset Tetap | C25: Perlengkapan | D25: Koreksi Audit 2024 - MMN Orchit Standing Setting (Plus Maintenance) | E25: Pullman - Mandalika | F25: 44784 | G25: 11000000 | H25: 48 | I25: 229167 | K25: 2 | L25: 12 | M25: 12 | N25: 12 | O25: 10 | P25: -5958333 | Q25: -1604167 | R25: -7562500 | S25: 3437500
A26: 24 | B26: Aset Tetap | C26: Perlengkapan | D26: Koreksi Audit 2024 - MMN Pembelian Yale Door Chain dan Vingcard Lift Controller | E26: Pullman - Mandalika | F26: 14/11/2022 | G26: 241708537 | H26: 48 | I26: 5035595 | K26: 2 | L26: 12 | M26: 12 | N26: 12 | O26: 10 | P26: -130925458 | Q26: -35249162 | R26: -166174619 | S26: 75533918
A27: 25 | B27: Aset Tetap | C27: Perlengkapan | D27: Koreksi Audit 2024 - MMN Pembelian 3Pcs Standing Lifebuoy | E27: Pullman - Mandalika | F27: 14/11/2022 | G27: 11250000 | H27: 48 | I27: 234375 | K27: 2 | L27: 12 | M27: 12 | N27: 12 | O27: 10 | P27: -6093750 | Q27: -1640625 | R27: -7734375 | S27: 3515625
A28: 26 | B28: Aset Tetap | C28: Perlengkapan | D28: Koreksi Audit 2024 - MMN Pembelian Rak Buku Anak dan Rak Sepatu Anak | E28: Pullman - Mandalika | F28: 18/11/2022 | G28: 28400000 | H28: 48 | I28: 591667 | K28: 2 | L28: 12 | M28: 12 | N28: 12 | O28: 10 | P28: -15383333 | Q28: -4141667 | R28: -19525000 | S28: 8875000
A29: 27 | B29: Aset Tetap | C29: Perlengkapan | D29: Koreksi Audit 2024 - MMN Pembelian Navitek NT Pro With Touchscreen Untuk IT | E29: Pullman - Mandalika | F29: 19/11/2022 | G29: 28860000 | H29: 48 | I29: 601250 | K29: 2 | L29: 12 | M29: 12 | N29: 12 | O29: 10 | P29: -15632500 | Q29: -4208750 | R29: -19841250 | S29: 9018750
A30: 28 | B30: Aset Tetap | C30: Perlengkapan | D30: Koreksi Audit 2024 - MMN Pembelian Cabinet File for Engineering | E30: Pullman - Mandalika | F30: 25/11/2022 | G30: 6658000 | H30: 48 | I30: 138708 | K30: 2 | L30: 12 | M30: 12 | N30: 12 | O30: 10 | P30: -3606417 | Q30: -970958 | R30: -4577375 | S30: 2080625
A31: 29 | B31: Aset Tetap | C31: Perlengkapan | D31: Koreksi Audit 2024 - MMN Freezer 4 Doors HF - 128 | E31: Pullman - Mandalika | F31: 26/12/2022 | G31: 114476000 | H31: 48 | I31: 2384917 | K31: 1 | L31: 12 | M31: 12 | N31: 12 | O31: 11 | P31: -59622917 | Q31: -16694417 | R31: -76317333 | S31: 38158667
A32: 30 | B32: Aset Tetap | C32: Perlengkapan | D32: Koreksi Audit 2024 - MMN Pembelian Accu Gel, Antena Kenbotong UHF, Cable Charger, Kabel RG8, Repeater, CDR500, Duplexer, Kabel Cor, & Jumper | E32: Pullman - Mandalika | F32: 30/11/2022 | G32: 139168504 | H32: 48 | I32: 2899344 | K32: 2 | L32: 12 | M32: 12 | N32: 12 | O32: 10 | P32: -75382940 | Q32: -20295407 | R32: -95678347 | S32: 43490158
A33: 31 | B33: Aset Tetap | C33: Perlengkapan | D33: Koreksi Audit 2024 - MMN Pembelian 5pcs S/S Cleaning Beach Troley | E33: Pullman - Mandalika | F33: 44724 | G33: 31250000 | H33: 48 | I33: 651042 | K33: 1 | L33: 12 | M33: 12 | N33: 12 | O33: 11 | P33: -16276042 | Q33: -4557292 | R33: -20833333 | S33: 10416667
A34: 32 | B34: Aset Tetap | C34: Perlengkapan | D34: Koreksi Audit 2024 - MMN Orchid Standing Setting, Indoor Plant AER Restaurant Plus Maintenance | E34: Pullman - Mandalika | F34: 44754 | G34: 16000000 | H34: 48 | I34: 333333 | K34: 1 | L34: 12 | M34: 12 | N34: 12 | O34: 11 | P34: -8333333 | Q34: -2333333 | R34: -10666667 | S34: 5333333
A35: 33 | B35: Aset Tetap | C35: Perlengkapan | D35: Koreksi Audit 2024 - MMN Pembelian File Cabinet 4 Shelf 4 Door | E35: Pullman - Mandalika | F35: 14/12/2022 | G35: 2969000 | H35: 48 | I35: 61854 | K35: 1 | L35: 12 | M35: 12 | N35: 12 | O35: 11 | P35: -1546354 | Q35: -432979 | R35: -1979333 | S35: 989667
A36: 34 | B36: Aset Tetap | C36: Perlengkapan | D36: Koreksi Audit 2024 - MMN Pembelian Shelving Steel 5 Shelf 120 x 44 dan Storage 5 Shelf Rack 180 x 70 x 25 | E36: Pullman - Mandalika | F36: 15/12/2022 | G36: 37313000 | H36: 48 | I36: 777354 | K36: 0 | L36: 12 | M36: 12 | N36: 12 | O36: 12 | P36: -18656500 | Q36: -5441479 | R36: -24097979 | S36: 13215021
A37: 35 | B37: Aset Tetap | C37: Perlengkapan | D37: Koreksi Audit 2024 - MMN Slat 35mm - Stick Chane Oak | E37: Pullman - Mandalika | F37: 15/12/2022 | G37: 23123772 | H37: 48 | I37: 481745 | K37: 0 | L37: 12 | M37: 12 | N37: 12 | O37: 12 | P37: -11561886 | Q37: -3372217 | R37: -14934103 | S37: 8189669
A38: 36 | B38: Aset Tetap | C38: Perlengkapan | D38: Koreksi Audit 2024 - MMN Getra Water Boiler CP - 15 | E38: Pullman - Mandalika | F38: 21/12/2022 | G38: 1900000 | H38: 48 | I38: 39583 | K38: 0 | L38: 12 | M38: 12 | N38: 12 | O38: 12 | P38: -950000 | Q38: -277083 | R38: -1227083 | S38: 672917
A39: 37 | B39: Aset Tetap | C39: Perlengkapan | D39: Koreksi Audit 2024 - MMN Pembuatan Signed Akrilik Logo PT. MMN | E39: Pullman - Mandalika | F39: 26/12/2022 | G39: 1100000 | H39: 48 | I39: 22917 | K39: 0 | L39: 12 | M39: 12 | N39: 12 | O39: 12 | P39: -550000 | Q39: -160417 | R39: -710417 | S39: 389583
A40: 38 | B40: Aset Tetap | C40: Perlengkapan | D40: Koreksi Audit 2024 - MMN Pembelian Vingcard Sigm, RFID, Black Titanium | E40: Pullman - Mandalika | F40: 26/12/2022 | G40: 78789078 | H40: 48 | I40: 1641439 | K40: 0 | L40: 12 | M40: 12 | N40: 12 | O40: 12 | P40: -39394539 | Q40: -11490074 | R40: -50884613 | S40: 27904465
...

Sheet Asset Data Circuit Mandalika
B3: Kategori Aset | C3: Sub Kategori | D3: Lokasi | E3: Segmen | F3: Detail Pekerjaan | G3: Tgl Perolehan | H3: Nilai Perolehan | I3: Masa Manfaat | J3: 21 | K3: 22 | L3: 23 | M3: 24 | N3: 25 | O3: Depre Per Bulan | P3: Depre 2021 | Q3: Depre 2022 | R3: Depre 2023 | S3: Depre 2024 | T3: Depre s/d Agst 2025 | U3: Acc. Depre s/d Agst 2025
B4: Bangunan | C4: Jalan Sirkuit | D4: Mandalika | E4: Race | F4: Jalan Kawasan Khusus (JKK) Sirkuit Mandalika (PHO 5-10-2021), Kantor Pusat | G4: 44326 | H4: 907693537223 | I4: 360 | J4: 3 | K4: 12 | L4: 12 | M4: 12 | N4: 12 | O4: 2521370937 | P4: 7.5641128e+09 | Q4: 3.0256451e+10 | R4: 3.0256451e+10 | S4: 3.0256451e+10 | T4: -9.455141e+09 | U4: 88878325520 | V4: Kunci saldo s/d 2024, Dampak Perubahan Masa Manfaat pada Tahun Berjalan 2025 (kertas kerja s/d Mei 2025)
B5: Bangunan | C5: Jalan Sirkuit | D5: Mandalika | E5: Race | F5: Jalan Kawasan Khusus (JKK) Sirkuit Mandalika (PHO 5-10-2021), Project Mandalika | G5: 44326 | H5: 199319801280 | I5: 360 | J5: 3 | K5: 12 | L5: 12 | M5: 12 | N5: 12 | O5: 553666115 | P5: 1660998344 | Q5: 6643993376 | R5: 6643993376 | S5: 6643993376 | T5: -2076247930 | U5: 19516730542 | V5: Kunci saldo s/d 2024, Dampak Perubahan Masa Manfaat pada Tahun Berjalan 2025 (kertas kerja s/d Mei 2025)
B6: Sub Total | H6: 1107013338503 | O6: 3075037051 | P6: 9225111154 | Q6: 36900444617 | R6: 36900444617 | S6: 36900444617 | T6: -11531388943 | U6: 108395056062
B9: Kategori Aset | C9: Sub Kategori | D9: Lokasi | E9: Segmen | F9: Detail Pekerjaan | G9: Tgl Perolehan | H9: Nilai Perolehan | I9: Masa Manfaat | J9: 21 | K9: 22 | L9: 23 | M9: 24 | N9: 25 | O9: Depre Per Bulan | P9: Depre 2021 | Q9: Depre 2022 | R9: Depre 2023 | S9: Depre 2024 | T9: Depre s/d Juni 2025 | U9: Acc. Depre s/d Juni 2025
B10: Bangunan | C10: Jalan Sirkuit | D10: Mandalika | E10: Race | F10: Jalan Kawasan Khusus (JKK) Sirkuit Mandalika (PHO 5-10-2021), Kantor Pusat | G10: 44326 | H10: 907693537223 | I10: 480 | J10: 3 | K10: 12 | L10: 12 | M10: 12 | N10: 12 | O10: 1891028203 | P10: 5.6730846e+09 | Q10: 2.2692338e+10 | R10: 2.2692338e+10 | S10: 2.2692338e+10 | T10: 1.5128226e+10 | U10: 88878325520 | V10: Adjustment total dari awal (hitungan baru)
B11: Bangunan | C11: Jalan Sirkuit | D11: Mandalika | E11: Race | F11: Jalan Kawasan Khusus (JKK) Sirkuit Mandalika (PHO 5-10-2021), Project Mandalika | G11: 44326 | H11: 199319801280 | I11: 480 | J11: 3 | K11: 12 | L11: 12 | M11: 12 | N11: 12 | O11: 415249586 | P11: 1245748758 | Q11: 4982995032 | R11: 4982995032 | S11: 4982995032 | T11: 3321996688 | U11: 19516730542 | V11: Adjustment total dari awal (hitungan baru)
H12: 1107013338503 | J12: Beban Depresiasi Re-kalkulasi | O12: 2306277789 | P12: 6918833366 | Q12: 27675333463 | R12: 27675333463 | S12: 27675333463 | T12: 18450222308 | U12: 108395056062
J15: Selisih Beban Depresiasi Per Tahun | P15: 2306277789 | Q15: 9225111154 | R15: 9225111154 | S15: 9225111154 | T15: -29981611251 | U15: 0
P16: v | Q16: v | R16: v | S16: v | T16: v
U17: 0 | V17: 24583366633 | W17: % Item 1 atas Dampak Perubahan Umur, Masuk Tahun berjalan
U18: 0 | V18: 5398244618 | W18: % Item 2 atas Dampak Perubahan Umur, Masuk Tahun berjalan
U19: 0 | V19: 29981611251

Sheet Maintenance History
A1: NO | B1: Description | C1: Month | D1: Amount
B3: Perbaikan
A4: 1 | B4: Pemasangan Floor Tiles, Niro Granite, Lux GLX34, Explosion Bl - Ballroom | C4: 45413 | D4: 32546258
A5: 2 | B5: Floor Tiles, Grandeur GDR04 Pietra Black Hi Gloss - Ballroom | C5: 45413 | D5: 227344965
A6: 3 | B6: Pemasangan Granit GDR04 Pietra Black Hi Gloss 120c Kawan Rinjani Teknik - Ballroom | C6: 45444 | D6: 74602007
A7: 6 | B7: Pembuatan Cover AC - Villa 119 -117 | C7: 45474 | D7: 17316000
A8: 15 | B8: AC, Gree, Mitsubishi, split wall, MS-JR24VF, 2.5PK Villa | C8: 45474 | D8: 50782500
A9: 19 | B9: Air Curtain, kitchen asian, GK-2509YS2-CE, 900x1 | C9: 45474 | D9: 39294000
A10: 20 | B10: Air Curtain, kitchen indonesia, GK-2512AS2-CE, 119 | C10: 45474 | D10: 7326000
A11: 21 | B11: Sliding Glass Door, Living Room, 228x224cm villa | C11: 45474 | D11: 12000000
A12: 22 | B12: Sliding Glass Door, Bed Room, 252x264cm Villa | C12: 45474 | D12: 18907000
A13: 23 | B13: Pintu kaca Swing, Bathroom G116, T251 cm, P262.3 c | C13: 45566 | D13: 18700000
A14: 24 | B14: Sliding Glass Door for Bathroom G109, 110, 111, 112, 113, 115, 116 | C14: 45566 | D14: 112200000
A15: 25 | B15: Sliding Glass Door for Living Room G 109, 110, 111, 112, 113, 115, 116 | C15: 45566 | D15: 59500000
A16: 26 | B16: Instalation UPS PLN | C16: 45597 | D16: 37615000
A17: 27 | B17: Blade, Fan Cooling Tower & Service | C17: December2024 | D17: 27000000
A18: 28 | B18: Blade, Fan Cooling Tower 2 & Service | C18: December2024 | D18: 13500000
A19: 29 | B19: Pulley Fan Cooling Tower, Bearing, Bubut shaft, & | C19: December2024 | D19: 28500000
A20: 30 | B20: Sand Filters, P Series, 145kg, 1.5inch, 0.31m2 | C20: December2024 | D20: 8745000
A21: 31 | B21: Sand Filters, P Series, 145kg, 1.5inch, 0.31m2 | C21: December2024 | D21: 8745000
A22: 32 | B22: Penguatan, Cooling, Tower 2 | C22: December2024 | D22: 9000000
A23: 33 | B23: Sand Filter, Kolam, Emaux P650 | C23: December2024 | D23: 16800000
A24: 34 | B24: Pengerjaan Blade Cooling tower, 24,27,30, & Motor | C24: December2024 | D24: 9000000
A25: 35 | B25: AC for Chill Out & SPA | C25: January2025 | D25: 110573205
A26: 36 | B26: Sand Filter, Kolam, Emaux P650 | C26: January2025 | D26: 8400000
A27: 37 | B27: Sand Filter, Kolam, Emaux P650 | C27: January2025 | D27: 8400000
A28: 38 | B28: Sand Filter, Kolam, Dab V650 | C28: 45689 | D28: 16800000
A29: 40 | B29: Blade cooling Tower, 3 | C29: 45717 | D29: 22000000
A30: 41 | B30: Welding, the cooling tower fan, support frame, CT | C30: 45717 | D30: 4000000
A31: 42 | B31: Preliminary, Cooling Tower 1, & Cooling Tower 3 | C31: 45717 | D31: 3000000
A32: 43 | B32: Patching, of cooling tower, fiber covers, CT 1&3 | C32: 45717 | D32: 6000000
A33: 44 | B33: Addition of cooling fan support frame towers, CT 1 | C33: 45717 | D33: 5000000
A34: 45 | B34: Pembuatan Cover AC | C34: 45717 | D34: 24242400
A35: 56 | B35: AC, Mitsubishi, split wall, MS-JR24VF, 2.5PK | C35: 45748 | D35: 32800500
A36: 60 | B36: Pembelian kayu Ulin untuk penggantian pool deck | D36: 229640180
A37: 61 | B37: Perbaikan pool - injeksi kebocoran | D37: 171540000
B39: TOTAL

Sheet Financial_Statements
B2: PT PENGEMBANGAN PARIWISATA INDONESIA (PERSERO)
B3: KOMPARASI SALDO
D4: 4 | E4: 5 | F4: 6 | G4: 7 | H4: 8 | I4: 9 | J4: 11
D5: KONSOLIDASI | E5: KONSOLIDASI | F5: KONSOLIDASI | G5: KONSOLIDASI | H5: KONSOLIDASI | I5: KONSOLIDASI | J5: KONSOLIDASI
B6: NO. | C6: URAIAN | D6: AUDITED | E6: AUDITED | F6: AUDITED | G6: AUDITED | H6: AUDITED | I6: AUDITED | J6: AUDITED
D7: TAHUN 2018 | E7: TAHUN 2019 | F7: TAHUN 2020 | G7: TAHUN 2021* | H7: TAHUN 2022 | I7: TAHUN 2023 | J7: TAHUN 2024
D8: 7 | E8: 8 | F8: 9 | G8: Penyajian Kembali
B9: A. | C9: LABA (RUGI) KOMPREHENSIF
C10: PENDAPATAN OPERASI
C11: Kompensasi Lahan
A12: LB-R-001 | C12: Kompensasi Minimum | D12: 154250348121 | E12: 164136662173 | F12: 168022939374 | G12: 181564663610 | H12: 237984752684 | I12: 282402822733 | J12: 250532564911
A13: LB-R-002 | C13: Kompensasi Persentase | D13: 68079728829 | E13: 87433983846 | F13: 28218685371 | G13: 1175444403 | H13: 5107184611 | I13: 44680082518 | J13: 122895584306
A14: LB-R-003 | C14: Kompensasi Sekaligus | D14: 4146445105 | E14: 2492644851 | F14: 2482149727 | G14: 2269482203 | H14: 2518238243 | I14: 21279633396 | J14: 19339082396
A15: LB-R-004 | C15: Penggantian Asosiasi | D15: 30090992792 | E15: 30830120393 | F15: 31802859227 | G15: 24259317871 | H15: 36537703976 | I15: 33753722089 | J15: 32904103224 | L15: 4
A16: LB-R-005 | C16: Kompensasi Lainnya | D16: 3705134739 | E16: 4290242594 | F16: 3927361184 | G16: 3793209434 | H16: 4074711680 | I16: 4834387185 | J16: 3480547899
C17: Jumlah Pendapatan Kompensasi Lahan | D17: 260272649587 | E17: 289183653857 | F17: 234453994883 | G17: 213062117521 | H17: 286222591194 | I17: 386950647921 | J17: 429151882737
C19: Pendapatan Tambahan
A20: LB-R-006 | C20: Jasa Pengelolaan Air | D20: 18124376468 | E20: 18178661109 | F20: 5725506882 | G20: 3330691690 | H20: 3105774662 | I20: 12819044201 | J20: 16824536519
A21: LB-R-007 | C21: Pendapatan Lainnya | D21: 11419417405 | E21: 8553223831 | F21: 1452897308 | G21: 6501319391 | H21: 31428678010 | I21: 21826467191 | J21: 10056206241
A22: LB-R-027 | C22: Pendapatan Sirkuit Lainnya | J22: 70427859563
A23: LB-R-014 | C23: Jasa Akomodasi | D23: - | E23: 110743376 | F23: 43066086 | G23: 2128125855 | H23: 4455793824 | I23: 2489584648 | J23: -
A24: LB-R-015 | C24: Pendapatan BBM | D24: - | E24: - | F24: - | G24: 26651076900 | H24: 52428311203 | I24: 68356058786 | J24: 78481732951
A25: LB-R-028 | C25: Pendapatan Aquabike | J25: 30318367056
A26: LB-R-016 | C26: Watersport | D26: - | E26: - | F26: - | G26: - | H26: - | I26: - | J26: -
A27: LB-R-017 | C27: Air Bersih Nusa Dua | D27: - | E27: - | F27: - | G27: - | H27: - | I27: 48355653
A28: LB-R-022 | C28: Air Bersih Mandalika | D28: - | E28: - | F28: - | G28: - | H28: 2510014596 | I28: 3685324009 | J28: 5237085673
A29: LB-R-018 | C29: ICT Nusa Dua | D29: - | E29: - | F29: - | G29: 350000000 | H29: 600000000 | I29: 1190234274
A30: LB-R-023 | C30: ICT Mandalika | E30: - | F30: - | G30: - | H30: 1071284996 | I30: 596040634 | J30: 819485447
A31: LB-R-019 | C31: Agen Distributor | D31: - | E31: - | F31: - | G31: 897363419 | H31: 11433931715 | I31: 1724058742 | J31: 3065132766
A32: LB-R-020 | C32: Jasa Owner Rep | D32: - | E32: - | F32: - | G32: - | H32: - | I32: - | J32: -
A33: LB-R-024 | C33: Pendapatan Penjualan Lahan | J33: 2593762500000
A34: LB-R-025 | C34: Destination Management | J34: -
A35: LB-R-026 | C35: MICE Golo Mori | J35: 1699678128
A36: LB-R-021 | C36: Jasa Pengelolaan (Management Fee) | D36: - | E36: - | F36: - | G36: - | H36: 959039204 | I36: - | J36: -
A37: LB-R-009 | C37: Pendapatan Hotel Pullman | D37: - | E37: - | F37: - | G37: - | H37: 16190010784 | I37: 75301278218 | J37: 104501617428
A38: LB-R-008 | C38: Penyelenggaraan Event MotoGP | D38: - | E38: - | F38: - | G38: - | H38: 194876857906 | I38: 285161655904 | J38: 220771070185
A39: LB-R-010 | C39: Penyelenggaraan Event WSBK | D39: - | E39: - | F39: - | G39: 69862253476 | H39: 52205363844 | I39: 25065061602 | J39: -
C40: Jumlah Pendapatan Tambahan | D40: 29543793872 | E40: 26842628316 | F40: 7221470276 | G40: 109720830731 | H40: 371265060744 | I40: 498263163862 | J40: 3135965271958
C42: Jumlah Pendapatan Operasional | D42: 289816443459 | E42: 316026282173 | F42: 241675465159 | G42: 322782948252 | H42: 657487651938 | I42: 885213811783 | J42: 3565117154694
A44: LB-E-022 | C44: HPP Motogp | D44: - | E44: - | F44: - | G44: - | H44: 209289112225 | I44: 311323528882 | J44: 427652339696
...

Sheet ESL_Analysis_Pullman
B2: ECONOMIC SERVICE LIFE (ESL) ANALYSIS - PULLMAN
B4: INPUT ASSUMPTIONS
B6: Inflation Rate (Annual) | D6: {=Inputs!C7} -> 0.0406 | E6: Based on Bank Indonesia historical data
B7: Confidence Level | D7: {=Inputs!C8} -> 0.9 | E7: Used for O&M cost standard deviation calculations
B8: Discount Rate | D8: {=Inputs!C7} -> 0.0406
B9: Analysis Base Year | D9: 2024
B11: ASSET INFORMATION
B13: Asset Category | C13: Total Value (IDR) | D13: Useful Life (Years) | E13: Acquisition Year
B14: Building & Equipment (Pullman) | C14: {='Asset Data Pullman'!G235} -> 768913758683 | D14: {=SUMPRODUCT('Asset Data Pullman'!G3:G234,'Asset Data Pullman'!H3:H234/12)/SUM('Asset Data Pullman'!G3:G234)} -> 30.900719 | E14: 2021
B17: O&M COST STATISTICS
B19: Number of Observations | D19: =COUNT('Maintenance History'!D4:D37) -> 34
B20: Mean Annual O&M Cost | D20: =Inputs!C27 -> 43288824
B21: Standard Deviation (±) | D21: =_xlfn.STDEV.S('Maintenance History'!D4:D37) -> 59501277
B22: Std Dev (%) | D22: =D21/D20 -> 1.3745182
B23: Upper Bound (Mean + StdDev) | D23: =D20+D21 -> 1.027901e+08
B24: Lower Bound (Mean - StdDev) | D24: =D20-D21 -> -16212453
B26: ESL CALCULATION TABLE
B28: Year | C28: Age | D28: Annual Investment Cost (AIC) | E28: Annual O&M Cost (AOC) | F28: Total Annual Cost (TAC) | H28: INTERPRETATION NOTES:
B29: {=D9} -> 2024 | C29: 1 | D29: =C14*(D8*(1+D8)^D14)/((1+D8)^D14-1) -> 4.4115489e+10 | E29: =D20*(1+D6)^(C29-1)*(1+(C29-1)*0.5/D14) -> 43288824 | F29: =D29+E29 -> 4.4158778e+10 | G29: ← Minimum TAC occurs around this age | H29: • TAC (Total Annual Cost) = AIC + AOC
B30: =B29+1 -> 2025 | C30: =C29+1 -> 2 | D30: =D29*(1+D6) -> 4.5906578e+10 | E30: =D20*(1+D6)^(C30-1)*(1+(C30-1)*0.5/D14) -> 45775239 | F30: =D30+E30 -> 4.5952353e+10 | H30: • AIC (Annual Investment Cost) represents capital recovery and depreciation
B31: =B30+1 -> 2026 | C31: =C30+1 -> 3 | D31: =D30*(1+$D$6) -> 4.7770385e+10 | E31: =$D$20*(1+$D$6)^(C31-1)*(1+(C31-1)*0.5/$D$14) -> 48392195 | F31: =D31+E31 -> 4.7818777e+10 | H31: • ESL occurs at the minimum point of the TAC curve
B32: =B31+1 -> 2027 | C32: =C31+1 -> 4 | D32: =D31*(1+$D$6) -> 4.9709863e+10 | E32: =$D$20*(1+$D$6)^(C32-1)*(1+(C32-1)*0.5/$D$14) -> 51146193 | F32: =D32+E32 -> 4.9761009e+10 | H32: • The optimal replacement year is when TAC is minimized
B33: =B32+1 -> 2028 | C33: =C32+1 -> 5 | D33: =D32*(1+$D$6) -> 5.1728083e+10 | E33: =$D$20*(1+$D$6)^(C33-1)*(1+(C33-1)*0.5/$D$14) -> 54044049 | F33: =D33+E33 -> 5.1782127e+10
B34: =B33+1 -> 2029 | C34: =C33+1 -> 6 | D34: =D33*(1+$D$6) -> 5.3828243e+10 | E34: =$D$20*(1+$D$6)^(C34-1)*(1+(C34-1)*0.5/$D$14) -> 57092903 | F34: =D34+E34 -> 5.3885336e+10
B35: =B34+1 -> 2030 | C35: =C34+1 -> 7 | D35: =D34*(1+$D$6) -> 5.601367e+10 | E35: =$D$20*(1+$D$6)^(C35-1)*(1+(C35-1)*0.5/$D$14) -> 60300240 | F35: =D35+E35 -> 5.607397e+10 | H35: MINIMUM TAC ANALYSIS:
B36: =B35+1 -> 2031 | C36: =C35+1 -> 8 | D36: =D35*(1+$D$6) -> 5.8287825e+10 | E36: =$D$20*(1+$D$6)^(C36-1)*(1+(C36-1)*0.5/$D$14) -> 63673903 | F36: =D36+E36 -> 5.8351499e+10 | H36: Minimum TAC Value: | J36: =MIN(F29:F88) -> 4.4158778e+10
B37: =B36+1 -> 2032 | C37: =C36+1 -> 9 | D37: =D36*(1+$D$6) -> 6.0654311e+10 | E37: =$D$20*(1+$D$6)^(C37-1)*(1+(C37-1)*0.5/$D$14) -> 67222111 | F37: =D37+E37 -> 6.0721533e+10 | H37: Year at Minimum TAC: | J37: {=INDEX(B29:B88,MATCH(MIN(F29:F88),F29:F88,0))} -> 2024
B38: =B37+1 -> 2033 | C38: =C37+1 -> 10 | D38: =D37*(1+$D$6) -> 6.3116876e+10 | E38: =$D$20*(1+$D$6)^(C38-1)*(1+(C38-1)*0.5/$D$14) -> 70953476 | F38: =D38+E38 -> 6.3187829e+10 | H38: Asset Age at ESL: | J38: {=INDEX(C29:C88,MATCH(MIN(F29:F88),F29:F88,0))} -> 1
B39: =B38+1 -> 2034 | C39: =C38+1 -> 11 | D39: =D38*(1+$D$6) -> 6.5679421e+10 | E39: =$D$20*(1+$D$6)^(C39-1)*(1+(C39-1)*0.5/$D$14) -> 74877022 | F39: =D39+E39 -> 6.5754298e+10 | H39: Remaining Economic Life: | J39: {=J38} -> 1 | K39: years from base year
B40: =B39+1 -> 2035 | C40: =C39+1 -> 12 | D40: =D39*(1+$D$6) -> 6.8346005e+10 | E40: =$D$20*(1+$D$6)^(C40-1)*(1+(C40-1)*0.5/$D$14) -> 79002203 | F40: =D40+E40 -> 6.8425007e+10
B41: =B40+1 -> 2036 | C41: =C40+1 -> 13 | D41: =D40*(1+$D$6) -> 7.1120853e+10 | E41: =$D$20*(1+$D$6)^(C41-1)*(1+(C41-1)*0.5/$D$14) -> 83338924 | F41: =D41+E41 -> 7.1204192e+10 | H41: ESL RESULTS SUMMARY
