Workbook

Sheet Cases Data
A1: CaseName | B1: CAPEX | C1: Revenue | D1: OPEX | E1: EBITDA | F1: Senior Debt | G1: Junior Debt | H1: Public Concessional | I1: Equity | J1: SeniorRate | K1: JuniorRate | L1: PublicRate | M1: SeniorTenor | N1: JuniorTenor | O1: PublicTenor
A2: Case 1 | B2: 8570000 | C2: 1071803.5 | D2: 131000 | E2: 940803.52 | F2: 2999500 | G2: 0 | H2: 4285000 | I2: 1285500 | J2: 0.087957 | K2: 0.05 | L2: 0.02 | M2: 12 | N2: 12 | O2: 12
A3: Case 2 | B3: 8570000 | C3: 1071803.5 | D3: 131000 | E3: 940803.52 | F3: 1499750 | G3: 0 | H3: 0 | I3: 7070250 | J3: 0.087957 | K3: 0.05 | L3: 0.02 | M3: 12 | N3: 12 | O3: 12
A4: Case 3 | B4: 8570000 | C4: 1071803.5 | D4: 131000 | E4: 940803.52 | F4: 2279700 | G4: 6290300 | H4: 0 | I4: 0 | J4: 0.087957 | K4: 0.05 | L4: 0.02 | M4: 12 | N4: 12 | O4: 12
A5: Case 4 | B5: 8570000 | C5: 1071803.5 | D5: 131000 | E5: 940803.52 | F5: 5099150 | G5: 0 | H5: 1285500 | I5: 2185350 | J5: 0.087957 | K5: 0.05 | L5: 0.02 | M5: 12 | N5: 12 | O5: 12
A6: Case 5 | B6: 8570000 | C6: 1071803.5 | D6: 131000 | E6: 940803.52 | F6: 6770300 | G6: 1799700 | H6: 0 | I6: 0 | J6: 0.087957 | K6: 0.05 | L6: 0.02 | M6: 12 | N6: 12 | O6: 12

Sheet Case Sensitivity
A1: Case | B1: Assumptions | C1: CAPEX adj | D1: Revenue adj | E1: OPEX adj | F1: EBITDA adj | G1: SeniorDebt base | H1: JuniorDebt base | I1: PublicConcessional base | J1: Shortfall | K1: SeniorDebt adj | L1: JuniorDebt adj | M1: PublicConcessional adj | N1: SeniorRate base | O1: SeniorRate adj | P1: SeniorDS | Q1: JuniorDS | R1: PublicDS | S1: TotalDS | T1: DSCR | U1: CashAfterDebt | V1: Equity base | W1: Equity adj
A2: ='Cases Data'!A2 -> Case 1 | B2: =Scenarios!A2 -> Baseline | C2: ='Cases Data'!B2 * Scenarios!D2 -> 8570000 | D2: ='Cases Data'!C2 * Scenarios!B2 * Scenarios!D2 -> 1071803.5 | E2: ='Cases Data'!D2 * Scenarios!D2 -> 131000 | F2: =D2 - E2 -> 940803.52 | G2: ='Cases Data'!F2 -> 2999500 | H2: ='Cases Data'!G2 -> 0 | I2: ='Cases Data'!H2 -> 4285000 | J2: =(I2 + H2) * (1 - Scenarios!E2) -> 0 | K2: =G2 * Scenarios!D2 + 0.7 * J2 -> 2999500 | L2: =H2 * Scenarios!E2 -> 0 | M2: =I2 * Scenarios!E2 -> 4285000 | N2: ='Cases Data'!J2 -> 0.087957 | O2: =N2 + Scenarios!C2 -> 0.087957 | P2: =IF(K2>0, PMT(INDIRECT(ADDRESS(ROW(),15)), 'Cases Data'!M2, -K2), 0) -> 414580.91 | Q2: =IF(L2>0, PMT('Cases Data'!K2, 'Cases Data'!N2, -L2), 0) -> 0 | R2: =IF(M2>0, PMT('Cases Data'!L2, 'Cases Data'!O2, -M2), 0) -> 405187.87 | S2: =P2 + Q2 + R2 -> 819768.79 | T2: =IF(S2>0, F2 / S2, NA()) -> 1.147645 | U2: ='Cases Data'!I2 -> 1285500 | V2: =F2 - S2 -> 121034.73 | W2: =U2 * Scenarios!D2 + 0.3 * J2 -> 1285500
A3: ='Cases Data'!A2 -> Case 1 | B3: =Scenarios!A3 -> Tariff -10% | C3: ='Cases Data'!B2 * Scenarios!D3 -> 8570000 | D3: ='Cases Data'!C2 * Scenarios!B3 * Scenarios!D3 -> 964623.17 | E3: ='Cases Data'!D2 * Scenarios!D3 -> 131000 | F3: =D3 - E3 -> 833623.17 | G3: ='Cases Data'!F2 -> 2999500 | H3: ='Cases Data'!G2 -> 0 | I3: ='Cases Data'!H2 -> 4285000 | J3: =(I3 + H3) * (1 - Scenarios!E3) -> 0 | K3: =G3 * Scenarios!D3 + 0.7 * J3 -> 2999500 | L3: =H3 * Scenarios!E3 -> 0 | M3: =I3 * Scenarios!E3 -> 4285000 | N3: ='Cases Data'!J2 -> 0.087957 | O3: =N3 + Scenarios!C3 -> 0.087957 | P3: =IF(K3>0, PMT(INDIRECT(ADDRESS(ROW(),15)), 'Cases Data'!M2, -K3), 0) -> 414580.91 | Q3: =IF(L3>0, PMT('Cases Data'!K2, 'Cases Data'!N2, -L3), 0) -> 0 | R3: =IF(M3>0, PMT('Cases Data'!L2, 'Cases Data'!O2, -M3), 0) -> 405187.87 | S3: =P3 + Q3 + R3 -> 819768.79 | T3: =IF(S3>0, F3 / S3, NA()) -> 1.0169004 | U3: ='Cases Data'!I2 -> 1285500 | V3: =F3 - S3 -> 13854.382 | W3: =U3 * Scenarios!D3 + 0.3 * J3 -> 1285500
A4: ='Cases Data'!A2 -> Case 1 | B4: =Scenarios!A4 -> Senior +200bps | C4: ='Cases Data'!B2 * Scenarios!D4 -> 8570000 | D4: ='Cases Data'!C2 * Scenarios!B4 * Scenarios!D4 -> 1071803.5 | E4: ='Cases Data'!D2 * Scenarios!D4 -> 131000 | F4: =D4 - E4 -> 940803.52 | G4: ='Cases Data'!F2 -> 2999500 | H4: ='Cases Data'!G2 -> 0 | I4: ='Cases Data'!H2 -> 4285000 | J4: =(I4 + H4) * (1 - Scenarios!E4) -> 0 | K4: =G4 * Scenarios!D4 + 0.7 * J4 -> 2999500 | L4: =H4 * Scenarios!E4 -> 0 | M4: =I4 * Scenarios!E4 -> 4285000 | N4: ='Cases Data'!J2 -> 0.087957 | O4: =N4 + Scenarios!C4 -> 0.107957 | P4: =IF(K4>0, PMT(INDIRECT(ADDRESS(ROW(),15)), 'Cases Data'!M2, -K4), 0) -> 457517.45 | Q4: =IF(L4>0, PMT('Cases Data'!K2, 'Cases Data'!N2, -L4), 0) -> 0 | R4: =IF(M4>0, PMT('Cases Data'!L2, 'Cases Data'!O2, -M4), 0) -> 405187.87 | S4: =P4 + Q4 + R4 -> 862705.32 | T4: =IF(S4>0, F4 / S4, NA()) -> 1.0905271 | U4: ='Cases Data'!I2 -> 1285500 | V4: =F4 - S4 -> 78098.2 | W4: =U4 * Scenarios!D4 + 0.3 * J4 -> 1285500
A5: ='Cases Data'!A2 -> Case 1 | B5: =Scenarios!A5 -> CAPEX +20% | C5: ='Cases Data'!B2 * Scenarios!D5 -> 10284000 | D5: ='Cases Data'!C2 * Scenarios!B5 * Scenarios!D5 -> 1286164.2 | E5: ='Cases Data'!D2 * Scenarios!D5 -> 157200 | F5: =D5 - E5 -> 1128964.2 | G5: ='Cases Data'!F2 -> 2999500 | H5: ='Cases Data'!G2 -> 0 | I5: ='Cases Data'!H2 -> 4285000 | J5: =(I5 + H5) * (1 - Scenarios!E5) -> 0 | K5: =G5 * Scenarios!D5 + 0.7 * J5 -> 3599400 | L5: =H5 * Scenarios!E5 -> 0 | M5: =I5 * Scenarios!E5 -> 4285000 | N5: ='Cases Data'!J2 -> 0.087957 | O5: =N5 + Scenarios!C5 -> 0.087957 | P5: =IF(K5>0, PMT(INDIRECT(ADDRESS(ROW(),15)), 'Cases Data'!M2, -K5), 0) -> 497497.1 | Q5: =IF(L5>0, PMT('Cases Data'!K2, 'Cases Data'!N2, -L5), 0) -> 0 | R5: =IF(M5>0, PMT('Cases Data'!L2, 'Cases Data'!O2, -M5), 0) -> 405187.87 | S5: =P5 + Q5 + R5 -> 902684.97 | T5: =IF(S5>0, F5 / S5, NA()) -> 1.2506736 | U5: ='Cases Data'!I2 -> 1285500 | V5: =F5 - S5 -> 226279.26 | W5: =U5 * Scenarios!D5 + 0.3 * J5 -> 1542600
A6: ='Cases Data'!A2 -> Case 1 | B6: =Scenarios!A6 -> Concessional -50% | C6: ='Cases Data'!B2 * Scenarios!D6 -> 8570000 | D6: ='Cases Data'!C2 * Scenarios!B6 * Scenarios!D6 -> 1071803.5 | E6: ='Cases Data'!D2 * Scenarios!D6 -> 131000 | F6: =D6 - E6 -> 940803.52 | G6: ='Cases Data'!F2 -> 2999500 | H6: ='Cases Data'!G2 -> 0 | I6: ='Cases Data'!H2 -> 4285000 | J6: =(I6 + H6) * (1 - Scenarios!E6) -> 2142500 | K6: =G6 * Scenarios!D6 + 0.7 * J6 -> 4499250 | L6: =H6 * Scenarios!E6 -> 0 | M6: =I6 * Scenarios!E6 -> 2142500 | N6: ='Cases Data'!J2 -> 0.087957 | O6: =N6 + Scenarios!C6 -> 0.087957 | P6: =IF(K6>0, PMT(INDIRECT(ADDRESS(ROW(),15)), 'Cases Data'!M2, -K6), 0) -> 621871.37 | Q6: =IF(L6>0, PMT('Cases Data'!K2, 'Cases Data'!N2, -L6), 0) -> 0 | R6: =IF(M6>0, PMT('Cases Data'!L2, 'Cases Data'!O2, -M6), 0) -> 202593.94 | S6: =P6 + Q6 + R6 -> 824465.31 | T6: =IF(S6>0, F6 / S6, NA()) -> 1.1411075 | U6: ='Cases Data'!I2 -> 1285500 | V6: =F6 - S6 -> 116338.21 | W6: =U6 * Scenarios!D6 + 0.3 * J6 -> 1928250
A7: ='Cases Data'!A3 -> Case 2 | B7: =Scenarios!A2 -> Baseline | C7: ='Cases Data'!B3 * Scenarios!D2 -> 8570000 | D7: ='Cases Data'!C3 * Scenarios!B2 * Scenarios!D2 -> 1071803.5 | E7: ='Cases Data'!D3 * Scenarios!D2 -> 131000 | F7: =D7 - E7 -> 940803.52 | G7: ='Cases Data'!F3 -> 1499750 | H7: ='Cases Data'!G3 -> 0 | I7: ='Cases Data'!H3 -> 0 | J7: =(I7 + H7) * (1 - Scenarios!E2) -> 0 | K7: =G7 * Scenarios!D2 + 0.7 * J7 -> 1499750 | L7: =H7 * Scenarios!E2 -> 0 | M7: =I7 * Scenarios!E2 -> 0 | N7: ='Cases Data'!J3 -> 0.087957 | O7: =N7 + Scenarios!C2 -> 0.087957 | P7: =IF(K7>0, PMT(INDIRECT(ADDRESS(ROW(),15)), 'Cases Data'!M3, -K7), 0) -> 207290.46 | Q7: =IF(L7>0, PMT('Cases Data'!K3, 'Cases Data'!N3, -L7), 0) -> 0 | R7: =IF(M7>0, PMT('Cases Data'!L3, 'Cases Data'!O3, -M7), 0) -> 0 | S7: =P7 + Q7 + R7 -> 207290.46 | T7: =IF(S7>0, F7 / S7, NA()) -> 4.5385761 | U7: ='Cases Data'!I3 -> 7070250 | V7: =F7 - S7 -> 733513.06 | W7: =U7 * Scenarios!D2 + 0.3 * J7 -> 7070250
A8: ='Cases Data'!A3 -> Case 2 | B8: =Scenarios!A3 -> Tariff -10% | C8: ='Cases Data'!B3 * Scenarios!D3 -> 8570000 | D8: ='Cases Data'!C3 * Scenarios!B3 * Scenarios!D3 -> 964623.17 | E8: ='Cases Data'!D3 * Scenarios!D3 -> 131000 | F8: =D8 - E8 -> 833623.17 | G8: ='Cases Data'!F3 -> 1499750 | H8: ='Cases Data'!G3 -> 0 | I8: ='Cases Data'!H3 -> 0 | J8: =(I8 + H8) * (1 - Scenarios!E3) -> 0 | K8: =G8 * Scenarios!D3 + 0.7 * J8 -> 1499750 | L8: =H8 * Scenarios!E3 -> 0 | M8: =I8 * Scenarios!E3 -> 0 | N8: ='Cases Data'!J3 -> 0.087957 | O8: =N8 + Scenarios!C3 -> 0.087957 | P8: =IF(K8>0, PMT(INDIRECT(ADDRESS(ROW(),15)), 'Cases Data'!M3, -K8), 0) -> 207290.46 | Q8: =IF(L8>0, PMT('Cases Data'!K3, 'Cases Data'!N3, -L8), 0) -> 0 | R8: =IF(M8>0, PMT('Cases Data'!L3, 'Cases Data'!O3, -M8), 0) -> 0 | S8: =P8 + Q8 + R8 -> 207290.46 | T8: =IF(S8>0, F8 / S8, NA()) -> 4.0215222 | U8: ='Cases Data'!I3 -> 7070250 | V8: =F8 - S8 -> 626332.71 | W8: =U8 * Scenarios!D3 + 0.3 * J8 -> 7070250
A9: ='Cases Data'!A3 -> Case 2 | B9: =Scenarios!A4 -> Senior +200bps | C9: ='Cases Data'!B3 * Scenarios!D4 -> 8570000 | D9: ='Cases Data'!C3 * Scenarios!B4 * Scenarios!D4 -> 1071803.5 | E9: ='Cases Data'!D3 * Scenarios!D4 -> 131000 | F9: =D9 - E9 -> 940803.52 | G9: ='Cases Data'!F3 -> 1499750 | H9: ='Cases Data'!G3 -> 0 | I9: ='Cases Data'!H3 -> 0 | J9: =(I9 + H9) * (1 - Scenarios!E4) -> 0 | K9: =G9 * Scenarios!D4 + 0.7 * J9 -> 1499750 | L9: =H9 * Scenarios!E4 -> 0 | M9: =I9 * Scenarios!E4 -> 0 | N9: ='Cases Data'!J3 -> 0.087957 | O9: =N9 + Scenarios!C4 -> 0.107957 | P9: =IF(K9>0, PMT(INDIRECT(ADDRESS(ROW(),15)), 'Cases Data'!M3, -K9), 0) -> 228758.72 | Q9: =IF(L9>0, PMT('Cases Data'!K3, 'Cases Data'!N3, -L9), 0) -> 0 | R9: =IF(M9>0, PMT('Cases Data'!L3, 'Cases Data'!O3, -M9), 0) -> 0 | S9: =P9 + Q9 + R9 -> 228758.72 | T9: =IF(S9>0, F9 / S9, NA()) -> 4.1126454 | U9: ='Cases Data'!I3 -> 7070250 | V9: =F9 - S9 -> 712044.8 | W9: =U9 * Scenarios!D4 + 0.3 * J9 -> 7070250
A10: ='Cases Data'!A3 -> Case 2 | B10: =Scenarios!A5 -> CAPEX +20% | C10: ='Cases Data'!B3 * Scenarios!D5 -> 10284000 | D10: ='Cases Data'!C3 * Scenarios!B5 * Scenarios!D5 -> 1286164.2 | E10: ='Cases Data'!D3 * Scenarios!D5 -> 157200 | F10: =D10 - E10 -> 1128964.2 | G10: ='Cases Data'!F3 -> 1499750 | H10: ='Cases Data'!G3 -> 0 | I10: ='Cases Data'!H3 -> 0 | J10: =(I10 + H10) * (1 - Scenarios!E5) -> 0 | K10: =G10 * Scenarios!D5 + 0.7 * J10 -> 1799700 | L10: =H10 * Scenarios!E5 -> 0 | M10: =I10 * Scenarios!E5 -> 0 | N10: ='Cases Data'!J3 -> 0.087957 | O10: =N10 + Scenarios!C5 -> 0.087957 | P10: =IF(K10>0, PMT(INDIRECT(ADDRESS(ROW(),15)), 'Cases Data'!M3, -K10), 0) -> 248748.55 | Q10: =IF(L10>0, PMT('Cases Data'!K3, 'Cases Data'!N3, -L10), 0) -> 0 | R10: =IF(M10>0, PMT('Cases Data'!L3, 'Cases Data'!O3, -M10), 0) -> 0 | S10: =P10 + Q10 + R10 -> 248748.55 | T10: =IF(S10>0, F10 / S10, NA()) -> 4.5385761 | U10: ='Cases Data'!I3 -> 7070250 | V10: =F10 - S10 -> 880215.68 | W10: =U10 * Scenarios!D5 + 0.3 * J10 -> 8484300
A11: ='Cases Data'!A3 -> Case 2 | B11: =Scenarios!A6 -> Concessional -50% | C11: ='Cases Data'!B3 * Scenarios!D6 -> 8570000 | D11: ='Cases Data'!C3 * Scenarios!B6 * Scenarios!D6 -> 1071803.5 | E11: ='Cases Data'!D3 * Scenarios!D6 -> 131000 | F11: =D11 - E11 -> 940803.52 | G11: ='Cases Data'!F3 -> 1499750 | H11: ='Cases Data'!G3 -> 0 | I11: ='Cases Data'!H3 -> 0 | J11: =(I11 + H11) * (1 - Scenarios!E6) -> 0 | K11: =G11 * Scenarios!D6 + 0.7 * J11 -> 1499750 | L11: =H11 * Scenarios!E6 -> 0 | M11: =I11 * Scenarios!E6 -> 0 | N11: ='Cases Data'!J3 -> 0.087957 | O11: =N11 + Scenarios!C6 -> 0.087957 | P11: =IF(K11>0, PMT(INDIRECT(ADDRESS(ROW(),15)), 'Cases Data'!M3, -K11), 0) -> 207290.46 | Q11: =IF(L11>0, PMT('Cases Data'!K3, 'Cases Data'!N3, -L11), 0) -> 0 | R11: =IF(M11>0, PMT('Cases Data'!L3, 'Cases Data'!O3, -M11), 0) -> 0 | S11: =P11 + Q11 + R11 -> 207290.46 | T11: =IF(S11>0, F11 / S11, NA()) -> 4.5385761 | U11: ='Cases Data'!I3 -> 7070250 | V11: =F11 - S11 -> 733513.06 | W11: =U11 * Scenarios!D6 + 0.3 * J11 -> 7070250
A12: ='Cases Data'!A4 -> Case 3 | B12: =Scenarios!A2 -> Baseline | C12: ='Cases Data'!B4 * Scenarios!D2 -> 8570000 | D12: ='Cases Data'!C4 * Scenarios!B2 * Scenarios!D2 -> 1071803.5 | E12: ='Cases Data'!D4 * Scenarios!D2 -> 131000 | F12: =D12 - E12 -> 940803.52 | G12: ='Cases Data'!F4 -> 2279700 | H12: ='Cases Data'!G4 -> 6290300 | I12: ='Cases Data'!H4 -> 0 | J12: =(I12 + H12) * (1 - Scenarios!E2) -> 0 | K12: =G12 * Scenarios!D2 + 0.7 * J12 -> 2279700 | L12: =H12 * Scenarios!E2 -> 6290300 | M12: =I12 * Scenarios!E2 -> 0 | N12: ='Cases Data'!J4 -> 0.087957 | O12: =N12 + Scenarios!C2 -> 0.087957 | P12: =IF(K12>0, PMT(INDIRECT(ADDRESS(ROW(),15)), 'Cases Data'!M4, -K12), 0) -> 315092.55 | Q12: =IF(L12>0, PMT('Cases Data'!K4, 'Cases Data'!N4, -L12), 0) -> 709705.68 | R12: =IF(M12>0, PMT('Cases Data'!L4, 'Cases Data'!O4, -M12), 0) -> 0 | S12: =P12 + Q12 + R12 -> 1024798.2 | T12: =IF(S12>0, F12 / S12, NA()) -> 0.91803781 | U12: ='Cases Data'!I4 -> 0 | V12: =F12 - S12 -> -83994.709 | W12: =U12 * Scenarios!D2 + 0.3 * J12 -> 0
A13: ='Cases Data'!A4 -> Case 3 | B13: =Scenarios!A3 -> Tariff -10% | C13: ='Cases Data'!B4 * Scenarios!D3 -> 8570000 | D13: ='Cases Data'!C4 * Scenarios!B3 * Scenarios!D3 -> 964623.17 | E13: ='Cases Data'!D4 * Scenarios!D3 -> 131000 | F13: =D13 - E13 -> 833623.17 | G13: ='Cases Data'!F4 -> 2279700 | H13: ='Cases Data'!G4 -> 6290300 | I13: ='Cases Data'!H4 -> 0 | J13: =(I13 + H13) * (1 - Scenarios!E3) -> 0 | K13: =G13 * Scenarios!D3 + 0.7 * J13 -> 2279700 | L13: =H13 * Scenarios!E3 -> 6290300 | M13: =I13 * Scenarios!E3 -> 0 | N13: ='Cases Data'!J4 -> 0.087957 | O13: =N13 + Scenarios!C3 -> 0.087957 | P13: =IF(K13>0, PMT(INDIRECT(ADDRESS(ROW(),15)), 'Cases Data'!M4, -K13), 0) -> 315092.55 | Q13: =IF(L13>0, PMT('Cases Data'!K4, 'Cases Data'!N4, -L13), 0) -> 709705.68 | R13: =IF(M13>0, PMT('Cases Data'!L4, 'Cases Data'!O4, -M13), 0) -> 0 | S13: =P13 + Q13 + R13 -> 1024798.2 | T13: =IF(S13>0, F13 / S13, NA()) -> 0.81345102 | U13: ='Cases Data'!I4 -> 0 | V13: =F13 - S13 -> -191175.06 | W13: =U13 * Scenarios!D3 + 0.3 * J13 -> 0
A14: ='Cases Data'!A4 -> Case 3 | B14: =Scenarios!A4 -> Senior +200bps | C14: ='Cases Data'!B4 * Scenarios!D4 -> 8570000 | D14: ='Cases Data'!C4 * Scenarios!B4 * Scenarios!D4 -> 1071803.5 | E14: ='Cases Data'!D4 * Scenarios!D4 -> 131000 | F14: =D14 - E14 -> 940803.52 | G14: ='Cases Data'!F4 -> 2279700 | H14: ='Cases Data'!G4 -> 6290300 | I14: ='Cases Data'!H4 -> 0 | J14: =(I14 + H14) * (1 - Scenarios!E4) -> 0 | K14: =G14 * Scenarios!D4 + 0.7 * J14 -> 2279700 | L14: =H14 * Scenarios!E4 -> 6290300 | M14: =I14 * Scenarios!E4 -> 0 | N14: ='Cases Data'!J4 -> 0.087957 | O14: =N14 + Scenarios!C4 -> 0.107957 | P14: =IF(K14>0, PMT(INDIRECT(ADDRESS(ROW(),15)), 'Cases Data'!M4, -K14), 0) -> 347725.46 | Q14: =IF(L14>0, PMT('Cases Data'!K4, 'Cases Data'!N4, -L14), 0) -> 709705.68 | R14: =IF(M14>0, PMT('Cases Data'!L4, 'Cases Data'!O4, -M14), 0) -> 0 | S14: =P14 + Q14 + R14 -> 1057431.1 | T14: =IF(S14>0, F14 / S14, NA()) -> 0.88970665 | U14: ='Cases Data'!I4 -> 0 | V14: =F14 - S14 -> -116627.62 | W14: =U14 * Scenarios!D4 + 0.3 * J14 -> 0
A15: ='Cases Data'!A4 -> Case 3 | B15: =Scenarios!A5 -> CAPEX +20% | C15: ='Cases Data'!B4 * Scenarios!D5 -> 10284000 | D15: ='Cases Data'!C4 * Scenarios!B5 * Scenarios!D5 -> 1286164.2 | E15: ='Cases Data'!D4 * Scenarios!D5 -> 157200 | F15: =D15 - E15 -> 1128964.2 | G15: ='Cases Data'!F4 -> 2279700 | H15: ='Cases Data'!G4 -> 6290300 | I15: ='Cases Data'!H4 -> 0 | J15: =(I15 + H15) * (1 - Scenarios!E5) -> 0 | K15: =G15 * Scenarios!D5 + 0.7 * J15 -> 2735640 | L15: =H15 * Scenarios!E5 -> 6290300 | M15: =I15 * Scenarios!E5 -> 0 | N15: ='Cases Data'!J4 -> 0.087957 | O15: =N15 + Scenarios!C5 -> 0.087957 | P15: =IF(K15>0, PMT(INDIRECT(ADDRESS(ROW(),15)), 'Cases Data'!M4, -K15), 0) -> 378111.06 | Q15: =IF(L15>0, PMT('Cases Data'!K4, 'Cases Data'!N4, -L15), 0) -> 709705.68 | R15: =IF(M15>0, PMT('Cases Data'!L4, 'Cases Data'!O4, -M15), 0) -> 0 | S15: =P15 + Q15 + R15 -> 1087816.7 | T15: =IF(S15>0, F15 / S15, NA()) -> 1.0378258 | U15: ='Cases Data'!I4 -> 0 | V15: =F15 - S15 -> 41147.485 | W15: =U15 * Scenarios!D5 + 0.3 * J15 -> 0
A16: ='Cases Data'!A4 -> Case 3 | B16: =Scenarios!A6 -> Concessional -50% | C16: ='Cases Data'!B4 * Scenarios!D6 -> 8570000 | D16: ='Cases Data'!C4 * Scenarios!B6 * Scenarios!D6 -> 1071803.5 | E16: ='Cases Data'!D4 * Scenarios!D6 -> 131000 | F16: =D16 - E16 -> 940803.52 | G16: ='Cases Data'!F4 -> 2279700 | H16: ='Cases Data'!G4 -> 6290300 | I16: ='Cases Data'!H4 -> 0 | J16: =(I16 + H16) * (1 - Scenarios!E6) -> 3145150 | K16: =G16 * Scenarios!D6 + 0.7 * J16 -> 4481305 | L16: =H16 * Scenarios!E6 -> 3145150 | M16: =I16 * Scenarios!E6 -> 0 | N16: ='Cases Data'!J4 -> 0.087957 | O16: =N16 + Scenarios!C6 -> 0.087957 | P16: =IF(K16>0, PMT(INDIRECT(ADDRESS(ROW(),15)), 'Cases Data'!M4, -K16), 0) -> 619391.07 | Q16: =IF(L16>0, PMT('Cases Data'!K4, 'Cases Data'!N4, -L16), 0) -> 354852.84 | R16: =IF(M16>0, PMT('Cases Data'!L4, 'Cases Data'!O4, -M16), 0) -> 0 | S16: =P16 + Q16 + R16 -> 974243.91 | T16: =IF(S16>0, F16 / S16, NA()) -> 0.96567554 | U16: ='Cases Data'!I4 -> 0 | V16: =F16 - S16 -> -33440.391 | W16: =U16 * Scenarios!D6 + 0.3 * J16 -> 943545
A17: ='Cases Data'!A5 -> Case 4 | B17: =Scenarios!A2 -> Baseline | C17: ='Cases Data'!B5 * Scenarios!D2 -> 8570000 | D17: ='Cases Data'!C5 * Scenarios!B2 * Scenarios!D2 -> 1071803.5 | E17: ='Cases Data'!D5 * Scenarios!D2 -> 131000 | F17: =D17 - E17 -> 940803.52 | G17: ='Cases Data'!F5 -> 5099150 | H17: ='Cases Data'!G5 -> 0 | I17: ='Cases Data'!H5 -> 1285500 | J17: =(I17 + H17) * (1 - Scenarios!E2) -> 0 | K17: =G17 * Scenarios!D2 + 0.7 * J17 -> 5099150 | L17: =H17 * Scenarios!E2 -> 0 | M17: =I17 * Scenarios!E2 -> 1285500 | N17: ='Cases Data'!J5 -> 0.087957 | O17: =N17 + Scenarios!C2 -> 0.087957 | P17: =IF(K17>0, PMT(INDIRECT(ADDRESS(ROW(),15)), 'Cases Data'!M5, -K17), 0) -> 704787.55 | Q17: =IF(L17>0, PMT('Cases Data'!K5, 'Cases Data'!N5, -L17), 0) -> 0 | R17: =IF(M17>0, PMT('Cases Data'!L5, 'Cases Data'!O5, -M17), 0) -> 121556.36 | S17: =P17 + Q17 + R17 -> 826343.92 | T17: =IF(S17>0, F17 / S17, NA()) -> 1.1385133 | U17: ='Cases Data'!I5 -> 2185350 | V17: =F17 - S17 -> 114459.6 | W17: =U17 * Scenarios!D2 + 0.3 * J17 -> 2185350
A18: ='Cases Data'!A5 -> Case 4 | B18: =Scenarios!A3 -> Tariff -10% | C18: ='Cases Data'!B5 * Scenarios!D3 -> 8570000 | D18: ='Cases Data'!C5 * Scenarios!B3 * Scenarios!D3 -> 964623.17 | E18: ='Cases Data'!D5 * Scenarios!D3 -> 131000 | F18: =D18 - E18 -> 833623.17 | G18: ='Cases Data'!F5 -> 5099150 | H18: ='Cases Data'!G5 -> 0 | I18: ='Cases Data'!H5 -> 1285500 | J18: =(I18 + H18) * (1 - Scenarios!E3) -> 0 | K18: =G18 * Scenarios!D3 + 0.7 * J18 -> 5099150 | L18: =H18 * Scenarios!E3 -> 0 | M18: =I18 * Scenarios!E3 -> 1285500 | N18: ='Cases Data'!J5 -> 0.087957 | O18: =N18 + Scenarios!C3 -> 0.087957 | P18: =IF(K18>0, PMT(INDIRECT(ADDRESS(ROW(),15)), 'Cases Data'!M5, -K18), 0) -> 704787.55 | Q18: =IF(L18>0, PMT('Cases Data'!K5, 'Cases Data'!N5, -L18), 0) -> 0 | R18: =IF(M18>0, PMT('Cases Data'!L5, 'Cases Data'!O5, -M18), 0) -> 121556.36 | S18: =P18 + Q18 + R18 -> 826343.92 | T18: =IF(S18>0, F18 / S18, NA()) -> 1.008809 | U18: ='Cases Data'!I5 -> 2185350 | V18: =F18 - S18 -> 7279.2524 | W18: =U18 * Scenarios!D3 + 0.3 * J18 -> 2185350
A19: ='Cases Data'!A5 -> Case 4 | B19: =Scenarios!A4 -> Senior +200bps | C19: ='Cases Data'!B5 * Scenarios!D4 -> 8570000 | D19: ='Cases Data'!C5 * Scenarios!B4 * Scenarios!D4 -> 1071803.5 | E19: ='Cases Data'!D5 * Scenarios!D4 -> 131000 | F19: =D19 - E19 -> 940803.52 | G19: ='Cases Data'!F5 -> 5099150 | H19: ='Cases Data'!G5 -> 0 | I19: ='Cases Data'!H5 -> 1285500 | J19: =(I19 + H19) * (1 - Scenarios!E4) -> 0 | K19: =G19 * Scenarios!D4 + 0.7 * J19 -> 5099150 | L19: =H19 * Scenarios!E4 -> 0 | M19: =I19 * Scenarios!E4 -> 1285500 | N19: ='Cases Data'!J5 -> 0.087957 | O19: =N19 + Scenarios!C4 -> 0.107957 | P19: =IF(K19>0, PMT(INDIRECT(ADDRESS(ROW(),15)), 'Cases Data'!M5, -K19), 0) -> 777779.66 | Q19: =IF(L19>0, PMT('Cases Data'!K5, 'Cases Data'!N5, -L19), 0) -> 0 | R19: =IF(M19>0, PMT('Cases Data'!L5, 'Cases Data'!O5, -M19), 0) -> 121556.36 | S19: =P19 + Q19 + R19 -> 899336.02 | T19: =IF(S19>0, F19 / S19, NA()) -> 1.046109 | U19: ='Cases Data'!I5 -> 2185350 | V19: =F19 - S19 -> 41467.497 | W19: =U19 * Scenarios!D4 + 0.3 * J19 -> 2185350
A20: ='Cases Data'!A5 -> Case 4 | B20: =Scenarios!A5 -> CAPEX +20% | C20: ='Cases Data'!B5 * Scenarios!D5 -> 10284000 | D20: ='Cases Data'!C5 * Scenarios!B5 * Scenarios!D5 -> 1286164.2 | E20: ='Cases Data'!D5 * Scenarios!D5 -> 157200 | F20: =D20 - E20 -> 1128964.2 | G20: ='Cases Data'!F5 -> 5099150 | H20: ='Cases Data'!G5 -> 0 | I20: ='Cases Data'!H5 -> 1285500 | J20: =(I20 + H20) * (1 - Scenarios!E5) -> 0 | K20: =G20 * Scenarios!D5 + 0.7 * J20 -> 6118980 | L20: =H20 * Scenarios!E5 -> 0 | M20: =I20 * Scenarios!E5 -> 1285500 | N20: ='Cases Data'!J5 -> 0.087957 | O20: =N20 + Scenarios!C5 -> 0.087957 | P20: =IF(K20>0, PMT(INDIRECT(ADDRESS(ROW(),15)), 'Cases Data'!M5, -K20), 0) -> 845745.07 | Q20: =IF(L20>0, PMT('Cases Data'!K5, 'Cases Data'!N5, -L20), 0) -> 0 | R20: =IF(M20>0, PMT('Cases Data'!L5, 'Cases Data'!O5, -M20), 0) -> 121556.36 | S20: =P20 + Q20 + R20 -> 967301.43 | T20: =IF(S20>0, F20 / S20, NA()) -> 1.1671276 | U20: ='Cases Data'!I5 -> 2185350 | V20: =F20 - S20 -> 161662.8 | W20: =U20 * Scenarios!D5 + 0.3 * J20 -> 2622420
A21: ='Cases Data'!A5 -> Case 4 | B21: =Scenarios!A6 -> Concessional -50% | C21: ='Cases Data'!B5 * Scenarios!D6 -> 8570000 | D21: ='Cases Data'!C5 * Scenarios!B6 * Scenarios!D6 -> 1071803.5 | E21: ='Cases Data'!D5 * Scenarios!D6 -> 131000 | F21: =D21 - E21 -> 940803.52 | G21: ='Cases Data'!F5 -> 5099150 | H21: ='Cases Data'!G5 -> 0 | I21: ='Cases Data'!H5 -> 1285500 | J21: =(I21 + H21) * (1 - Scenarios!E6) -> 642750 | K21: =G21 * Scenarios!D6 + 0.7 * J21 -> 5549075 | L21: =H21 * Scenarios!E6 -> 0 | M21: =I21 * Scenarios!E6 -> 642750 | N21: ='Cases Data'!J5 -> 0.087957 | O21: =N21 + Scenarios!C6 -> 0.087957 | P21: =IF(K21>0, PMT(INDIRECT(ADDRESS(ROW(),15)), 'Cases Data'!M5, -K21), 0) -> 766974.69 | Q21: =IF(L21>0, PMT('Cases Data'!K5, 'Cases Data'!N5, -L21), 0) -> 0 | R21: =IF(M21>0, PMT('Cases Data'!L5, 'Cases Data'!O5, -M21), 0) -> 60778.181 | S21: =P21 + Q21 + R21 -> 827752.87 | T21: =IF(S21>0, F21 / S21, NA()) -> 1.1365754 | U21: ='Cases Data'!I5 -> 2185350 | V21: =F21 - S21 -> 113050.65 | W21: =U21 * Scenarios!D6 + 0.3 * J21 -> 2378175
A22: ='Cases Data'!A6 -> Case 5 | B22: =Scenarios!A2 -> Baseline | C22: ='Cases Data'!B6 * Scenarios!D2 -> 8570000 | D22: ='Cases Data'!C6 * Scenarios!B2 * Scenarios!D2 -> 1071803.5 | E22: ='Cases Data'!D6 * Scenarios!D2 -> 131000 | F22: =D22 - E22 -> 940803.52 | G22: ='Cases Data'!F6 -> 6770300 | H22: ='Cases Data'!G6 -> 1799700 | I22: ='Cases Data'!H6 -> 0 | J22: =(I22 + H22) * (1 - Scenarios!E2) -> 0 | K22: =G22 * Scenarios!D2 + 0.7 * J22 -> 6770300 | L22: =H22 * Scenarios!E2 -> 1799700 | M22: =I22 * Scenarios!E2 -> 0 | N22: ='Cases Data'!J6 -> 0.087957 | O22: =N22 + Scenarios!C2 -> 0.087957 | P22: =IF(K22>0, PMT(INDIRECT(ADDRESS(ROW(),15)), 'Cases Data'!M6, -K22), 0) -> 935768.35 | Q22: =IF(L22>0, PMT('Cases Data'!K6, 'Cases Data'!N6, -L22), 0) -> 203051.89 | R22: =IF(M22>0, PMT('Cases Data'!L6, 'Cases Data'!O6, -M22), 0) -> 0 | S22: =P22 + Q22 + R22 -> 1138820.2 | T22: =IF(S22>0, F22 / S22, NA()) -> 0.82612118 | U22: ='Cases Data'!I6 -> 0 | V22: =F22 - S22 -> -198016.72 | W22: =U22 * Scenarios!D2 + 0.3 * J22 -> 0
A23: ='Cases Data'!A6 -> Case 5 | B23: =Scenarios!A3 -> Tariff -10% | C23: ='Cases Data'!B6 * Scenarios!D3 -> 8570000 | D23: ='Cases Data'!C6 * Scenarios!B3 * Scenarios!D3 -> 964623.17 | E23: ='Cases Data'!D6 * Scenarios!D3 -> 131000 | F23: =D23 - E23 -> 833623.17 | G23: ='Cases Data'!F6 -> 6770300 | H23: ='Cases Data'!G6 -> 1799700 | I23: ='Cases Data'!H6 -> 0 | J23: =(I23 + H23) * (1 - Scenarios!E3) -> 0 | K23: =G23 * Scenarios!D3 + 0.7 * J23 -> 6770300 | L23: =H23 * Scenarios!E3 -> 1799700 | M23: =I23 * Scenarios!E3 -> 0 | N23: ='Cases Data'!J6 -> 0.087957 | O23: =N23 + Scenarios!C3 -> 0.087957 | P23: =IF(K23>0, PMT(INDIRECT(ADDRESS(ROW(),15)), 'Cases Data'!M6, -K23), 0) -> 935768.35 | Q23: =IF(L23>0, PMT('Cases Data'!K6, 'Cases Data'!N6, -L23), 0) -> 203051.89 | R23: =IF(M23>0, PMT('Cases Data'!L6, 'Cases Data'!O6, -M23), 0) -> 0 | S23: =P23 + Q23 + R23 -> 1138820.2 | T23: =IF(S23>0, F23 / S23, NA()) -> 0.73200593 | U23: ='Cases Data'!I6 -> 0 | V23: =F23 - S23 -> -305197.07 | W23: =U23 * Scenarios!D3 + 0.3 * J23 -> 0
A24: ='Cases Data'!A6 -> Case 5 | B24: =Scenarios!A4 -> Senior +200bps | C24: ='Cases Data'!B6 * Scenarios!D4 -> 8570000 | D24: ='Cases Data'!C6 * Scenarios!B4 * Scenarios!D4 -> 1071803.5 | E24: ='Cases Data'!D6 * Scenarios!D4 -> 131000 | F24: =D24 - E24 -> 940803.52 | G24: ='Cases Data'!F6 -> 6770300 | H24: ='Cases Data'!G6 -> 1799700 | I24: ='Cases Data'!H6 -> 0 | J24: =(I24 + H24) * (1 - Scenarios!E4) -> 0 | K24: =G24 * Scenarios!D4 + 0.7 * J24 -> 6770300 | L24: =H24 * Scenarios!E4 -> 1799700 | M24: =I24 * Scenarios!E4 -> 0 | N24: ='Cases Data'!J6 -> 0.087957 | O24: =N24 + Scenarios!C4 -> 0.107957 | P24: =IF(K24>0, PMT(INDIRECT(ADDRESS(ROW(),15)), 'Cases Data'!M6, -K24), 0) -> 1032682.2 | Q24: =IF(L24>0, PMT('Cases Data'!K6, 'Cases Data'!N6, -L24), 0) -> 203051.89 | R24: =IF(M24>0, PMT('Cases Data'!L6, 'Cases Data'!O6, -M24), 0) -> 0 | S24: =P24 + Q24 + R24 -> 1235734.1 | T24: =IF(S24>0, F24 / S24, NA()) -> 0.76133166 | U24: ='Cases Data'!I6 -> 0 | V24: =F24 - S24 -> -294930.61 | W24: =U24 * Scenarios!D4 + 0.3 * J24 -> 0
A25: ='Cases Data'!A6 -> Case 5 | B25: =Scenarios!A5 -> CAPEX +20% | C25: ='Cases Data'!B6 * Scenarios!D5 -> 10284000 | D25: ='Cases Data'!C6 * Scenarios!B5 * Scenarios!D5 -> 1286164.2 | E25: ='Cases Data'!D6 * Scenarios!D5 -> 157200 | F25: =D25 - E25 -> 1128964.2 | G25: ='Cases Data'!F6 -> 6770300 | H25: ='Cases Data'!G6 -> 1799700 | I25: ='Cases Data'!H6 -> 0 | J25: =(I25 + H25) * (1 - Scenarios!E5) -> 0 | K25: =G25 * Scenarios!D5 + 0.7 * J25 -> 8124360 | L25: =H25 * Scenarios!E5 -> 1799700 | M25: =I25 * Scenarios!E5 -> 0 | N25: ='Cases Data'!J6 -> 0.087957 | O25: =N25 + Scenarios!C5 -> 0.087957 | P25: =IF(K25>0, PMT(INDIRECT(ADDRESS(ROW(),15)), 'Cases Data'!M6, -K25), 0) -> 1122922 | Q25: =IF(L25>0, PMT('Cases Data'!K6, 'Cases Data'!N6, -L25), 0) -> 203051.89 | R25: =IF(M25>0, PMT('Cases Data'!L6, 'Cases Data'!O6, -M25), 0) -> 0 | S25: =P25 + Q25 + R25 -> 1325973.9 | T25: =IF(S25>0, F25 / S25, NA()) -> 0.85142265 | U25: ='Cases Data'!I6 -> 0 | V25: =F25 - S25 -> -197009.69 | W25: =U25 * Scenarios!D5 + 0.3 * J25 -> 0
A26: ='Cases Data'!A6 -> Case 5 | B26: =Scenarios!A6 -> Concessional -50% | C26: ='Cases Data'!B6 * Scenarios!D6 -> 8570000 | D26: ='Cases Data'!C6 * Scenarios!B6 * Scenarios!D6 -> 1071803.5 | E26: ='Cases Data'!D6 * Scenarios!D6 -> 131000 | F26: =D26 - E26 -> 940803.52 | G26: ='Cases Data'!F6 -> 6770300 | H26: ='Cases Data'!G6 -> 1799700 | I26: ='Cases Data'!H6 -> 0 | J26: =(I26 + H26) * (1 - Scenarios!E6) -> 899850 | K26: =G26 * Scenarios!D6 + 0.7 * J26 -> 7400195 | L26: =H26 * Scenarios!E6 -> 899850 | M26: =I26 * Scenarios!E6 -> 0 | N26: ='Cases Data'!J6 -> 0.087957 | O26: =N26 + Scenarios!C6 -> 0.087957 | P26: =IF(K26>0, PMT(INDIRECT(ADDRESS(ROW(),15)), 'Cases Data'!M6, -K26), 0) -> 1022830.3 | Q26: =IF(L26>0, PMT('Cases Data'!K6, 'Cases Data'!N6, -L26), 0) -> 101525.95 | R26: =IF(M26>0, PMT('Cases Data'!L6, 'Cases Data'!O6, -M26), 0) -> 0 | S26: =P26 + Q26 + R26 -> 1124356.3 | T26: =IF(S26>0, F26 / S26, NA()) -> 0.83674857 | U26: ='Cases Data'!I6 -> 0 | V26: =F26 - S26 -> -183552.77 | W26: =U26 * Scenarios!D6 + 0.3 * J26 -> 269955

Sheet Inputs
A1: Name | B1: Value | C1: Source | D1: Rationale
A2: Project MW | B2: 10 | C2: Project definition (scaling assumption for analysis) | D2: 10 MW is a common reference size in SEA renewable projects, easy for comparison.
A3: CAPEX per kW USD | B3: 857 | C3: IRENA Renewable Power Generation Costs 2021 (Solar PV CAPEX, SEA avg) | D3: Provides realistic benchmark for SEA utility-scale solar; aligns with 2020–2022 data.
A4: OPEX per kW per year USD | B4: 13.1 | C4: IRENA REmap/O&M benchmark database | D4: Typical fixed O&M costs for solar PV in SEA; widely used in feasibility models.
A5: Capacity Factor | B5: 0.16 | C5: IRENA/ASEAN Renewable Energy statistics | D5: 16% CF is realistic for SEA solar (moderate irradiance vs. MENA/India).
A6: Hours per year | B6: 8760 | C6: Standard calendar assumption | D6: Always 365×24, used globally in generation modeling.
A7: Tariff USD per MWh | B7: 76.47 | C7: BloombergNEF / Climatescope 2021 SEA tariffs | D7: Reflects regional PPA tariffs for renewables (Indonesia/Vietnam range).
A8: Senior rate base | B8: 0.087957 | C8: World Bank Enterprise Survey lending rate data (Indonesia ~9%) | D8: Reflects commercial loan rates in SEA for infrastructure lending.
A9: Senior tenor years | B9: 12 | C9: Typical PF structure / World Bank/ADB lending tenor | D9: 12 years is a standard tenor acceptable for renewables in SEA.
A10: Junior rate base | B10: 0.05 | C10: MDB concessional finance averages (e.g., GCF/ADB blends) | D10: Reflects below-market rates typically offered by MDBs for climate finance.
A11: Junior tenor years | B11: 12 | C11: Concessional loan docs (ADB/GCF examples) | D11: Tenors often matched to senior loans for blended tranches.
A12: Public rate base | B12: 0.02 | C12: Public concessional funds (e.g., SDG Indonesia One anchor facilities) | D12: Illustrates deep concessional support seen in SDG One, GAIA junior tranches.
A13: Public tenor years | B13: 20 | C13: Long-tenor concessional loans (Green Climate Fund, KfW, JICA) | D13: Donor-backed concessional loans often run longer to improve affordability.
... A19: Depreciation USD per year | B19: 0 | C19: Not included in cashflow model (focus on CFADS/DSCR) | D19: Depreciation is non-cash; excluded for sensitivity analysis.

Sheet Scenarios
A1: Assumptions | B1: TariffMult | C1: SeniorRateAdd | D1: CAPEXMult | E1: ConcessionalMult
A2: Baseline | B2: 1 | C2: 0 | D2: 1 | E2: 1
A3: Tariff -10% | B3: 0.9 | C3: 0 | D3: 1 | E3: 1
A4: Senior +200bps | B4: 1 | C4: 0.02 | D4: 1 | E4: 1
A5: CAPEX +20% | B5: 1 | C5: 0 | D5: 1.2 | E5: 1
A6: Concessional -50% | B6: 1 | C6: 0 | D6: 1 | E6: 0.5
A8: TariffMult = 0.9 (−10%) | B8: A 10% drop in realized revenue (lower tariff or generation) is a typical downside stress used in PF models to test price/revenue risk. It’s big enough to show sensitivity but not extreme; many lenders request a tariff stress of 5–15% in their credit memos
A9: SeniorRateAdd = +0.02 (+200 bps) | B9: Interest-rate shocks are often modeled as +100–300 bps to capture market repricing or tightening. +200 bps is a common “stressed cost of debt” scenario to test debt-service resilience
A10: CAPEXMult = 1.2 (+20%) | B10: 20% cost overrun is a standard construction/contingency stress. It reflects realistic EPC risk and supply-chain inflation that projects experience
A11: ConcessionalMult = 0.5 (50%) | B11: Half of originally-expected concessional support (grants/subsidized loans/junior tranche) is not available. To demonstrates how crucial concessional layers are for bankability

Sheet Scenarios Def
A1: Option | B1: concess pct | C1: grant pct | D1: comm pct | E1: equity pct
A2: Option 1 | B2: 0.2 | C2: 0 | D2: 0.5 | E2: 0.3
A3: Option 2 | B3: 0 | C3: 0.3 | D3: 0.5 | E3: 0.2
A4: Option 3 | B4: 0.15 | C4: 0.15 | D4: 0.4 | E4: 0.3
A6: Option 1: (20/50/30) | B6: a typical blended structure where concessional debt provides a modest concessional layer (20%), commercial lenders fund a majority of debt (50%), and sponsor equity covers the rest (30). This mirrors many MDB-blended project templates
A8: Option 2: (30 grant / 50 commercial / 20 equity) | B8: shows a grant-heavy scenario - grant replaces a chunk of CAPEX so debt burden drops; used to illustrate best-case DSCR with donor support
A10: Option 3: (15/15/40/30) | B10: mixes grant + concessional + commercial; 15% concessional echoes anchor-first-loss examples (e.g., Pentagreen anchor ~15%), and 15% grant shows some donor support - this gives a resilient but complex stack

Sheet Scenarios Sensitivity
A1: Option | B1: Assumptions | C1: Concessional USD | D1: Grant USD | E1: Commercial USD | F1: Equity USD | G1: SeniorRate adj | H1: SeniorDS | I1: ConcessionalDS | J1: Total DS | K1: DSCR | L1: Cash After Debt
A2: ='Scenarios Def'!A2 -> Option 1 | B2: =Scenarios!A2 -> Baseline | C2: =Inputs!B14 * 'Scenarios Def'!B2 -> 1714000 | D2: =Inputs!B14 * 'Scenarios Def'!C2 -> 0 | E2: =Inputs!B14 * 'Scenarios Def'!D2 -> 4285000 | F2: =Inputs!B14 * 'Scenarios Def'!E2 -> 2571000 | G2: =Inputs!B8 + Scenarios!C2 -> 0.087957 | H2: =IF(E2>0, PMT(G2, Inputs!B9, -E2), 0) -> 592258.45 | I2: =IF(C2>0, PMT(Inputs!B10, Inputs!B11, -C2), 0) -> 193382.75 | J2: =H2 + I2 -> 785641.2 | K2: =IF(J2>0, ((Inputs!B2*Inputs!B5*Inputs!B6*Scenarios!B2) - (Inputs!B2*1000*Inputs!B4*Scenarios!D2)) / J2, NA()) -> -0.14890258 | L2: =((Inputs!B2*Inputs!B5*Inputs!B6*Scenarios!B2) - (Inputs!B2*1000*Inputs!B4*Scenarios!D2)) - J2 -> -902625.2
A3: ='Scenarios Def'!A2 -> Option 1 | B3: =Scenarios!A3 -> Tariff -10% | C3: =Inputs!B14 * 'Scenarios Def'!B2 -> 1714000 | D3: =Inputs!B14 * 'Scenarios Def'!C2 -> 0 | E3: =Inputs!B14 * 'Scenarios Def'!D2 -> 4285000 | F3: =Inputs!B14 * 'Scenarios Def'!E2 -> 2571000 | G3: =Inputs!B8 + Scenarios!C3 -> 0.087957 | H3: =IF(E3>0, PMT(G3, Inputs!B9, -E3), 0) -> 592258.45 | I3: =IF(C3>0, PMT(Inputs!B10, Inputs!B11, -C3), 0) -> 193382.75 | J3: =H3 + I3 -> 785641.2 | K3: =IF(J3>0, ((Inputs!B2*Inputs!B5*Inputs!B6*Scenarios!B3) - (Inputs!B2*1000*Inputs!B4*Scenarios!D3)) / J3, NA()) -> -0.1506866 | L3: =((Inputs!B2*Inputs!B5*Inputs!B6*Scenarios!B3) - (Inputs!B2*1000*Inputs!B4*Scenarios!D3)) - J3 -> -904026.8
A4: ='Scenarios Def'!A2 -> Option 1 | B4: =Scenarios!A4 -> Senior +200bps | C4: =Inputs!B14 * 'Scenarios Def'!B2 -> 1714000 | D4: =Inputs!B14 * 'Scenarios Def'!C2 -> 0 | E4: =Inputs!B14 * 'Scenarios Def'!D2 -> 4285000 | F4: =Inputs!B14 * 'Scenarios Def'!E2 -> 2571000 | G4: =Inputs!B8 + Scenarios!C4 -> 0.107957 | H4: =IF(E4>0, PMT(G4, Inputs!B9, -E4), 0) -> 653596.35 | I4: =IF(C4>0, PMT(Inputs!B10, Inputs!B11, -C4), 0) -> 193382.75 | J4: =H4 + I4 -> 846979.11 | K4: =IF(J4>0, ((Inputs!B2*Inputs!B5*Inputs!B6*Scenarios!B4) - (Inputs!B2*1000*Inputs!B4*Scenarios!D4)) / J4, NA()) -> -0.13811911 | L4: =((Inputs!B2*Inputs!B5*Inputs!B6*Scenarios!B4) - (Inputs!B2*1000*Inputs!B4*Scenarios!D4)) - J4 -> -963963.11
A5: ='Scenarios Def'!A2 -> Option 1 | B5: =Scenarios!A5 -> CAPEX +20% | C5: =Inputs!B14 * 'Scenarios Def'!B2 -> 1714000 | D5: =Inputs!B14 * 'Scenarios Def'!C2 -> 0 | E5: =Inputs!B14 * 'Scenarios Def'!D2 -> 4285000 | F5: =Inputs!B14 * 'Scenarios Def'!E2 -> 2571000 | G5: =Inputs!B8 + Scenarios!C5 -> 0.087957 | H5: =IF(E5>0, PMT(G5, Inputs!B9, -E5), 0) -> 592258.45 | I5: =IF(C5>0, PMT(Inputs!B10, Inputs!B11, -C5), 0) -> 193382.75 | J5: =H5 + I5 -> 785641.2 | K5: =IF(J5>0, ((Inputs!B2*Inputs!B5*Inputs!B6*Scenarios!B5) - (Inputs!B2*1000*Inputs!B4*Scenarios!D5)) / J5, NA()) -> -0.18225113 | L5: =((Inputs!B2*Inputs!B5*Inputs!B6*Scenarios!B5) - (Inputs!B2*1000*Inputs!B4*Scenarios!D5)) - J5 -> -928825.2
A6: ='Scenarios Def'!A2 -> Option 1 | B6: =Scenarios!A6 -> Concessional -50% | C6: =Inputs!B14 * 'Scenarios Def'!B2 -> 1714000 | D6: =Inputs!B14 * 'Scenarios Def'!C2 -> 0 | E6: =Inputs!B14 * 'Scenarios Def'!D2 -> 4285000 | F6: =Inputs!B14 * 'Scenarios Def'!E2 -> 2571000 | G6: =Inputs!B8 + Scenarios!C6 -> 0.087957 | H6: =IF(E6>0, PMT(G6, Inputs!B9, -E6), 0) -> 592258.45 | I6: =IF(C6>0, PMT(Inputs!B10, Inputs!B11, -C6), 0) -> 193382.75 | J6: =H6 + I6 -> 785641.2 | K6: =IF(J6>0, ((Inputs!B2*Inputs!B5*Inputs!B6*Scenarios!B6) - (Inputs!B2*1000*Inputs!B4*Scenarios!D6)) / J6, NA()) -> -0.14890258 | L6: =((Inputs!B2*Inputs!B5*Inputs!B6*Scenarios!B6) - (Inputs!B2*1000*Inputs!B4*Scenarios!D6)) - J6 -> -902625.2
A7: ='Scenarios Def'!A3 -> Option 2 | B7: =Scenarios!A2 -> Baseline | C7: =Inputs!B14 * 'Scenarios Def'!B3 -> 0 | D7: =Inputs!B14 * 'Scenarios Def'!C3 -> 2571000 | E7: =Inputs!B14 * 'Scenarios Def'!D3 -> 4285000 | F7: =Inputs!B14 * 'Scenarios Def'!E3 -> 1714000 | G7: =Inputs!B8 + Scenarios!C2 -> 0.087957 | H7: =IF(E7>0, PMT(G7, Inputs!B9, -E7), 0) -> 592258.45 | I7: =IF(C7>0, PMT(Inputs!B10, Inputs!B11, -C7), 0) -> 0 | J7: =H7 + I7 -> 592258.45 | K7: =IF(J7>0, ((Inputs!B2*Inputs!B5*Inputs!B6*Scenarios!B2) - (Inputs!B2*1000*Inputs!B4*Scenarios!D2)) / J7, NA()) -> -0.19752188 | L7: =((Inputs!B2*Inputs!B5*Inputs!B6*Scenarios!B2) - (Inputs!B2*1000*Inputs!B4*Scenarios!D2)) - J7 -> -709242.45
A8: ='Scenarios Def'!A3 -> Option 2 | B8: =Scenarios!A3 -> Tariff -10% | C8: =Inputs!B14 * 'Scenarios Def'!B3 -> 0 | D8: =Inputs!B14 * 'Scenarios Def'!C3 -> 2571000 | E8: =Inputs!B14 * 'Scenarios Def'!D3 -> 4285000 | F8: =Inputs!B14 * 'Scenarios Def'!E3 -> 1714000 | G8: =Inputs!B8 + Scenarios!C3 -> 0.087957 | H8: =IF(E8>0, PMT(G8, Inputs!B9, -E8), 0) -> 592258.45 | I8: =IF(C8>0, PMT(Inputs!B10, Inputs!B11, -C8), 0) -> 0 | J8: =H8 + I8 -> 592258.45 | K8: =IF(J8>0, ((Inputs!B2*Inputs!B5*Inputs!B6*Scenarios!B3) - (Inputs!B2*1000*Inputs!B4*Scenarios!D3)) / J8, NA()) -> -0.19988841 | L8: =((Inputs!B2*Inputs!B5*Inputs!B6*Scenarios!B3) - (Inputs!B2*1000*Inputs!B4*Scenarios!D3)) - J8 -> -710644.05
A9: ='Scenarios Def'!A3 -> Option 2 | B9: =Scenarios!A4 -> Senior +200bps | C9: =Inputs!B14 * 'Scenarios Def'!B3 -> 0 | D9: =Inputs!B14 * 'Scenarios Def'!C3 -> 2571000 | E9: =Inputs!B14 * 'Scenarios Def'!D3 -> 4285000 | F9: =Inputs!B14 * 'Scenarios Def'!E3 -> 1714000 | G9: =Inputs!B8 + Scenarios!C4 -> 0.107957 | H9: =IF(E9>0, PMT(G9, Inputs!B9, -E9), 0) -> 653596.35 | I9: =IF(C9>0, PMT(Inputs!B10, Inputs!B11, -C9), 0) -> 0 | J9: =H9 + I9 -> 653596.35 | K9: =IF(J9>0, ((Inputs!B2*Inputs!B5*Inputs!B6*Scenarios!B4) - (Inputs!B2*1000*Inputs!B4*Scenarios!D4)) / J9, NA()) -> -0.17898509 | L9: =((Inputs!B2*Inputs!B5*Inputs!B6*Scenarios!B4) - (Inputs!B2*1000*Inputs!B4*Scenarios!D4)) - J9 -> -770580.35
A10: ='Scenarios Def'!A3 -> Option 2 | B10: =Scenarios!A5 -> CAPEX +20% | C10: =Inputs!B14 * 'Scenarios Def'!B3 -> 0 | D10: =Inputs!B14 * 'Scenarios Def'!C3 -> 2571000 | E10: =Inputs!B14 * 'Scenarios Def'!D3 -> 4285000 | F10: =Inputs!B14 * 'Scenarios Def'!E3 -> 1714000 | G10: =Inputs!B8 + Scenarios!C5 -> 0.087957 | H10: =IF(E10>0, PMT(G10, Inputs!B9, -E10), 0) -> 592258.45 | I10: =IF(C10>0, PMT(Inputs!B10, Inputs!B11, -C10), 0) -> 0 | J10: =H10 + I10 -> 592258.45 | K10: =IF(J10>0, ((Inputs!B2*Inputs!B5*Inputs!B6*Scenarios!B5) - (Inputs!B2*1000*Inputs!B4*Scenarios!D5)) / J10, NA()) -> -0.24175932 | L10: =((Inputs!B2*Inputs!B5*Inputs!B6*Scenarios!B5) - (Inputs!B2*1000*Inputs!B4*Scenarios!D5)) - J10 -> -735442.45
A11: ='Scenarios Def'!A3 -> Option 2 | B11: =Scenarios!A6 -> Concessional -50% | C11: =Inputs!B14 * 'Scenarios Def'!B3 -> 0 | D11: =Inputs!B14 * 'Scenarios Def'!C3 -> 2571000 | E11: =Inputs!B14 * 'Scenarios Def'!D3 -> 4285000 | F11: =Inputs!B14 * 'Scenarios Def'!E3 -> 1714000 | G11: =Inputs!B8 + Scenarios!C6 -> 0.087957 | H11: =IF(E11>0, PMT(G11, Inputs!B9, -E11), 0) -> 592258.45 | I11: =IF(C11>0, PMT(Inputs!B10, Inputs!B11, -C11), 0) -> 0 | J11: =H11 + I11 -> 592258.45 | K11: =IF(J11>0, ((Inputs!B2*Inputs!B5*Inputs!B6*Scenarios!B6) - (Inputs!B2*1000*Inputs!B4*Scenarios!D6)) / J11, NA()) -> -0.19752188 | L11: =((Inputs!B2*Inputs!B5*Inputs!B6*Scenarios!B6) - (Inputs!B2*1000*Inputs!B4*Scenarios!D6)) - J11 -> -709242.45
A12: ='Scenarios Def'!A4 -> Option 3 | B12: =Scenarios!A2 -> Baseline | C12: =Inputs!B14 * 'Scenarios Def'!B4 -> 1285500 | D12: =Inputs!B14 * 'Scenarios Def'!C4 -> 1285500 | E12: =Inputs!B14 * 'Scenarios Def'!D4 -> 3428000 | F12: =Inputs!B14 * 'Scenarios Def'!E4 -> 2571000 | G12: =Inputs!B8 + Scenarios!C2 -> 0.087957 | H12: =IF(E12>0, PMT(G12, Inputs!B9, -E12), 0) -> 473806.76 | I12: =IF(C12>0, PMT(Inputs!B10, Inputs!B11, -C12), 0) -> 145037.06 | J12: =H12 + I12 -> 618843.82 | K12: =IF(J12>0, ((Inputs!B2*Inputs!B5*Inputs!B6*Scenarios!B2) - (Inputs!B2*1000*Inputs!B4*Scenarios!D2)) / J12, NA()) -> -0.18903639 | L12: =((Inputs!B2*Inputs!B5*Inputs!B6*Scenarios!B2) - (Inputs!B2*1000*Inputs!B4*Scenarios!D2)) - J12 -> -735827.82
A13: ='Scenarios Def'!A4 -> Option 3 | B13: =Scenarios!A3 -> Tariff -10% | C13: =Inputs!B14 * 'Scenarios Def'!B4 -> 1285500 | D13: =Inputs!B14 * 'Scenarios Def'!C4 -> 1285500 | E13: =Inputs!B14 * 'Scenarios Def'!D4 -> 3428000 | F13: =Inputs!B14 * 'Scenarios Def'!E4 -> 2571000 | G13: =Inputs!B8 + Scenarios!C3 -> 0.087957 | H13: =IF(E13>0, PMT(G13, Inputs!B9, -E13), 0) -> 473806.76 | I13: =IF(C13>0, PMT(Inputs!B10, Inputs!B11, -C13), 0) -> 145037.06 | J13: =H13 + I13 -> 618843.82 | K13: =IF(J13>0, ((Inputs!B2*Inputs!B5*Inputs!B6*Scenarios!B3) - (Inputs!B2*1000*Inputs!B4*Scenarios!D3)) / J13, NA()) -> -0.19130125 | L13: =((Inputs!B2*Inputs!B5*Inputs!B6*Scenarios!B3) - (Inputs!B2*1000*Inputs!B4*Scenarios!D3)) - J13 -> -737229.42
A14: ='Scenarios Def'!A4 -> Option 3 | B14: =Scenarios!A4 -> Senior +200bps | C14: =Inputs!B14 * 'Scenarios Def'!B4 -> 1285500 | D14: =Inputs!B14 * 'Scenarios Def'!C4 -> 1285500 | E14: =Inputs!B14 * 'Scenarios Def'!D4 -> 3428000 | F14: =Inputs!B14 * 'Scenarios Def'!E4 -> 2571000 | G14: =Inputs!B8 + Scenarios!C4 -> 0.107957 | H14: =IF(E14>0, PMT(G14, Inputs!B9, -E14), 0) -> 522877.08 | I14: =IF(C14>0, PMT(Inputs!B10, Inputs!B11, -C14), 0) -> 145037.06 | J14: =H14 + I14 -> 667914.15 | K14: =IF(J14>0, ((Inputs!B2*Inputs!B5*Inputs!B6*Scenarios!B4) - (Inputs!B2*1000*Inputs!B4*Scenarios!D4)) / J14, NA()) -> -0.17514826 | L14: =((Inputs!B2*Inputs!B5*Inputs!B6*Scenarios!B4) - (Inputs!B2*1000*Inputs!B4*Scenarios!D4)) - J14 -> -784898.15
A15: ='Scenarios Def'!A4 -> Option 3 | B15: =Scenarios!A5 -> CAPEX +20% | C15: =Inputs!B14 * 'Scenarios Def'!B4 -> 1285500 | D15: =Inputs!B14 * 'Scenarios Def'!C4 -> 1285500 | E15: =Inputs!B14 * 'Scenarios Def'!D4 -> 3428000 | F15: =Inputs!B14 * 'Scenarios Def'!E4 -> 2571000 | G15: =Inputs!B8 + Scenarios!C5 -> 0.087957 | H15: =IF(E15>0, PMT(G15, Inputs!B9, -E15), 0) -> 473806.76 | I15: =IF(C15>0, PMT(Inputs!B10, Inputs!B11, -C15), 0) -> 145037.06 | J15: =H15 + I15 -> 618843.82 | K15: =IF(J15>0, ((Inputs!B2*Inputs!B5*Inputs!B6*Scenarios!B5) - (Inputs!B2*1000*Inputs!B4*Scenarios!D5)) / J15, NA()) -> -0.2313734 | L15: =((Inputs!B2*Inputs!B5*Inputs!B6*Scenarios!B5) - (Inputs!B2*1000*Inputs!B4*Scenarios!D5)) - J15 -> -762027.82
A16: ='Scenarios Def'!A4 -> Option 3 | B16: =Scenarios!A6 -> Concessional -50% | C16: =Inputs!B14 * 'Scenarios Def'!B4 -> 1285500 | D16: =Inputs!B14 * 'Scenarios Def'!C4 -> 1285500 | E16: =Inputs!B14 * 'Scenarios Def'!D4 -> 3428000 | F16: =Inputs!B14 * 'Scenarios Def'!E4 -> 2571000 | G16: =Inputs!B8 + Scenarios!C6 -> 0.087957 | H16: =IF(E16>0, PMT(G16, Inputs!B9, -E16), 0) -> 473806.76 | I16: =IF(C16>0, PMT(Inputs!B10, Inputs!B11, -C16), 0) -> 145037.06 | J16: =H16 + I16 -> 618843.82 | K16: =IF(J16>0, ((Inputs!B2*Inputs!B5*Inputs!B6*Scenarios!B6) - (Inputs!B2*1000*Inputs!B4*Scenarios!D6)) / J16, NA()) -> -0.18903639 | L16: =((Inputs!B2*Inputs!B5*Inputs!B6*Scenarios!B6) - (Inputs!B2*1000*Inputs!B4*Scenarios!D6)) - J16 -> -735827.82

Sheet Option 1
A1: Assumption | B1: Baseline | C1: Tariff -10% | D1: Senior +200bps | E1: CAPEX +20% | F1: Concessional -50%
A2: Sales (Revenue) | B2: =Inputs!$B$2*Inputs!$B$5*Inputs!$B$6*Inputs!$B$7*Scenarios!B2 -> 1071803.5 | C2: =Inputs!$B$2*Inputs!$B$5*Inputs!$B$6*Inputs!$B$7*Scenarios!B3 -> 964623.17 | D2: =Inputs!$B$2*Inputs!$B$5*Inputs!$B$6*Inputs!$B$7*Scenarios!B4 -> 1071803.5 | E2: =Inputs!$B$2*Inputs!$B$5*Inputs!$B$6*Inputs!$B$7*Scenarios!B5 -> 1071803.5 | F2: =Inputs!$B$2*Inputs!$B$5*Inputs!$B$6*Inputs!$B$7*Scenarios!B6 -> 1071803.5
A3: Cost of sales (O&M) | B3: =Inputs!$B$2*1000*Inputs!$B$4*Scenarios!D2 -> 131000 | C3: =Inputs!$B$2*1000*Inputs!$B$4*Scenarios!D3 -> 131000 | D3: =Inputs!$B$2*1000*Inputs!$B$4*Scenarios!D4 -> 131000 | E3: =Inputs!$B$2*1000*Inputs!$B$4*Scenarios!D5 -> 157200 | F3: =Inputs!$B$2*1000*Inputs!$B$4*Scenarios!D6 -> 131000
A4: Gross margin | B4: =B$2 - B$3 -> 940803.52 | C4: =C$2 - C$3 -> 833623.17 | D4: =D$2 - D$3 -> 940803.52 | E4: =E$2 - E$3 -> 914603.52 | F4: =F$2 - F$3 -> 940803.52
A5: Wages & Salaries | B5: =Inputs!$B$14 * Scenarios!D2 -> 8570000 | C5: =Inputs!$B$14 * Scenarios!D3 -> 8570000 | D5: =Inputs!$B$14 * Scenarios!D4 -> 8570000 | E5: =Inputs!$B$14 * Scenarios!D5 -> 10284000 | F5: =Inputs!$B$14 * Scenarios!D6 -> 8570000
A6: Sales and marketing | B6: =Inputs!$B$15 * Scenarios!D2 -> 50000 | C6: =Inputs!$B$15 * Scenarios!D3 -> 50000 | D6: =Inputs!$B$15 * Scenarios!D4 -> 50000 | E6: =Inputs!$B$15 * Scenarios!D5 -> 60000 | F6: =Inputs!$B$15 * Scenarios!D6 -> 50000
A7: Administration expenses | B7: =Inputs!$B$16 * Scenarios!D2 -> 6000 | C7: =Inputs!$B$16 * Scenarios!D3 -> 6000 | D7: =Inputs!$B$16 * Scenarios!D4 -> 6000 | E7: =Inputs!$B$16 * Scenarios!D5 -> 7200 | F7: =Inputs!$B$16 * Scenarios!D6 -> 6000
A8: Operating expenses (total) | B8: =(B$5 + B$6 + B$7 + Inputs!$B$17 * Scenarios!D2) -> 8632000 | C8: =(C$5 + C$6 + C$7 + Inputs!$B$17 * Scenarios!D3) -> 8632000 | D8: =(D$5 + D$6 + D$7 + Inputs!$B$17 * Scenarios!D4) -> 8632000 | E8: =(E$5 + E$6 + E$7 + Inputs!$B$17 * Scenarios!D5) -> 10358400 | F8: =(F$5 + F$6 + F$7 + Inputs!$B$17 * Scenarios!D6) -> 8632000
A9: Depreciation | B9: =Inputs!$B$18 * Scenarios!D2 -> 30000 | C9: =Inputs!$B$18 * Scenarios!D3 -> 30000 | D9: =Inputs!$B$18 * Scenarios!D4 -> 30000 | E9: =Inputs!$B$18 * Scenarios!D5 -> 36000 | F9: =Inputs!$B$18 * Scenarios!D6 -> 30000
A10: Operating income | B10: =B$4 - B$8 -> -7691196.5 | C10: =C$4 - C$8 -> -7798376.8 | D10: =D$4 - D$8 -> -7691196.5 | E10: =E$4 - E$8 -> -9443796.5 | F10: =F$4 - F$8 -> -7691196.5
A11: Interest on loans (total debt service) | B11: =IF(Inputs!$B$14*'Scenarios Def'!D2>0, PMT(B$19, Inputs!$B$9, -Inputs!$B$14*'Scenarios Def'!D2), 0) -> 592258.45 | C11: =IF(Inputs!$B$14*'Scenarios Def'!D2>0, PMT(C$19, Inputs!$B$9, -Inputs!$B$14*'Scenarios Def'!D2), 0) -> 592258.45 | D11: =IF(Inputs!$B$14*'Scenarios Def'!D2>0, PMT(D$19, Inputs!$B$9, -Inputs!$B$14*'Scenarios Def'!D2), 0) -> 653596.35 | E11: =IF(Inputs!$B$14*'Scenarios Def'!D2>0, PMT(E$19, Inputs!$B$9, -Inputs!$B$14*'Scenarios Def'!D2), 0) -> 592258.45 | F11: =IF(Inputs!$B$14*'Scenarios Def'!D2>0, PMT(F$19, Inputs!$B$9, -Inputs!$B$14*'Scenarios Def'!D2), 0) -> 592258.45
A12: Net profit before tax | B12: =Inputs!$B$14 * 'Scenarios Def'!D2 -> 4285000 | C12: =Inputs!$B$14 * 'Scenarios Def'!D2 -> 4285000 | D12: =Inputs!$B$14 * 'Scenarios Def'!D2 -> 4285000 | E12: =Inputs!$B$14 * 'Scenarios Def'!D2 -> 4285000 | F12: =Inputs!$B$14 * 'Scenarios Def'!D2 -> 4285000
A13: Senior debt service (commercial) | B13: =Inputs!$B$14 * 'Scenarios Def'!B2 -> 1714000 | C13: =Inputs!$B$14 * 'Scenarios Def'!B2 -> 1714000 | D13: =Inputs!$B$14 * 'Scenarios Def'!B2 -> 1714000 | E13: =Inputs!$B$14 * 'Scenarios Def'!B2 -> 1714000 | F13: =Inputs!$B$14 * 'Scenarios Def'!B2 -> 1714000
A14: Concessional debt service | B14: =IF(Inputs!$B$14*'Scenarios Def'!B2>0, PMT(Inputs!$B$12, Inputs!$B$13, -Inputs!$B$14*'Scenarios Def'!B2), 0) -> 104822.61 | C14: =IF(Inputs!$B$14*'Scenarios Def'!B2>0, PMT(Inputs!$B$12, Inputs!$B$13, -Inputs!$B$14*'Scenarios Def'!B2), 0) -> 104822.61 | D14: =IF(Inputs!$B$14*'Scenarios Def'!B2>0, PMT(Inputs!$B$12, Inputs!$B$13, -Inputs!$B$14*'Scenarios Def'!B2), 0) -> 104822.61 | E14: =IF(Inputs!$B$14*'Scenarios Def'!B2>0, PMT(Inputs!$B$12, Inputs!$B$13, -Inputs!$B$14*'Scenarios Def'!B2), 0) -> 104822.61 | F14: =IF(Inputs!$B$14*'Scenarios Def'!B2>0, PMT(Inputs!$B$12, Inputs!$B$13, -Inputs!$B$14*'Scenarios Def'!B2), 0) -> 104822.61
A15: CAPEX (total) | B15: =B$10 - (B$11 + B$14) -> -8388277.5 | C15: =C$10 - (C$11 + C$14) -> -8495457.9 | D15: =D$10 - (D$11 + D$14) -> -8449615.4 | E15: =E$10 - (E$11 + E$14) -> -10140878 | F15: =F$10 - (F$11 + F$14) -> -8388277.5
A16: Concessional amount (principal) | B16: =Inputs!$B$14 * 'Scenarios Def'!D2 -> 4285000 | C16: =Inputs!$B$14 * 'Scenarios Def'!D2 -> 4285000 | D16: =Inputs!$B$14 * 'Scenarios Def'!D2 -> 4285000 | E16: =Inputs!$B$14 * 'Scenarios Def'!D2 -> 4285000 | F16: =Inputs!$B$14 * 'Scenarios Def'!D2 -> 4285000
A17: Commercial amount (principal) | B17: =Inputs!$B$14 * 'Scenarios Def'!E2 -> 2571000 | C17: =Inputs!$B$14 * 'Scenarios Def'!E2 -> 2571000 | D17: =Inputs!$B$14 * 'Scenarios Def'!E2 -> 2571000 | E17: =Inputs!$B$14 * 'Scenarios Def'!E2 -> 2571000 | F17: =Inputs!$B$14 * 'Scenarios Def'!E2 -> 2571000
A18: Equity amount (sponsor) | B18: =Inputs!$B$14 * 'Scenarios Def'!C2 -> 0 | C18: =Inputs!$B$14 * 'Scenarios Def'!C2 -> 0 | D18: =Inputs!$B$14 * 'Scenarios Def'!C2 -> 0 | E18: =Inputs!$B$14 * 'Scenarios Def'!C2 -> 0 | F18: =Inputs!$B$14 * 'Scenarios Def'!C2 -> 0
A19: Grant amount | B19: =Inputs!$B$8 + Scenarios!C2 -> 0.087957 | C19: =Inputs!$B$8 + Scenarios!C3 -> 0.087957 | D19: =Inputs!$B$8 + Scenarios!C4 -> 0.107957 | E19: =Inputs!$B$8 + Scenarios!C5 -> 0.087957 | F19: =Inputs!$B$8 + Scenarios!C6 -> 0.087957

Sheet Option 2
A1: Assumption | B1: Baseline | C1: Tariff -10% | D1: Senior +200bps | E1: CAPEX +20% | F1: Concessional -50%
A2: Sales (Revenue) | B2: =Inputs!$B$2*Inputs!$B$5*Inputs!$B$6*Inputs!$B$7*Scenarios!B2 -> 1071803.5 | C2: =Inputs!$B$2*Inputs!$B$5*Inputs!$B$6*Inputs!$B$7*Scenarios!B3 -> 964623.17 | D2: =Inputs!$B$2*Inputs!$B$5*Inputs!$B$6*Inputs!$B$7*Scenarios!B4 -> 1071803.5 | E2: =Inputs!$B$2*Inputs!$B$5*Inputs!$B$6*Inputs!$B$7*Scenarios!B5 -> 1071803.5 | F2: =Inputs!$B$2*Inputs!$B$5*Inputs!$B$6*Inputs!$B$7*Scenarios!B6 -> 1071803.5
A3: Cost of sales (O&M) | B3: =Inputs!$B$2*1000*Inputs!$B$4*Scenarios!D2 -> 131000 | C3: =Inputs!$B$2*1000*Inputs!$B$4*Scenarios!D3 -> 131000 | D3: =Inputs!$B$2*1000*Inputs!$B$4*Scenarios!D4 -> 131000 | E3: =Inputs!$B$2*1000*Inputs!$B$4*Scenarios!D5 -> 157200 | F3: =Inputs!$B$2*1000*Inputs!$B$4*Scenarios!D6 -> 131000
A4: Gross margin | B4: =B$2 - B$3 -> 940803.52 | C4: =C$2 - C$3 -> 833623.17 | D4: =D$2 - D$3 -> 940803.52 | E4: =E$2 - E$3 -> 914603.52 | F4: =F$2 - F$3 -> 940803.52
A5: Wages & Salaries | B5: =Inputs!$B$14 * Scenarios!D2 -> 8570000 | C5: =Inputs!$B$14 * Scenarios!D3 -> 8570000 | D5: =Inputs!$B$14 * Scenarios!D4 -> 8570000 | E5: =Inputs!$B$14 * Scenarios!D5 -> 10284000 | F5: =Inputs!$B$14 * Scenarios!D6 -> 8570000
A6: Sales and marketing | B6: =Inputs!$B$15 * Scenarios!D2 -> 50000 | C6: =Inputs!$B$15 * Scenarios!D3 -> 50000 | D6: =Inputs!$B$15 * Scenarios!D4 -> 50000 | E6: =Inputs!$B$15 * Scenarios!D5 -> 60000 | F6: =Inputs!$B$15 * Scenarios!D6 -> 50000
A7: Administration expenses | B7: =Inputs!$B$16 * Scenarios!D2 -> 6000 | C7: =Inputs!$B$16 * Scenarios!D3 -> 6000 | D7: =Inputs!$B$16 * Scenarios!D4 -> 6000 | E7: =Inputs!$B$16 * Scenarios!D5 -> 7200 | F7: =Inputs!$B$16 * Scenarios!D6 -> 6000
A8: Operating expenses (total) | B8: =(B$5 + B$6 + B$7 + Inputs!$B$17 * Scenarios!D2) -> 8632000 | C8: =(C$5 + C$6 + C$7 + Inputs!$B$17 * Scenarios!D3) -> 8632000 | D8: =(D$5 + D$6 + D$7 + Inputs!$B$17 * Scenarios!D4) -> 8632000 | E8: =(E$5 + E$6 + E$7 + Inputs!$B$17 * Scenarios!D5) -> 10358400 | F8: =(F$5 + F$6 + F$7 + Inputs!$B$17 * Scenarios!D6) -> 8632000
A9: Depreciation | B9: =Inputs!$B$18 * Scenarios!D2 -> 30000 | C9: =Inputs!$B$18 * Scenarios!D3 -> 30000 | D9: =Inputs!$B$18 * Scenarios!D4 -> 30000 | E9: =Inputs!$B$18 * Scenarios!D5 -> 36000 | F9: =Inputs!$B$18 * Scenarios!D6 -> 30000
A10: Operating income | B10: =B$4 - B$8 -> -7691196.5 | C10: =C$4 - C$8 -> -7798376.8 | D10: =D$4 - D$8 -> -7691196.5 | E10: =E$4 - E$8 -> -9443796.5 | F10: =F$4 - F$8 -> -7691196.5
A11: Interest on loans (total debt service) | B11: =IF(Inputs!$B$14*'Scenarios Def'!D3>0, PMT(B$19, Inputs!$B$9, -Inputs!$B$14*'Scenarios Def'!D3), 0) -> 592258.45 | C11: =IF(Inputs!$B$14*'Scenarios Def'!D3>0, PMT(C$19, Inputs!$B$9, -Inputs!$B$14*'Scenarios Def'!D3), 0) -> 592258.45 | D11: =IF(Inputs!$B$14*'Scenarios Def'!D3>0, PMT(D$19, Inputs!$B$9, -Inputs!$B$14*'Scenarios Def'!D3), 0) -> 653596.35 | E11: =IF(Inputs!$B$14*'Scenarios Def'!D3>0, PMT(E$19, Inputs!$B$9, -Inputs!$B$14*'Scenarios Def'!D3), 0) -> 592258.45 | F11: =IF(Inputs!$B$14*'Scenarios Def'!D3>0, PMT(F$19, Inputs!$B$9, -Inputs!$B$14*'Scenarios Def'!D3), 0) -> 592258.45
A12: Net profit before tax | B12: =Inputs!$B$14 * 'Scenarios Def'!D3 -> 4285000 | C12: =Inputs!$B$14 * 'Scenarios Def'!D3 -> 4285000 | D12: =Inputs!$B$14 * 'Scenarios Def'!D3 -> 4285000 | E12: =Inputs!$B$14 * 'Scenarios Def'!D3 -> 4285000 | F12: =Inputs!$B$14 * 'Scenarios Def'!D3 -> 4285000
A13: Senior debt service (commercial) | B13: =Inputs!$B$14 * 'Scenarios Def'!B3 -> 0 | C13: =Inputs!$B$14 * 'Scenarios Def'!B3 -> 0 | D13: =Inputs!$B$14 * 'Scenarios Def'!B3 -> 0 | E13: =Inputs!$B$14 * 'Scenarios Def'!B3 -> 0 | F13: =Inputs!$B$14 * 'Scenarios Def'!B3 -> 0
A14: Concessional debt service | B14: =IF(Inputs!$B$14*'Scenarios Def'!B3>0, PMT(Inputs!$B$12, Inputs!$B$13, -Inputs!$B$14*'Scenarios Def'!B3), 0) -> 0 | C14: =IF(Inputs!$B$14*'Scenarios Def'!B3>0, PMT(Inputs!$B$12, Inputs!$B$13, -Inputs!$B$14*'Scenarios Def'!B3), 0) -> 0 | D14: =IF(Inputs!$B$14*'Scenarios Def'!B3>0, PMT(Inputs!$B$12, Inputs!$B$13, -Inputs!$B$14*'Scenarios Def'!B3), 0) -> 0 | E14: =IF(Inputs!$B$14*'Scenarios Def'!B3>0, PMT(Inputs!$B$12, Inputs!$B$13, -Inputs!$B$14*'Scenarios Def'!B3), 0) -> 0 | F14: =IF(Inputs!$B$14*'Scenarios Def'!B3>0, PMT(Inputs!$B$12, Inputs!$B$13, -Inputs!$B$14*'Scenarios Def'!B3), 0) -> 0
A15: CAPEX (total) | B15: =B$10 - (B$11 + B$14) -> -8283454.9 | C15: =C$10 - (C$11 + C$14) -> -8390635.3 | D15: =D$10 - (D$11 + D$14) -> -8344792.8 | E15: =E$10 - (E$11 + E$14) -> -10036055 | F15: =F$10 - (F$11 + F$14) -> -8283454.9
A16: Concessional amount (principal) | B16: =Inputs!$B$14 * 'Scenarios Def'!D3 -> 4285000 | C16: =Inputs!$B$14 * 'Scenarios Def'!D3 -> 4285000 | D16: =Inputs!$B$14 * 'Scenarios Def'!D3 -> 4285000 | E16: =Inputs!$B$14 * 'Scenarios Def'!D3 -> 4285000 | F16: =Inputs!$B$14 * 'Scenarios Def'!D3 -> 4285000
A17: Commercial amount (principal) | B17: =Inputs!$B$14 * 'Scenarios Def'!E3 -> 1714000 | C17: =Inputs!$B$14 * 'Scenarios Def'!E3 -> 1714000 | D17: =Inputs!$B$14 * 'Scenarios Def'!E3 -> 1714000 | E17: =Inputs!$B$14 * 'Scenarios Def'!E3 -> 1714000 | F17: =Inputs!$B$14 * 'Scenarios Def'!E3 -> 1714000
A18: Equity amount (sponsor) | B18: =Inputs!$B$14 * 'Scenarios Def'!C3 -> 2571000 | C18: =Inputs!$B$14 * 'Scenarios Def'!C3 -> 2571000 | D18: =Inputs!$B$14 * 'Scenarios Def'!C3 -> 2571000 | E18: =Inputs!$B$14 * 'Scenarios Def'!C3 -> 2571000 | F18: =Inputs!$B$14 * 'Scenarios Def'!C3 -> 2571000
A19: Grant amount | B19: =Inputs!$B$8 + Scenarios!C2 -> 0.087957 | C19: =Inputs!$B$8 + Scenarios!C3 -> 0.087957 | D19: =Inputs!$B$8 + Scenarios!C4 -> 0.107957 | E19: =Inputs!$B$8 + Scenarios!C5 -> 0.087957 | F19: =Inputs!$B$8 + Scenarios!C6 -> 0.087957

Sheet Option 3
A1: Assumption | B1: Baseline | C1: Tariff -10% | D1: Senior +200bps | E1: CAPEX +20% | F1: Concessional -50%
A2: Sales (Revenue) | B2: =Inputs!$B$2*Inputs!$B$5*Inputs!$B$6*Inputs!$B$7*Scenarios!B2 -> 1071803.5 | C2: =Inputs!$B$2*Inputs!$B$5*Inputs!$B$6*Inputs!$B$7*Scenarios!B3 -> 964623.17 | D2: =Inputs!$B$2*Inputs!$B$5*Inputs!$B$6*Inputs!$B$7*Scenarios!B4 -> 1071803.5 | E2: =Inputs!$B$2*Inputs!$B$5*Inputs!$B$6*Inputs!$B$7*Scenarios!B5 -> 1071803.5 | F2: =Inputs!$B$2*Inputs!$B$5*Inputs!$B$6*Inputs!$B$7*Scenarios!B6 -> 1071803.5
A3: Cost of sales (O&M) | B3: =Inputs!$B$2*1000*Inputs!$B$4*Scenarios!D2 -> 131000 | C3: =Inputs!$B$2*1000*Inputs!$B$4*Scenarios!D3 -> 131000 | D3: =Inputs!$B$2*1000*Inputs!$B$4*Scenarios!D4 -> 131000 | E3: =Inputs!$B$2*1000*Inputs!$B$4*Scenarios!D5 -> 157200 | F3: =Inputs!$B$2*1000*Inputs!$B$4*Scenarios!D6 -> 131000
A4: Gross margin | B4: =B$2 - B$3 -> 940803.52 | C4: =C$2 - C$3 -> 833623.17 | D4: =D$2 - D$3 -> 940803.52 | E4: =E$2 - E$3 -> 914603.52 | F4: =F$2 - F$3 -> 940803.52
A5: Wages & Salaries | B5: =Inputs!$B$14 * Scenarios!D2 -> 8570000 | C5: =Inputs!$B$14 * Scenarios!D3 -> 8570000 | D5: =Inputs!$B$14 * Scenarios!D4 -> 8570000 | E5: =Inputs!$B$14 * Scenarios!D5 -> 10284000 | F5: =Inputs!$B$14 * Scenarios!D6 -> 8570000
A6: Sales and marketing | B6: =Inputs!$B$15 * Scenarios!D2 -> 50000 | C6: =Inputs!$B$15 * Scenarios!D3 -> 50000 | D6: =Inputs!$B$15 * Scenarios!D4 -> 50000 | E6: =Inputs!$B$15 * Scenarios!D5 -> 60000 | F6: =Inputs!$B$15 * Scenarios!D6 -> 50000
A7: Administration expenses | B7: =Inputs!$B$16 * Scenarios!D2 -> 6000 | C7: =Inputs!$B$16 * Scenarios!D3 -> 6000 | D7: =Inputs!$B$16 * Scenarios!D4 -> 6000 | E7: =Inputs!$B$16 * Scenarios!D5 -> 7200 | F7: =Inputs!$B$16 * Scenarios!D6 -> 6000
A8: Operating expenses (total) | B8: =(B$5 + B$6 + B$7 + Inputs!$B$17 * Scenarios!D2) -> 8632000 | C8: =(C$5 + C$6 + C$7 + Inputs!$B$17 * Scenarios!D3) -> 8632000 | D8: =(D$5 + D$6 + D$7 + Inputs!$B$17 * Scenarios!D4) -> 8632000 | E8: =(E$5 + E$6 + E$7 + Inputs!$B$17 * Scenarios!D5) -> 10358400 | F8: =(F$5 + F$6 + F$7 + Inputs!$B$17 * Scenarios!D6) -> 8632000
A9: Depreciation | B9: =Inputs!$B$18 * Scenarios!D2 -> 30000 | C9: =Inputs!$B$18 * Scenarios!D3 -> 30000 | D9: =Inputs!$B$18 * Scenarios!D4 -> 30000 | E9: =Inputs!$B$18 * Scenarios!D5 -> 36000 | F9: =Inputs!$B$18 * Scenarios!D6 -> 30000
A10: Operating income | B10: =B$4 - B$8 -> -7691196.5 | C10: =C$4 - C$8 -> -7798376.8 | D10: =D$4 - D$8 -> -7691196.5 | E10: =E$4 - E$8 -> -9443796.5 | F10: =F$4 - F$8 -> -7691196.5
A11: Interest on loans (total debt service) | B11: =IF(Inputs!$B$14*'Scenarios Def'!D4>0, PMT(B$19, Inputs!$B$9, -Inputs!$B$14*'Scenarios Def'!D4), 0) -> 473806.76 | C11: =IF(Inputs!$B$14*'Scenarios Def'!D4>0, PMT(C$19, Inputs!$B$9, -Inputs!$B$14*'Scenarios Def'!D4), 0) -> 473806.76 | D11: =IF(Inputs!$B$14*'Scenarios Def'!D4>0, PMT(D$19, Inputs!$B$9, -Inputs!$B$14*'Scenarios Def'!D4), 0) -> 522877.08 | E11: =IF(Inputs!$B$14*'Scenarios Def'!D4>0, PMT(E$19, Inputs!$B$9, -Inputs!$B$14*'Scenarios Def'!D4), 0) -> 473806.76 | F11: =IF(Inputs!$B$14*'Scenarios Def'!D4>0, PMT(F$19, Inputs!$B$9, -Inputs!$B$14*'Scenarios Def'!D4), 0) -> 473806.76
A12: Net profit before tax | B12: =Inputs!$B$14 * 'Scenarios Def'!D4 -> 3428000 | C12: =Inputs!$B$14 * 'Scenarios Def'!D4 -> 3428000 | D12: =Inputs!$B$14 * 'Scenarios Def'!D4 -> 3428000 | E12: =Inputs!$B$14 * 'Scenarios Def'!D4 -> 3428000 | F12: =Inputs!$B$14 * 'Scenarios Def'!D4 -> 3428000
A13: Senior debt service (commercial) | B13: =Inputs!$B$14 * 'Scenarios Def'!B4 -> 1285500 | C13: =Inputs!$B$14 * 'Scenarios Def'!B4 -> 1285500 | D13: =Inputs!$B$14 * 'Scenarios Def'!B4 -> 1285500 | E13: =Inputs!$B$14 * 'Scenarios Def'!B4 -> 1285500 | F13: =Inputs!$B$14 * 'Scenarios Def'!B4 -> 1285500
A14: Concessional debt service | B14: =IF(Inputs!$B$14*'Scenarios Def'!B4>0, PMT(Inputs!$B$12, Inputs!$B$13, -Inputs!$B$14*'Scenarios Def'!B4), 0) -> 78616.961 | C14: =IF(Inputs!$B$14*'Scenarios Def'!B4>0, PMT(Inputs!$B$12, Inputs!$B$13, -Inputs!$B$14*'Scenarios Def'!B4), 0) -> 78616.961 | D14: =IF(Inputs!$B$14*'Scenarios Def'!B4>0, PMT(Inputs!$B$12, Inputs!$B$13, -Inputs!$B$14*'Scenarios Def'!B4), 0) -> 78616.961 | E14: =IF(Inputs!$B$14*'Scenarios Def'!B4>0, PMT(Inputs!$B$12, Inputs!$B$13, -Inputs!$B$14*'Scenarios Def'!B4), 0) -> 78616.961 | F14: =IF(Inputs!$B$14*'Scenarios Def'!B4>0, PMT(Inputs!$B$12, Inputs!$B$13, -Inputs!$B$14*'Scenarios Def'!B4), 0) -> 78616.961
A15: CAPEX (total) | B15: =B$10 - (B$11 + B$14) -> -8243620.2 | C15: =C$10 - (C$11 + C$14) -> -8350800.6 | D15: =D$10 - (D$11 + D$14) -> -8292690.5 | E15: =E$10 - (E$11 + E$14) -> -9996220.2 | F15: =F$10 - (F$11 + F$14) -> -8243620.2
A16: Concessional amount (principal) | B16: =Inputs!$B$14 * 'Scenarios Def'!D4 -> 3428000 | C16: =Inputs!$B$14 * 'Scenarios Def'!D4 -> 3428000 | D16: =Inputs!$B$14 * 'Scenarios Def'!D4 -> 3428000 | E16: =Inputs!$B$14 * 'Scenarios Def'!D4 -> 3428000 | F16: =Inputs!$B$14 * 'Scenarios Def'!D4 -> 3428000
A17: Commercial amount (principal) | B17: =Inputs!$B$14 * 'Scenarios Def'!E4 -> 2571000 | C17: =Inputs!$B$14 * 'Scenarios Def'!E4 -> 2571000 | D17: =Inputs!$B$14 * 'Scenarios Def'!E4 -> 2571000 | E17: =Inputs!$B$14 * 'Scenarios Def'!E4 -> 2571000 | F17: =Inputs!$B$14 * 'Scenarios Def'!E4 -> 2571000
A18: Equity amount (sponsor) | B18: =Inputs!$B$14 * 'Scenarios Def'!C4 -> 1285500 | C18: =Inputs!$B$14 * 'Scenarios Def'!C4 -> 1285500 | D18: =Inputs!$B$14 * 'Scenarios Def'!C4 -> 1285500 | E18: =Inputs!$B$14 * 'Scenarios Def'!C4 -> 1285500 | F18: =Inputs!$B$14 * 'Scenarios Def'!C4 -> 1285500
