Workbook
Name sales_yr1: Input!$N$9
Name assumed_debt_maturity_year: Input!$I$9
Name sub_notes_avg_int: Input!$I$44
Name sga_exp_ann_incr: Input!$N$14
Name other_curr_assets_ann_incr: Input!$N$26
Name mezzdebt_prepay: Input!$I$53
Name goodwill_intang_deductible: Depr_Amort!$N$6
Name assumed_debt_prepay: Input!$I$13
Name prepaids_ann_incr: Input!$N$24
Name inventories_ann_incr: Input!$N$22
Name capex_interval: Input!$N$38
Name other_exp_ann_incr: Input!$N$16
Name sub_notes_years_PIK: Input!$I$45
Name termloanB_avg_int: Input!$I$32
Name seller_notes_cou_rate: Input!$I$58
Name acc_recv_ann_incr: Input!$N$20
Name seller_notes_years_PIK: Input!$I$60
Name seller_notes_ann_repay: Input!$I$57
Name year1: Input!$N$46
Name termloanA_avg_int: Input!$I$24
Name termloanA_prepay: Input!$I$25
Name ebitda_multiple_range: Input!$N$53
Name tax_rate: Input!$N$45
Name cash_min_amt: Input!$N$42
Name acc_exp: Input!$N$32
Name assumed_debt_ann_repay: Input!$I$10
Name mezzdebt_maturity_year: Input!$I$49
Name termloanB_term_years: Input!$I$28
Name cogs_ann_incr: Input!$N$12
Name sub_notes_mat_yr: Input!$I$42
Name perpetuity_growth_rate: Input!$N$54
Name discount_rate_range: Input!$N$51
Name sales_ann_incr: Input!$N$10
Name pref_stock_retired_year: Input!$I$66
Name pref_stock_div: Input!$I$64
Name sub_notes_prepay: Input!$I$46
Name prepaids: Input!$N$23
Name termloanB_ann_repay: Input!$I$29
Name termloanA_cou_rate: Input!$I$23
Name termloanA_term_years: Input!$I$21
Name acc_payable_ann_incr: Input!$N$31
Name acc_payable: Input!$N$30
Name acc_recv: Input!$N$19
Name sub_notes_cou_rate: Input!$I$43
Name other_curr_assets: Input!$N$25
Name senior_notes_mat_yr: Input!$I$36
Name sga_exp: Input!$N$13
Name seller_notes_avg_int: Input!$I$59
Name revolver_limit: Input!$I$17
Name other_longterm_assets: Input!$N$27
Name perpetuity_growth_range: Input!$N$55
Name termloanB_prepay: Input!$I$33
Name ebitda_multiple: Input!$N$52
Name exit_year: IRR_Returns!$B$4
Name capex_start_year: Input!$N$37
Name termloanB_bulletyr_repayment: Input!$I$30
Name senior_notes_prepay: Input!$I$39
Name assumed_debt_avg_int: Input!$I$12
Name other_curr_liab: Input!$N$34
Name seller_notes_prepay: Input!$I$61

Sheet Input
A2: Leveraged Buyout (LBO) Model
A4: Input Values
A5: *Enter values in yellow cells.
A7: Estimated Cost of Deal: | G7: Debt Assumptions: | L7: Income/BS Assumptions:
A8: Curent Stock Price | C8: 6 | D8: $ amt | G8: =A26 -> Assumed Debt | L8: Income Statement:
A9: Offer Premium | C9: 0.1 | D9: % | G9: Maturity Year | I9: 9 | L9: Sales Year 1 | N9: 1100000 | O9: $ amt
A10: Offer Price Per Share | C10: =C8*(1+C9) -> 6.6 | D10: $ amt | G10: Annual Repayment | I10: =1/assumed_debt_maturity_year -> 0.11111111 | L10: Sales - Annual Increase | N10: 0.1 | O10: %
A11: No. of Shares outstanding | C11: 100000 | D11: nos. | G11: Coupon Rate | I11: 0.0425 | L11: Cost of goods sold | N11: 0.45 | O11: % of revenue
A12: Equity Purchase Price | C12: =C10*C11 -> 660000 | D12: $ amt | G12: Average Interest | I12: 1 | L12: =L11&" - Annual Increase" -> Cost of goods sold - Annual Increase | N12: 0.0025 | O12: %
G13: Optional Prepayment | I13: 1 | L13: SG&A expenses | N13: 0.14 | O13: % of revenue
A14: Existing Debt Retired | C14: =Bal_Sheet!C46-C15 -> 185000 | D14: $ amt | L14: =L13&" - Annual Increase" -> SG&A expenses - Annual Increase | N14: 0.005 | O14: %
A15: Assumed Debt | C15: 65000 | D15: $ amt | G15: =A27 -> Bank Revolver | L15: Other expenses | N15: 0.12 | O15: % of revenue
A16: Expensed Transaction Costs | C16: 2500 | D16: $ amt | G16: Coupon Rate | I16: 0.0475 | L16: =L15&" - Annual Increase" -> Other expenses - Annual Increase | N16: 0.0015 | O16: %
A17: Capitalized Financing Costs | C17: =E27*revolver_limit+SUMPRODUCT(C28:C33,E28:E33) -> 10887.5 | D17: $ amt | G17: Revolver limit | I17: 600000
A18: Cash Infusion | C18: 27500 | D18: $ amt | G18: Undrawn Commitment Fee | I18: 0.01 | L18: Balance Sheet:
L19: Accounts receivable | N19: 0.18 | O19: % of revenue
A20: Total Funds Requirement | C20: =SUM(C12,C14:C18) -> 950887.5 | D20: $ amt | G20: =A28 -> Term Loan "A" | L20: =L19&" - Annual Increase" -> Accounts receivable - Annual Increase | N20: 0.05 | O20: %
G21: Term Years | I21: 8 | L21: Inventories | N21: 0.2 | O21: % of COGS
G22: Annual Repayment | I22: =1/I21 -> 0.125 | L22: =L21&" - Annual Increase" -> Inventories - Annual Increase | N22: 0.04 | O22: %
A23: Sources of Funds: | G23: Coupon Rate | I23: 0.055 | L23: Prepaids | N23: 0.045 | O23: % of revenue
A24: Excess Cash | C24: =IF(cash_min=1,Bal_Sheet!C10-cash_min_amt,Bal_Sheet!C10) -> 5000 | D24: $ amt | G24: Average Interest | I24: 1 | L24: =L23&" - Annual Increase" -> Prepaids - Annual Increase | N24: 0.02 | O24: % | Q24: Financing | R24: Annual
A25: Debt: | E25: Fees | G25: Optional Prepayment | I25: 1 | L25: Other current assets | N25: 0.12 | O25: % of revenue | Q25: Costs | R25: Amortization
A26: =A15 -> Assumed Debt | C26: =C15 -> 65000 | D26: $ amt | L26: =L25&" - Annual Increase" -> Other current assets - Annual Increase | N26: 0.025 | O26: % | S26: Period (Yrs)
A27: Bank Revolver | C27: =C20-SUM(C24,C26,C28:C33,C35,C37:C39) -> 200887.5 | D27: $ amt | E27: 0.0075 | G27: =A29 -> Term Loan "B" | L27: Other long-term assets | N27: 0.04 | O27: % of revenue | Q27: =revolver_limit*E27 -> 4500 | R27: =Q27/S27 -> 450 | S27: 10
A28: Term Loan "A" | C28: 80000 | D28: $ amt | E28: 0.015 | G28: Term Years | I28: 11 | L28: =L27&" - Annual Increase" -> Other long-term assets - Annual Increase | N28: 0.005 | O28: % | Q28: =C28*E28 -> 1200 | R28: =Q28/I21 -> 150
A29: Term Loan "B" | C29: 55000 | D29: $ amt | E29: 0.0175 | G29: Annual Repayment | I29: 0.04 | Q29: =C29*E29 -> 962.5 | R29: =Q29/I28 -> 87.5
A30: Senior Notes | C30: 65000 | D30: $ amt | E30: 0.02 | G30: Bullet Year Repayment | I30: =1-(I28-1)*termloanB_ann_repay -> 0.6 | L30: Accounts payable | N30: 0.15 | O30: % of COGS plus inventory increase | Q30: =C30*E30 -> 1300 | R30: =Q30/senior_notes_mat_yr -> 144.44444
A31: Subordinated Notes | C31: 40000 | D31: $ amt | E31: 0.025 | G31: Coupon Rate | I31: 0.0525 | L31: =L30&" - Annual Increase" -> Accounts payable - Annual Increase | N31: 0.02 | O31: % | Q31: =C31*E31 -> 1000 | R31: =Q31/sub_notes_mat_yr -> 83.333333
A32: Mezzanine Debt | C32: 70000 | D32: $ amt | E32: 0.0275 | G32: Average Interest | I32: 1 | L32: Accrued expenses | N32: 0.06 | O32: % of revenue | Q32: =C32*E32 -> 1925 | R32: =Q32/mezzdebt_maturity_year -> 137.5
A33: Seller Notes | C33: 25000 | D33: $ amt | E33: 0 | G33: Optional Prepayment | I33: 1 | L33: =L32&" - Annual Increase" -> Accrued expenses - Annual Increase | N33: 0.015 | O33: % | Q33: =C33*E33 -> 0 | R33: =Q33/I56 -> 0
A34: Preferred: | L34: Other current liabilities | N34: 0.08 | O34: % of revenue | Q34: =SUM(Q27:Q33) -> 10887.5 | R34: =SUM(R27:R33) -> 1052.7778
A35: Preferred Stock | C35: 60000 | D35: $ amt | E35: 0.02 | G35: =A30 -> Senior Notes | L35: =L34&" - Annual Increase" -> Other current liabilities - Annual Increase | N35: 0.01 | O35: % | Q35: =C35*E35 -> 1200
A36: Equity: | G36: Maturity Year | I36: 9 | L36: Capex | N36: 0.1 | O36: % of revenue | Q36: =SUM(Q34:Q35) -> 12087.5
A37: Common - Sponsor Equity | C37: 220000 | D37: $ amt | G37: Coupon Rate | I37: 0.0425 | L37: Capex Start Year | N37: 1 | O37: in years
A38: Management Equity | C38: 40000 | D38: $ amt | G38: Average Interest | I38: 1 | L38: Capex Interval | N38: 1 | O38: in years
A39: New Equity | C39: 25000 | D39: $ amt | G39: Optional Prepayment | I39: 1
A40: Total | C40: =SUM(C24:C39) -> 950887.5 | D40: $ amt
G41: =A31 -> Subordinated Notes | L41: Other Assumptions:
G42: Maturity Year | I42: 12 | L42: Cash Minimum | N42: 50000 | O42: $ amt
A43: Goodwill / Bargain Purchase: | G43: Coupon Rate | I43: 0.045 | L43: On / Off | N43: 1 | O43: 1=On. 0=Off.
...

Sheet Inc_St
A2: Income Statements
A4: Year | D4: 2016 | E4: =D4+1 -> 2017 | F4: =E4+1 -> 2018 | G4: =F4+1 -> 2019 | H4: =G4+1 -> 2020 | I4: =H4+1 -> 2021 | J4: =I4+1 -> 2022 | K4: =J4+1 -> 2023 | L4: =K4+1 -> 2024 | M4: =L4+1 -> 2025
A5: Year No. | D5: 1 | E5: =D5+1 -> 2 | F5: =E5+1 -> 3 | G5: =F5+1 -> 4 | H5: =G5+1 -> 5 | I5: =H5+1 -> 6 | J5: =I5+1 -> 7 | K5: =J5+1 -> 8 | L5: =K5+1 -> 9 | M5: =L5+1 -> 10
A8: Net Sales | D8: =sales_yr1 -> 1100000 | E8: =D8*(1+sales_ann_incr) -> 1210000 | F8: =E8*(1+sales_ann_incr) -> 1331000 | G8: =F8*(1+sales_ann_incr) -> 1464100 | H8: =G8*(1+sales_ann_incr) -> 1610510 | I8: =H8*(1+sales_ann_incr) -> 1771561 | J8: =I8*(1+sales_ann_incr) -> 1948717.1 | K8: =J8*(1+sales_ann_incr) -> 2143588.8 | L8: =K8*(1+sales_ann_incr) -> 2357947.7 | M8: =L8*(1+sales_ann_incr) -> 2593742.5
A10: =Input!L11 -> Cost of goods sold | D10: =D8*cogs*(1+cogs_ann_incr)^(D5-1) -> 495000 | E10: =E8*cogs*(1+cogs_ann_incr)^(E5-1) -> 545861.25 | F10: =F8*cogs*(1+cogs_ann_incr)^(F5-1) -> 601948.49 | G10: =G8*cogs*(1+cogs_ann_incr)^(G5-1) -> 663798.7 | H10: =H8*cogs*(1+cogs_ann_incr)^(H5-1) -> 732004.02 | I10: =I8*cogs*(1+cogs_ann_incr)^(I5-1) -> 807217.43 | J10: =J8*cogs*(1+cogs_ann_incr)^(J5-1) -> 890159.02 | K10: =K8*cogs*(1+cogs_ann_incr)^(K5-1) -> 981622.86 | ... M10: =M8*cogs*(1+cogs_ann_incr)^(M5-1) -> 1193709.9
A12: Gross Margin | D12: =D8-D10 -> 605000 | E12: =E8-E10 -> 664138.75 | F12: =F8-F10 -> 729051.51 | G12: =G8-G10 -> 800301.3 | H12: =H8-H10 -> 878505.98 | I12: =I8-I10 -> 964343.57 | J12: =J8-J10 -> 1058558.1 | K12: =K8-K10 -> 1161965.9 | ... M12: =M8-M10 -> 1400032.6
A14: Operating Expenses | D14: =SUM(D15:D16) -> 286000 | E14: =SUM(E15:E16) -> 315664.8 | F14: =SUM(F15:F16) -> 348407.58 | G14: =SUM(G15:G16) -> 384547.81 | H14: =SUM(H15:H16) -> 424438.14 | I14: =SUM(I15:I16) -> 468467.83 | J14: =SUM(J15:J16) -> 517066.57 | K14: =SUM(K15:K16) -> 570708.66 | ... M14: =SUM(M15:M16) -> 695271.43
A15: =Input!L13 -> SG&A expenses | D15: =D8*sga_exp*(1+sga_exp_ann_incr)^(D5-1) -> 154000 | E15: =E8*sga_exp*(1+sga_exp_ann_incr)^(E5-1) -> 170247 | F15: =F8*sga_exp*(1+sga_exp_ann_incr)^(F5-1) -> 188208.06 | G15: =G8*sga_exp*(1+sga_exp_ann_incr)^(G5-1) -> 208064.01 | H15: =H8*sga_exp*(1+sga_exp_ann_incr)^(H5-1) -> 230014.76 | I15: =I8*sga_exp*(1+sga_exp_ann_incr)^(I5-1) -> 254281.32 | J15: =J8*sga_exp*(1+sga_exp_ann_incr)^(J5-1) -> 281108 | K15: =K8*sga_exp*(1+sga_exp_ann_incr)^(K5-1) -> 310764.89 | ... M15: =M8*sga_exp*(1+sga_exp_ann_incr)^(M5-1) -> 379795.17
A16: =Input!L15 -> Other expenses | D16: =D8*other_exp*(1+other_exp_ann_incr)^(D5-1) -> 132000 | E16: =E8*other_exp*(1+other_exp_ann_incr)^(E5-1) -> 145417.8 | F16: =F8*other_exp*(1+other_exp_ann_incr)^(F5-1) -> 160199.52 | G16: =G8*other_exp*(1+other_exp_ann_incr)^(G5-1) -> 176483.8 | H16: =H8*other_exp*(1+other_exp_ann_incr)^(H5-1) -> 194423.38 | I16: =I8*other_exp*(1+other_exp_ann_incr)^(I5-1) -> 214186.52 | J16: =J8*other_exp*(1+other_exp_ann_incr)^(J5-1) -> 235958.57 | K16: =K8*other_exp*(1+other_exp_ann_incr)^(K5-1) -> 259943.76 | ... M16: =M8*other_exp*(1+other_exp_ann_incr)^(M5-1) -> 315476.26
A18: EBITDA | D18: =D12-D14 -> 319000 | E18: =E12-E14 -> 348473.95 | F18: =F12-F14 -> 380643.93 | G18: =G12-G14 -> 415753.49 | H18: =H12-H14 -> 454067.84 | I18: =I12-I14 -> 495875.74 | J18: =J12-J14 -> 541491.51 | K18: =K12-K14 -> 591257.29 | ... M18: =M12-M14 -> 704761.12
A20: D&A | D20: =Depr_Amort!F39+Depr_Amort!F42+Depr_Amort!F43 -> 72924.167 | E20: =Depr_Amort!G39+Depr_Amort!G42+Depr_Amort!G43 -> 85024.167 | F20: =Depr_Amort!H39+Depr_Amort!H42+Depr_Amort!H43 -> 93897.5 | G20: =Depr_Amort!I39+Depr_Amort!I42+Depr_Amort!I43 -> 104355.36 | H20: =Depr_Amort!J39+Depr_Amort!J42+Depr_Amort!J43 -> 117776.27 | I20: =Depr_Amort!K39+Depr_Amort!K42+Depr_Amort!K43 -> 128848.53 | J20: =Depr_Amort!L39+Depr_Amort!L42+Depr_Amort!L43 -> 101531.64 | K20: =Depr_Amort!M39+Depr_Amort!M42+Depr_Amort!M43 -> 115822.24 | ... M20: =Depr_Amort!O39+Depr_Amort!O42+Depr_Amort!O43 -> 149661.32
A22: EBIT | D22: =D18-D20 -> 246075.83 | E22: =E18-E20 -> 263449.78 | F22: =F18-F20 -> 286746.43 | G22: =G18-G20 -> 311398.13 | H22: =H18-H20 -> 336291.57 | I22: =I18-I20 -> 367027.21 | J22: =J18-J20 -> 439959.86 | K22: =K18-K20 -> 475435.06 | ... M22: =M18-M20 -> 555099.8
A24: Interest Expense | D24: =SUM(D25:D32) -> #REF! | E24: =SUM(E25:E32) -> #REF! | F24: =SUM(F25:F32) -> #REF! | G24: =SUM(G25:G32) -> #REF! | H24: =SUM(H25:H32) -> #REF! | I24: =SUM(I25:I32) -> #REF! | J24: =SUM(J25:J32) -> #REF! | K24: =SUM(K25:K32) -> #REF! | ... M24: =SUM(M25:M32) -> #REF!
A25: =Bal_Sheet!A46 -> Existing Debt | D25: =IF(assumed_debt_avg_int=1,AVERAGE(Bal_Sheet!E46,Bal_Sheet!F46)*assumed_debt_cou_rate,Bal_Sheet!E46*assumed_debt_cou_rate) -> #REF! | E25: =IF(assumed_debt_avg_int=1,AVERAGE(Bal_Sheet!F46,Bal_Sheet!G46)*assumed_debt_cou_rate,Bal_Sheet!F46*assumed_debt_cou_rate) -> #REF! | F25: =IF(assumed_debt_avg_int=1,AVERAGE(Bal_Sheet!G46,Bal_Sheet!H46)*assumed_debt_cou_rate,Bal_Sheet!G46*assumed_debt_cou_rate) -> #REF! | G25: =IF(assumed_debt_avg_int=1,AVERAGE(Bal_Sheet!H46,Bal_Sheet!I46)*assumed_debt_cou_rate,Bal_Sheet!H46*assumed_debt_cou_rate) -> #REF! | H25: =IF(assumed_debt_avg_int=1,AVERAGE(Bal_Sheet!I46,Bal_Sheet!J46)*assumed_debt_cou_rate,Bal_Sheet!I46*assumed_debt_cou_rate) -> #REF! | I25: =IF(assumed_debt_avg_int=1,AVERAGE(Bal_Sheet!J46,Bal_Sheet!K46)*assumed_debt_cou_rate,Bal_Sheet!J46*assumed_debt_cou_rate) -> #REF! | J25: =IF(assumed_debt_avg_int=1,AVERAGE(Bal_Sheet!K46,Bal_Sheet!L46)*assumed_debt_cou_rate,Bal_Sheet!K46*assumed_debt_cou_rate) -> #REF! | K25: =IF(assumed_debt_avg_int=1,AVERAGE(Bal_Sheet!L46,Bal_Sheet!M46)*assumed_debt_cou_rate,Bal_Sheet!L46*assumed_debt_cou_rate) -> #REF! | ... M25: =IF(assumed_debt_avg_int=1,AVERAGE(Bal_Sheet!N46,Bal_Sheet!O46)*assumed_debt_cou_rate,Bal_Sheet!N46*assumed_debt_cou_rate) -> #REF!
A26: =Bal_Sheet!A47 -> Bank Revolver | D26: =Bal_Sheet!E47*bank_revolver_cou_rate+(revolver_limit-Bal_Sheet!E47)*undrawn_commit_fee -> 13533.281 | E26: =Bal_Sheet!F47*bank_revolver_cou_rate+(revolver_limit-Bal_Sheet!F47)*undrawn_commit_fee -> #REF! | F26: =Bal_Sheet!G47*bank_revolver_cou_rate+(revolver_limit-Bal_Sheet!G47)*undrawn_commit_fee -> #REF! | G26: =Bal_Sheet!H47*bank_revolver_cou_rate+(revolver_limit-Bal_Sheet!H47)*undrawn_commit_fee -> #REF! | H26: =Bal_Sheet!I47*bank_revolver_cou_rate+(revolver_limit-Bal_Sheet!I47)*undrawn_commit_fee -> #REF! | I26: =Bal_Sheet!J47*bank_revolver_cou_rate+(revolver_limit-Bal_Sheet!J47)*undrawn_commit_fee -> #REF! | J26: =Bal_Sheet!K47*bank_revolver_cou_rate+(revolver_limit-Bal_Sheet!K47)*undrawn_commit_fee -> #REF! | K26: =Bal_Sheet!L47*bank_revolver_cou_rate+(revolver_limit-Bal_Sheet!L47)*undrawn_commit_fee -> #REF! | ... M26: =Bal_Sheet!N47*bank_revolver_cou_rate+(revolver_limit-Bal_Sheet!N47)*undrawn_commit_fee -> #REF!
A27: =Bal_Sheet!A48 -> Term Loan "A" | D27: =IF(termloanA_avg_int=1,AVERAGE(Bal_Sheet!E48,Bal_Sheet!F48)*termloanA_cou_rate,Bal_Sheet!E48*termloanA_cou_rate) -> #REF! | E27: =IF(termloanA_avg_int=1,AVERAGE(Bal_Sheet!F48,Bal_Sheet!G48)*termloanA_cou_rate,Bal_Sheet!F48*termloanA_cou_rate) -> #REF! | F27: =IF(termloanA_avg_int=1,AVERAGE(Bal_Sheet!G48,Bal_Sheet!H48)*termloanA_cou_rate,Bal_Sheet!G48*termloanA_cou_rate) -> #REF! | G27: =IF(termloanA_avg_int=1,AVERAGE(Bal_Sheet!H48,Bal_Sheet!I48)*termloanA_cou_rate,Bal_Sheet!H48*termloanA_cou_rate) -> #REF! | H27: =IF(termloanA_avg_int=1,AVERAGE(Bal_Sheet!I48,Bal_Sheet!J48)*termloanA_cou_rate,Bal_Sheet!I48*termloanA_cou_rate) -> #REF! | I27: =IF(termloanA_avg_int=1,AVERAGE(Bal_Sheet!J48,Bal_Sheet!K48)*termloanA_cou_rate,Bal_Sheet!J48*termloanA_cou_rate) -> #REF! | J27: =IF(termloanA_avg_int=1,AVERAGE(Bal_Sheet!K48,Bal_Sheet!L48)*termloanA_cou_rate,Bal_Sheet!K48*termloanA_cou_rate) -> #REF! | K27: =IF(termloanA_avg_int=1,AVERAGE(Bal_Sheet!L48,Bal_Sheet!M48)*termloanA_cou_rate,Bal_Sheet!L48*termloanA_cou_rate) -> #REF! | ... M27: =IF(termloanA_avg_int=1,AVERAGE(Bal_Sheet!N48,Bal_Sheet!O48)*termloanA_cou_rate,Bal_Sheet!N48*termloanA_cou_rate) -> #REF!
A28: =Bal_Sheet!A49 -> Term Loan "B" | D28: =IF(termloanB_avg_int=1,AVERAGE(Bal_Sheet!E49,Bal_Sheet!F49)*termloanB_cou_rate,Bal_Sheet!E49*termloanB_cou_rate) -> #REF! | E28: =IF(termloanB_avg_int=1,AVERAGE(Bal_Sheet!F49,Bal_Sheet!G49)*termloanB_cou_rate,Bal_Sheet!F49*termloanB_cou_rate) -> #REF! | F28: =IF(termloanB_avg_int=1,AVERAGE(Bal_Sheet!G49,Bal_Sheet!H49)*termloanB_cou_rate,Bal_Sheet!G49*termloanB_cou_rate) -> #REF! | G28: =IF(termloanB_avg_int=1,AVERAGE(Bal_Sheet!H49,Bal_Sheet!I49)*termloanB_cou_rate,Bal_Sheet!H49*termloanB_cou_rate) -> #REF! | H28: =IF(termloanB_avg_int=1,AVERAGE(Bal_Sheet!I49,Bal_Sheet!J49)*termloanB_cou_rate,Bal_Sheet!I49*termloanB_cou_rate) -> #REF! | I28: =IF(termloanB_avg_int=1,AVERAGE(Bal_Sheet!J49,Bal_Sheet!K49)*termloanB_cou_rate,Bal_Sheet!J49*termloanB_cou_rate) -> #REF! | J28: =IF(termloanB_avg_int=1,AVERAGE(Bal_Sheet!K49,Bal_Sheet!L49)*termloanB_cou_rate,Bal_Sheet!K49*termloanB_cou_rate) -> #REF! | K28: =IF(termloanB_avg_int=1,AVERAGE(Bal_Sheet!L49,Bal_Sheet!M49)*termloanB_cou_rate,Bal_Sheet!L49*termloanB_cou_rate) -> #REF! | ... M28: =IF(termloanB_avg_int=1,AVERAGE(Bal_Sheet!N49,Bal_Sheet!O49)*termloanB_cou_rate,Bal_Sheet!N49*termloanB_cou_rate) -> #REF!
A29: =Bal_Sheet!A50 -> Senior Notes | D29: =IF(senior_notes_avg_int=1,AVERAGE(Bal_Sheet!E50,Bal_Sheet!F50)*senior_notes_cou_rate,Bal_Sheet!E50*senior_notes_cou_rate) -> #REF! | E29: =IF(senior_notes_avg_int=1,AVERAGE(Bal_Sheet!F50,Bal_Sheet!G50)*senior_notes_cou_rate,Bal_Sheet!F50*senior_notes_cou_rate) -> #REF! | F29: =IF(senior_notes_avg_int=1,AVERAGE(Bal_Sheet!G50,Bal_Sheet!H50)*senior_notes_cou_rate,Bal_Sheet!G50*senior_notes_cou_rate) -> #REF! | G29: =IF(senior_notes_avg_int=1,AVERAGE(Bal_Sheet!H50,Bal_Sheet!I50)*senior_notes_cou_rate,Bal_Sheet!H50*senior_notes_cou_rate) -> #REF! | H29: =IF(senior_notes_avg_int=1,AVERAGE(Bal_Sheet!I50,Bal_Sheet!J50)*senior_notes_cou_rate,Bal_Sheet!I50*senior_notes_cou_rate) -> #REF! | I29: =IF(senior_notes_avg_int=1,AVERAGE(Bal_Sheet!J50,Bal_Sheet!K50)*senior_notes_cou_rate,Bal_Sheet!J50*senior_notes_cou_rate) -> #REF! | J29: =IF(senior_notes_avg_int=1,AVERAGE(Bal_Sheet!K50,Bal_Sheet!L50)*senior_notes_cou_rate,Bal_Sheet!K50*senior_notes_cou_rate) -> #REF! | K29: =IF(senior_notes_avg_int=1,AVERAGE(Bal_Sheet!L50,Bal_Sheet!M50)*senior_notes_cou_rate,Bal_Sheet!L50*senior_notes_cou_rate) -> #REF! | ... M29: =IF(senior_notes_avg_int=1,AVERAGE(Bal_Sheet!N50,Bal_Sheet!O50)*senior_notes_cou_rate,Bal_Sheet!N50*senior_notes_cou_rate) -> #REF!
A30: =Bal_Sheet!A51 -> Subordinated Notes | D30: =IF(sub_notes_avg_int=1,AVERAGE(Bal_Sheet!E51,Bal_Sheet!F51)*sub_notes_cou_rate,Bal_Sheet!E51*sub_notes_cou_rate) -> 1800 | E30: =IF(sub_notes_avg_int=1,AVERAGE(Bal_Sheet!F51,Bal_Sheet!G51)*sub_notes_cou_rate,Bal_Sheet!F51*sub_notes_cou_rate) -> #REF! | F30: =IF(sub_notes_avg_int=1,AVERAGE(Bal_Sheet!G51,Bal_Sheet!H51)*sub_notes_cou_rate,Bal_Sheet!G51*sub_notes_cou_rate) -> #REF! | G30: =IF(sub_notes_avg_int=1,AVERAGE(Bal_Sheet!H51,Bal_Sheet!I51)*sub_notes_cou_rate,Bal_Sheet!H51*sub_notes_cou_rate) -> #REF! | H30: =IF(sub_notes_avg_int=1,AVERAGE(Bal_Sheet!I51,Bal_Sheet!J51)*sub_notes_cou_rate,Bal_Sheet!I51*sub_notes_cou_rate) -> #REF! | I30: =IF(sub_notes_avg_int=1,AVERAGE(Bal_Sheet!J51,Bal_Sheet!K51)*sub_notes_cou_rate,Bal_Sheet!J51*sub_notes_cou_rate) -> #REF! | J30: =IF(sub_notes_avg_int=1,AVERAGE(Bal_Sheet!K51,Bal_Sheet!L51)*sub_notes_cou_rate,Bal_Sheet!K51*sub_notes_cou_rate) -> #REF! | K30: =IF(sub_notes_avg_int=1,AVERAGE(Bal_Sheet!L51,Bal_Sheet!M51)*sub_notes_cou_rate,Bal_Sheet!L51*sub_notes_cou_rate) -> #REF! | ... M30: =IF(sub_notes_avg_int=1,AVERAGE(Bal_Sheet!N51,Bal_Sheet!O51)*sub_notes_cou_rate,Bal_Sheet!N51*sub_notes_cou_rate) -> #REF!
A31: =Bal_Sheet!A52 -> Mezzanine Debt | D31: =IF(mezzdebt_avg_int=1,AVERAGE(Bal_Sheet!E52,Bal_Sheet!F52)*mezzdebt_cou_rate,Bal_Sheet!E52*mezzdebt_cou_rate) -> 3150 | E31: =IF(mezzdebt_avg_int=1,AVERAGE(Bal_Sheet!F52,Bal_Sheet!G52)*mezzdebt_cou_rate,Bal_Sheet!F52*mezzdebt_cou_rate) -> #REF! | F31: =IF(mezzdebt_avg_int=1,AVERAGE(Bal_Sheet!G52,Bal_Sheet!H52)*mezzdebt_cou_rate,Bal_Sheet!G52*mezzdebt_cou_rate) -> #REF! | G31: =IF(mezzdebt_avg_int=1,AVERAGE(Bal_Sheet!H52,Bal_Sheet!I52)*mezzdebt_cou_rate,Bal_Sheet!H52*mezzdebt_cou_rate) -> #REF! | H31: =IF(mezzdebt_avg_int=1,AVERAGE(Bal_Sheet!I52,Bal_Sheet!J52)*mezzdebt_cou_rate,Bal_Sheet!I52*mezzdebt_cou_rate) -> #REF! | I31: =IF(mezzdebt_avg_int=1,AVERAGE(Bal_Sheet!J52,Bal_Sheet!K52)*mezzdebt_cou_rate,Bal_Sheet!J52*mezzdebt_cou_rate) -> #REF! | J31: =IF(mezzdebt_avg_int=1,AVERAGE(Bal_Sheet!K52,Bal_Sheet!L52)*mezzdebt_cou_rate,Bal_Sheet!K52*mezzdebt_cou_rate) -> #REF! | K31: =IF(mezzdebt_avg_int=1,AVERAGE(Bal_Sheet!L52,Bal_Sheet!M52)*mezzdebt_cou_rate,Bal_Sheet!L52*mezzdebt_cou_rate) -> #REF! | ... M31: =IF(mezzdebt_avg_int=1,AVERAGE(Bal_Sheet!N52,Bal_Sheet!O52)*mezzdebt_cou_rate,Bal_Sheet!N52*mezzdebt_cou_rate) -> #REF!
A32: =Bal_Sheet!A53 -> Seller Notes | D32: =IF(seller_notes_avg_int=1,AVERAGE(Bal_Sheet!E53,Bal_Sheet!F53)*seller_notes_cou_rate,Bal_Sheet!E53*seller_notes_cou_rate) -> #REF! | E32: =IF(seller_notes_avg_int=1,AVERAGE(Bal_Sheet!F53,Bal_Sheet!G53)*seller_notes_cou_rate,Bal_Sheet!F53*seller_notes_cou_rate) -> #REF! | F32: =IF(seller_notes_avg_int=1,AVERAGE(Bal_Sheet!G53,Bal_Sheet!H53)*seller_notes_cou_rate,Bal_Sheet!G53*seller_notes_cou_rate) -> #REF! | G32: =IF(seller_notes_avg_int=1,AVERAGE(Bal_Sheet!H53,Bal_Sheet!I53)*seller_notes_cou_rate,Bal_Sheet!H53*seller_notes_cou_rate) -> #REF! | H32: =IF(seller_notes_avg_int=1,AVERAGE(Bal_Sheet!I53,Bal_Sheet!J53)*seller_notes_cou_rate,Bal_Sheet!I53*seller_notes_cou_rate) -> #REF! | I32: =IF(seller_notes_avg_int=1,AVERAGE(Bal_Sheet!J53,Bal_Sheet!K53)*seller_notes_cou_rate,Bal_Sheet!J53*seller_notes_cou_rate) -> #REF! | J32: =IF(seller_notes_avg_int=1,AVERAGE(Bal_Sheet!K53,Bal_Sheet!L53)*seller_notes_cou_rate,Bal_Sheet!K53*seller_notes_cou_rate) -> #REF! | K32: =IF(seller_notes_avg_int=1,AVERAGE(Bal_Sheet!L53,Bal_Sheet!M53)*seller_notes_cou_rate,Bal_Sheet!L53*seller_notes_cou_rate) -> #REF! | ... M32: =IF(seller_notes_avg_int=1,AVERAGE(Bal_Sheet!N53,Bal_Sheet!O53)*seller_notes_cou_rate,Bal_Sheet!N53*seller_notes_cou_rate) -> #REF!
A34: Other Expenses (Income) | D34: =SUM(D36:D37) -> #REF! | E34: =SUM(E36:E37) -> #REF! | F34: =SUM(F36:F37) -> #REF! | G34: =SUM(G36:G37) -> #REF! | H34: =SUM(H36:H37) -> #REF! | I34: =SUM(I36:I37) -> #REF! | J34: =SUM(J36:J37) -> #REF! | K34: =SUM(K36:K37) -> #REF! | ... M34: =SUM(M36:M37) -> #REF!
A35: Amortization of Capitalized
A36: Financing Costs | D36: =Depr_Amort!F45 -> #REF! | E36: =Depr_Amort!G45 -> #REF! | F36: =Depr_Amort!H45 -> #REF! | G36: =Depr_Amort!I45 -> #REF! | H36: =Depr_Amort!J45 -> #REF! | I36: =Depr_Amort!K45 -> #REF! | J36: =Depr_Amort!L45 -> #REF! | K36: =Depr_Amort!M45 -> #REF! | ... M36: =Depr_Amort!O45 -> #REF!
A37: (Gain) Loss on Asset Sales | D37: =-Income_Tax!D11 -> -1250 | E37: =-Income_Tax!E11 -> -1350 | F37: =-Income_Tax!F11 -> -1450 | G37: =-Income_Tax!G11 -> -1550 | H37: =-Income_Tax!H11 -> -1650 | I37: =-Income_Tax!I11 -> -1750 | J37: =-Income_Tax!J11 -> -1850 | K37: =-Income_Tax!K11 -> -1950 | ... M37: =-Income_Tax!M11 -> -2150
A39: Net Income before Taxes | D39: =D22-D24-D34 -> #REF! | E39: =E22-E24-E34 -> #REF! | F39: =F22-F24-F34 -> #REF! | G39: =G22-G24-G34 -> #REF! | H39: =H22-H24-H34 -> #REF! | I39: =I22-I24-I34 -> #REF! | J39: =J22-J24-J34 -> #REF! | K39: =K22-K24-K34 -> #REF! | ... M39: =M22-M24-M34 -> #REF!
A41: Income Tax Expense (Benefit) | D41: =Income_Tax!D28 -> #REF! | E41: =Income_Tax!E28 -> #REF! | F41: =Income_Tax!F28 -> #REF! | G41: =Income_Tax!G28 -> #REF! | H41: =Income_Tax!H28 -> #REF! | I41: =Income_Tax!I28 -> #REF! | J41: =Income_Tax!J28 -> #REF! | K41: =Income_Tax!K28 -> #REF! | ... M41: =Income_Tax!M28 -> #REF!
A43: Net Income | D43: =D39-D41 -> #REF! | E43: =E39-E41 -> #REF! | F43: =F39-F41 -> #REF! | G43: =G39-G41 -> #REF! | H43: =H39-H41 -> #REF! | I43: =I39-I41 -> #REF! | J43: =J39-J41 -> #REF! | K43: =K39-K41 -> #REF! | ... M43: =M39-M41 -> #REF!
A45: Dividend | D45: =SUM(D46:D47) -> 6700 | E45: =SUM(E46:E47) -> 7194 | F45: =SUM(F46:F47) -> 7658.58 | G45: =SUM(G46:G47) -> 8245.1806 | H45: =SUM(H46:H47) -> 8955.3432 | I45: =SUM(I46:I47) -> 9390.7173 | J45: =SUM(J46:J47) -> 9590.7173 | K45: =SUM(K46:K47) -> 9890.7173 | ... M45: =SUM(M46:M47) -> 10290.717
A46: =Input!G64 -> Preferred Stock Dividend | D46: =Bal_Sheet!E61*pref_stock_div -> 4200 | E46: =Bal_Sheet!F61*pref_stock_div -> 4494 | F46: =Bal_Sheet!G61*pref_stock_div -> 4808.58 | G46: =Bal_Sheet!H61*pref_stock_div -> 5145.1806 | H46: =Bal_Sheet!I61*pref_stock_div -> 5505.3432 | I46: =Bal_Sheet!J61*pref_stock_div -> 5890.7173 | J46: =Bal_Sheet!K61*pref_stock_div -> 5890.7173 | K46: =Bal_Sheet!L61*pref_stock_div -> 5890.7173 | ... M46: =Bal_Sheet!N61*pref_stock_div -> 5890.7173
A47: Common Stock Dividend | D47: 2500 | E47: 2700 | F47: 2850 | G47: 3100 | H47: 3450 | I47: 3500 | J47: 3700 | K47: 4000 | L47: 4100 | M47: 4400
A49: Net Income to Common Shareholders | D49: =D43-D45 -> #REF! | E49: =E43-E45 -> #REF! | F49: =F43-F45 -> #REF! | G49: =G43-G45 -> #REF! | H49: =H43-H45 -> #REF! | I49: =I43-I45 -> #REF! | J49: =J43-J45 -> #REF! | K49: =K43-K45 -> #REF! | ... M49: =M43-M45 -> #REF!

Sheet Bal_Sheet
A2: Balance Sheets
A4: Year | C4: Pre-Acq | D4: Adj | E4: Post-Acq | F4: 2016 | G4: =F4+1 -> 2017 | H4: =G4+1 -> 2018 | I4: =H4+1 -> 2019 | J4: =I4+1 -> 2020 | K4: =J4+1 -> 2021 | L4: =K4+1 -> 2022 | M4: =L4+1 -> 2023 | N4: =M4+1 -> 2024 | O4: =N4+1 -> 2025
A5: Year No. | E5: =F5-1 -> 0 | F5: 1 | G5: =F5+1 -> 2 | H5: =G5+1 -> 3 | I5: =H5+1 -> 4 | J5: =I5+1 -> 5 | K5: =J5+1 -> 6 | L5: =K5+1 -> 7 | M5: =L5+1 -> 8 | N5: =M5+1 -> 9 | O5: =N5+1 -> 10
A7: ASSETS
A9: Current Assets:
A10: Cash in bank | C10: 55000 | D10: =Input!C18-Input!C24 -> 22500 | E10: =SUM(C10:D10) -> 77500 | F10: =Cash_Flow!D110 -> #REF! | G10: =Cash_Flow!E110 -> #REF! | H10: =Cash_Flow!F110 -> #REF! | I10: =Cash_Flow!G110 -> #REF! | J10: =Cash_Flow!H110 -> #REF! | K10: =Cash_Flow!I110 -> #REF! | L10: =Cash_Flow!J110 -> #REF! | M10: =Cash_Flow!K110 -> #REF! | ... O10: =Cash_Flow!M110 -> #REF!
A11: Accounts receivable | C11: 85000 | E11: =SUM(C11:D11) -> 85000 | F11: =Inc_St!D8*acc_recv*(1+acc_recv_ann_incr)^(F5-1) -> 198000 | G11: =Inc_St!E8*acc_recv*(1+acc_recv_ann_incr)^(G5-1) -> 228690 | H11: =Inc_St!F8*acc_recv*(1+acc_recv_ann_incr)^(H5-1) -> 264136.95 | I11: =Inc_St!G8*acc_recv*(1+acc_recv_ann_incr)^(I5-1) -> 305078.18 | J11: =Inc_St!H8*acc_recv*(1+acc_recv_ann_incr)^(J5-1) -> 352365.29 | K11: =Inc_St!I8*acc_recv*(1+acc_recv_ann_incr)^(K5-1) -> 406981.92 | L11: =Inc_St!J8*acc_recv*(1+acc_recv_ann_incr)^(L5-1) -> 470064.11 | M11: =Inc_St!K8*acc_recv*(1+acc_recv_ann_incr)^(M5-1) -> 542924.05 | ... O11: =Inc_St!M8*acc_recv*(1+acc_recv_ann_incr)^(O5-1) -> 724274.26
A12: Inventories | C12: 95999 | E12: =SUM(C12:D12) -> 95999 | F12: =Inc_St!D10*inventories*(1+inventories_ann_incr)^(F5-1) -> 99000 | G12: =Inc_St!E10*inventories*(1+inventories_ann_incr)^(G5-1) -> 113539.14 | H12: =Inc_St!F10*inventories*(1+inventories_ann_incr)^(H5-1) -> 130213.5 | I12: =Inc_St!G10*inventories*(1+inventories_ann_incr)^(I5-1) -> 149336.65 | J12: =Inc_St!H10*inventories*(1+inventories_ann_incr)^(J5-1) -> 171268.23 | K12: =Inc_St!I10*inventories*(1+inventories_ann_incr)^(K5-1) -> 196420.69 | L12: =Inc_St!J10*inventories*(1+inventories_ann_incr)^(L5-1) -> 225267.03 | M12: =Inc_St!K10*inventories*(1+inventories_ann_incr)^(M5-1) -> 258349.74 | ... O12: =Inc_St!M10*inventories*(1+inventories_ann_incr)^(O5-1) -> 339804.28
A13: Prepaids | C13: 22000 | E13: =SUM(C13:D13) -> 22000 | F13: =Inc_St!D8*prepaids*(1+prepaids_ann_incr)^(F5-1) -> 49500 | G13: =Inc_St!E8*prepaids*(1+prepaids_ann_incr)^(G5-1) -> 55539 | H13: =Inc_St!F8*prepaids*(1+prepaids_ann_incr)^(H5-1) -> 62314.758 | I13: =Inc_St!G8*prepaids*(1+prepaids_ann_incr)^(I5-1) -> 69917.158 | J13: =Inc_St!H8*prepaids*(1+prepaids_ann_incr)^(J5-1) -> 78447.052 | K13: =Inc_St!I8*prepaids*(1+prepaids_ann_incr)^(K5-1) -> 88017.592 | L13: =Inc_St!J8*prepaids*(1+prepaids_ann_incr)^(L5-1) -> 98755.738 | M13: =Inc_St!K8*prepaids*(1+prepaids_ann_incr)^(M5-1) -> 110803.94 | ... O13: =Inc_St!M8*prepaids*(1+prepaids_ann_incr)^(O5-1) -> 139489.31
A14: Other current assets | C14: 45000 | E14: =SUM(C14:D14) -> 45000 | F14: =Inc_St!D8*other_curr_assets*(1+other_curr_assets_ann_incr)^(F5-1) -> 132000 | G14: =Inc_St!E8*other_curr_assets*(1+other_curr_assets_ann_incr)^(G5-1) -> 148830 | H14: =Inc_St!F8*other_curr_assets*(1+other_curr_assets_ann_incr)^(H5-1) -> 167805.83 | I14: =Inc_St!G8*other_curr_assets*(1+other_curr_assets_ann_incr)^(I5-1) -> 189201.07 | J14: =Inc_St!H8*other_curr_assets*(1+other_curr_assets_ann_incr)^(J5-1) -> 213324.2 | K14: =Inc_St!I8*other_curr_assets*(1+other_curr_assets_ann_incr)^(K5-1) -> 240523.04 | L14: =Inc_St!J8*other_curr_assets*(1+other_curr_assets_ann_incr)^(L5-1) -> 271189.73 | M14: =Inc_St!K8*other_curr_assets*(1+other_curr_assets_ann_incr)^(M5-1) -> 305766.42 | ... O14: =Inc_St!M8*other_curr_assets*(1+other_curr_assets_ann_incr)^(O5-1) -> 388707.47
A16: Total Current Assets | C16: =SUM(C10:C14) -> 302999 | E16: =SUM(E10:E14) -> 325499 | F16: =SUM(F10:F14) -> #REF! | G16: =SUM(G10:G14) -> #REF! | H16: =SUM(H10:H14) -> #REF! | I16: =SUM(I10:I14) -> #REF! | J16: =SUM(J10:J14) -> #REF! | K16: =SUM(K10:K14) -> #REF! | L16: =SUM(L10:L14) -> #REF! | ... O16: =SUM(O10:O14) -> #REF!
A18: Non-Current Assets:
A19: Goodwill | C19: 20000 | D19: =-C19+Input!C53 -> 191478.5 | E19: =SUM(C19:D19) -> 211478.5 | F19: =E19-Depr_Amort!F43 -> 211478.5 | G19: =F19-Depr_Amort!G43 -> 211478.5 | H19: =G19-Depr_Amort!H43 -> 211478.5 | I19: =H19-Depr_Amort!I43 -> 211478.5 | J19: =I19-Depr_Amort!J43 -> 211478.5 | K19: =J19-Depr_Amort!K43 -> 211478.5 | L19: =K19-Depr_Amort!L43 -> 211478.5 | M19: =L19-Depr_Amort!M43 -> 211478.5 | ... O19: =N19-Depr_Amort!O43 -> 211478.5
A20: Intangible Assets | C20: 950 | D20: =Input!C50 -> 1200 | E20: =SUM(C20:D20) -> 2150 | F20: =E20-Depr_Amort!F42 -> 1970.8333 | G20: =F20-Depr_Amort!G42 -> 1791.6667 | H20: =G20-Depr_Amort!H42 -> 1612.5 | I20: =H20-Depr_Amort!I42 -> 1433.3333 | J20: =I20-Depr_Amort!J42 -> 1254.1667 | K20: =J20-Depr_Amort!K42 -> 1075 | L20: =K20-Depr_Amort!L42 -> 895.83333 | M20: =L20-Depr_Amort!M42 -> 716.66667 | ... O20: =N20-Depr_Amort!O42 -> 358.33333
A21: =Input!A17 -> Capitalized Financing Costs | C21: 0 | D21: =Input!Q34 -> 10887.5 | E21: =SUM(C21:D21) -> 10887.5 | F21: =E21-Depr_Amort!F45 -> #REF! | G21: =F21-Depr_Amort!G45 -> #REF! | H21: =G21-Depr_Amort!H45 -> #REF! | I21: =H21-Depr_Amort!I45 -> #REF! | J21: =I21-Depr_Amort!J45 -> #REF! | K21: =J21-Depr_Amort!K45 -> #REF! | L21: =K21-Depr_Amort!L45 -> #REF! | M21: =L21-Depr_Amort!M45 -> #REF! | ... O21: =N21-Depr_Amort!O45 -> #REF!
A22: Other Long-Term Assets | C22: 15000 | E22: =SUM(C22:D22) -> 15000 | F22: =Inc_St!D8*other_longterm_assets*(1+other_longterm_assets_ann_incr)^(F5-1) -> 44000 | G22: =Inc_St!E8*other_longterm_assets*(1+other_longterm_assets_ann_incr)^(G5-1) -> 48642 | H22: =Inc_St!F8*other_longterm_assets*(1+other_longterm_assets_ann_incr)^(H5-1) -> 53773.731 | I22: =Inc_St!G8*other_longterm_assets*(1+other_longterm_assets_ann_incr)^(I5-1) -> 59446.86 | J22: =Inc_St!H8*other_longterm_assets*(1+other_longterm_assets_ann_incr)^(J5-1) -> 65718.503 | K22: =Inc_St!I8*other_longterm_assets*(1+other_longterm_assets_ann_incr)^(K5-1) -> 72651.805 | L22: =Inc_St!J8*other_longterm_assets*(1+other_longterm_assets_ann_incr)^(L5-1) -> 80316.571 | M22: =Inc_St!K8*other_longterm_assets*(1+other_longterm_assets_ann_incr)^(M5-1) -> 88789.969 | ... O22: =Inc_St!M8*other_longterm_assets*(1+other_longterm_assets_ann_incr)^(O5-1) -> 108512.91
A23: PP&E:
A24: Gross PP&E | C24: 500000 | D24: =Input!C49 -> 2450 | E24: =SUM(C24:D24) -> 502450 | F24: =E24 -> 502450 | G24: =F24+F25 -> 612450 | H24: =G24+G25 -> 733450 | I24: =H24+H25 -> 866550 | J24: =I24+I25 -> 1012960 | K24: =J24+J25 -> 1174011 | L24: =K24+K25 -> 1351167.1 | M24: =L24+L25 -> 1546038.8 | N24: =M24+M25 -> 1760397.7 | O24: =N24+N25 -> 1996192.5
A25: Capex | C25: 0 | E25: =SUM(C25:D25) -> 0 | F25: =Depr_Amort!B24 -> 110000 | G25: =Depr_Amort!B25 -> 121000 | H25: =Depr_Amort!B26 -> 133100 | I25: =Depr_Amort!B27 -> 146410 | J25: =Depr_Amort!B28 -> 161051 | K25: =Depr_Amort!B29 -> 177156.1 | L25: =Depr_Amort!B30 -> 194871.71 | M25: =Depr_Amort!B31 -> 214358.88 | N25: =Depr_Amort!B32 -> 235794.77 | O25: =Depr_Amort!B33 -> 259374.25
A26: Depreciation (Current) | C26: 0 | E26: =SUM(C26:D26) -> 0 | F26: =Depr_Amort!F39 -> 72745 | G26: =Depr_Amort!G39 -> 84845 | H26: =Depr_Amort!H39 -> 93718.333 | I26: =Depr_Amort!I39 -> 104176.19 | J26: =Depr_Amort!J39 -> 117597.11 | K26: =Depr_Amort!K39 -> 128669.36 | L26: =Depr_Amort!L39 -> 101352.48 | M26: =Depr_Amort!M39 -> 115643.07 | ... O26: =Depr_Amort!O39 -> 149482.15
A27: Accumulated Depreciation | C27: 25000 | E27: =SUM(C27:D27) -> 25000 | F27: =E27+F26 -> 97745 | G27: =F27+G26 -> 182590 | H27: =G27+H26 -> 276308.33 | I27: =H27+I26 -> 380484.52 | J27: =I27+J26 -> 498081.63 | K27: =J27+K26 -> 626750.99 | L27: =K27+L26 -> 728103.47 | M27: =L27+M26 -> 843746.54 | ... O27: =N27+O26 -> 1121096.3
A28: Net PP&E | C28: =C24+C25-C27 -> 475000 | E28: =E24+E25-E27 -> 477450 | F28: =F24+F25-F27 -> 514705 | G28: =G24+G25-G27 -> 550860 | H28: =H24+H25-H27 -> 590241.67 | I28: =I24+I25-I27 -> 632475.48 | J28: =J24+J25-J27 -> 675929.37 | K28: =K24+K25-K27 -> 724416.11 | L28: =L24+L25-L27 -> 817935.34 | ... O28: =O24+O25-O27 -> 1134470.4
A30: Total Non-Current Assets | C30: =SUM(C19,C20,C21,C22,C28) -> 510950 | E30: =SUM(E19,E20,E21,E22,E28) -> 716966 | F30: =SUM(F19,F20,F21,F22,F28) -> #REF! | G30: =SUM(G19,G20,G21,G22,G28) -> #REF! | H30: =SUM(H19,H20,H21,H22,H28) -> #REF! | I30: =SUM(I19,I20,I21,I22,I28) -> #REF! | J30: =SUM(J19,J20,J21,J22,J28) -> #REF! | K30: =SUM(K19,K20,K21,K22,K28) -> #REF! | L30: =SUM(L19,L20,L21,L22,L28) -> #REF! | ... O30: =SUM(O19,O20,O21,O22,O28) -> #REF!
A32: Total Assets | C32: =SUM(C16,C30) -> 813949 | D32: =SUM(D10:D31) -> 228516 | E32: =SUM(E16,E30) -> 1042465 | F32: =SUM(F16,F30) -> #REF! | G32: =SUM(G16,G30) -> #REF! | H32: =SUM(H16,H30) -> #REF! | I32: =SUM(I16,I30) -> #REF! | J32: =SUM(J16,J30) -> #REF! | K32: =SUM(K16,K30) -> #REF! | L32: =SUM(L16,L30) -> #REF! | ... O32: =SUM(O16,O30) -> #REF!
A35: LIABILITIES & EQUITY
A37: Current Liabilities:
A38: Accounts payable | C38: 51800 | E38: =SUM(C38:D38) -> 51800 | F38: =(Inc_St!D10+F12-E12)*acc_payable*(1+acc_payable_ann_incr)^(F5-1) -> 74700.15 | G38: =(Inc_St!E10+G12-F12)*acc_payable*(1+acc_payable_ann_incr)^(G5-1) -> 85741.26 | H38: =(Inc_St!F10+H12-G12)*acc_payable*(1+acc_payable_ann_incr)^(H5-1) -> 96542.282 | I38: =(Inc_St!G10+I12-H12)*acc_payable*(1+acc_payable_ann_incr)^(I5-1) -> 108708.32 | J38: =(Inc_St!H10+J12-I12)*acc_payable*(1+acc_payable_ann_incr)^(J5-1) -> 122412.62 | K38: =(Inc_St!I10+K12-J12)*acc_payable*(1+acc_payable_ann_incr)^(K5-1) -> 137850.54 | L38: =(Inc_St!J10+L12-K12)*acc_payable*(1+acc_payable_ann_incr)^(L5-1) -> 155242.4 | M38: =(Inc_St!K10+M12-L12)*acc_payable*(1+acc_payable_ann_incr)^(M5-1) -> 174836.66 | ... O38: =(Inc_St!M10+O12-N12)*acc_payable*(1+acc_payable_ann_incr)^(O5-1) -> 221789.44
A39: Accrued expenses | C39: 24000 | E39: =SUM(C39:D39) -> 24000 | F39: =Inc_St!D8*acc_exp*(1+acc_exp_ann_incr)^(F5-1) -> 66000 | G39: =Inc_St!E8*acc_exp*(1+acc_exp_ann_incr)^(G5-1) -> 73689 | H39: =Inc_St!F8*acc_exp*(1+acc_exp_ann_incr)^(H5-1) -> 82273.769 | I39: =Inc_St!G8*acc_exp*(1+acc_exp_ann_incr)^(I5-1) -> 91858.663 | J39: =Inc_St!H8*acc_exp*(1+acc_exp_ann_incr)^(J5-1) -> 102560.2 | K39: =Inc_St!I8*acc_exp*(1+acc_exp_ann_incr)^(K5-1) -> 114508.46 | L39: =Inc_St!J8*acc_exp*(1+acc_exp_ann_incr)^(L5-1) -> 127848.7 | M39: =Inc_St!K8*acc_exp*(1+acc_exp_ann_incr)^(M5-1) -> 142743.07 | ... O39: =Inc_St!M8*acc_exp*(1+acc_exp_ann_incr)^(O5-1) -> 177939.55
A40: Other current liabilities | C40: 22000 | E40: =SUM(C40:D40) -> 22000 | F40: =Inc_St!D8*other_curr_liab*(1+other_curr_liab_ann_incr)^(F5-1) -> 88000 | G40: =Inc_St!E8*other_curr_liab*(1+other_curr_liab_ann_incr)^(G5-1) -> 97768 | H40: =Inc_St!F8*other_curr_liab*(1+other_curr_liab_ann_incr)^(H5-1) -> 108620.25 | I40: =Inc_St!G8*other_curr_liab*(1+other_curr_liab_ann_incr)^(I5-1) -> 120677.1 | J40: =Inc_St!H8*other_curr_liab*(1+other_curr_liab_ann_incr)^(J5-1) -> 134072.25 | K40: =Inc_St!I8*other_curr_liab*(1+other_curr_liab_ann_incr)^(K5-1) -> 148954.27 | L40: =Inc_St!J8*other_curr_liab*(1+other_curr_liab_ann_incr)^(L5-1) -> 165488.2 | M40: =Inc_St!K8*other_curr_liab*(1+other_curr_liab_ann_incr)^(M5-1) -> 183857.39 | ... O40: =Inc_St!M8*other_curr_liab*(1+other_curr_liab_ann_incr)^(O5-1) -> 226939.03
A42: Total Current Liabilities | C42: =SUM(C38:C40) -> 97800 | E42: =SUM(E38:E40) -> 97800 | F42: =SUM(F38:F40) -> 228700.15 | G42: =SUM(G38:G40) -> 257198.26 | H42: =SUM(H38:H40) -> 287436.3 | I42: =SUM(I38:I40) -> 321244.08 | J42: =SUM(J38:J40) -> 359045.07 | K42: =SUM(K38:K40) -> 401313.27 | L42: =SUM(L38:L40) -> 448579.29 | ... O42: =SUM(O38:O40) -> 626668.02
A44: Deferred Tax Liability | C44: 1400 | D44: =-C44-Input!C52 -> -122.5 | E44: =SUM(C44:D44) -> 1277.5 | F44: =E44+Income_Tax!D30 -> #REF! | G44: =F44+Income_Tax!E30 -> #REF! | H44: =G44+Income_Tax!F30 -> #REF! | I44: =H44+Income_Tax!G30 -> #REF! | J44: =I44+Income_Tax!H30 -> #REF! | K44: =J44+Income_Tax!I30 -> #REF! | L44: =K44+Income_Tax!J30 -> #REF! | M44: =L44+Income_Tax!K30 -> #REF! | ... O44: =N44+Income_Tax!M30 -> #REF!
A45: Long-Term Debt:
A46: Existing Debt | C46: 250000 | D46: =-Input!C14 -> -185000 | E46: =SUM(C46:D46) -> 65000 | F46: =E46-Cash_Flow!D85-Cash_Flow!D100 -> #REF! | G46: =F46-Cash_Flow!E85-Cash_Flow!E100 -> #REF! | H46: =G46-Cash_Flow!F85-Cash_Flow!F100 -> #REF! | I46: =H46-Cash_Flow!G85-Cash_Flow!G100 -> #REF! | J46: =I46-Cash_Flow!H85-Cash_Flow!H100 -> #REF! | K46: =J46-Cash_Flow!I85-Cash_Flow!I100 -> #REF! | L46: =K46-Cash_Flow!J85-Cash_Flow!J100 -> #REF! | M46: =L46-Cash_Flow!K85-Cash_Flow!K100 -> #REF! | ... O46: =N46-Cash_Flow!M85-Cash_Flow!M100 -> #REF!
A47: =Input!A27 -> Bank Revolver | C47: 0 | D47: =Input!C27 -> 200887.5 | E47: =SUM(C47:D47) -> 200887.5 | F47: =E47+Cash_Flow!D96-Cash_Flow!D107 -> #REF! | G47: =F47+Cash_Flow!E96-Cash_Flow!E107 -> #REF! | H47: =G47+Cash_Flow!F96-Cash_Flow!F107 -> #REF! | I47: =H47+Cash_Flow!G96-Cash_Flow!G107 -> #REF! | J47: =I47+Cash_Flow!H96-Cash_Flow!H107 -> #REF! | K47: =J47+Cash_Flow!I96-Cash_Flow!I107 -> #REF! | L47: =K47+Cash_Flow!J96-Cash_Flow!J107 -> #REF! | M47: =L47+Cash_Flow!K96-Cash_Flow!K107 -> #REF! | ... O47: =N47+Cash_Flow!M96-Cash_Flow!M107 -> #REF!
A48: =Input!A28 -> Term Loan "A" | C48: 0 | D48: =Input!C28 -> 80000 | E48: =SUM(C48:D48) -> 80000 | F48: =E48-Cash_Flow!D86-Cash_Flow!D101 -> #REF! | G48: =F48-Cash_Flow!E86-Cash_Flow!E101 -> #REF! | H48: =G48-Cash_Flow!F86-Cash_Flow!F101 -> #REF! | I48: =H48-Cash_Flow!G86-Cash_Flow!G101 -> #REF! | J48: =I48-Cash_Flow!H86-Cash_Flow!H101 -> #REF! | K48: =J48-Cash_Flow!I86-Cash_Flow!I101 -> #REF! | L48: =K48-Cash_Flow!J86-Cash_Flow!J101 -> #REF! | M48: =L48-Cash_Flow!K86-Cash_Flow!K101 -> #REF! | ... O48: =N48-Cash_Flow!M86-Cash_Flow!M101 -> #REF!
A49: =Input!A29 -> Term Loan "B" | C49: 0 | D49: =Input!C29 -> 55000 | E49: =SUM(C49:D49) -> 55000 | F49: =E49-Cash_Flow!D87-Cash_Flow!D102 -> #REF! | G49: =F49-Cash_Flow!E87-Cash_Flow!E102 -> #REF! | H49: =G49-Cash_Flow!F87-Cash_Flow!F102 -> #REF! | I49: =H49-Cash_Flow!G87-Cash_Flow!G102 -> #REF! | J49: =I49-Cash_Flow!H87-Cash_Flow!H102 -> #REF! | K49: =J49-Cash_Flow!I87-Cash_Flow!I102 -> #REF! | L49: =K49-Cash_Flow!J87-Cash_Flow!J102 -> #REF! | M49: =L49-Cash_Flow!K87-Cash_Flow!K102 -> #REF! | ... O49: =N49-Cash_Flow!M87-Cash_Flow!M102 -> #REF!
A50: =Input!A30 -> Senior Notes | C50: 0 | D50: =Input!C30 -> 65000 | E50: =SUM(C50:D50) -> 65000 | F50: =E50-Cash_Flow!D88-Cash_Flow!D103 -> #REF! | G50: =F50-Cash_Flow!E88-Cash_Flow!E103 -> #REF! | H50: =G50-Cash_Flow!F88-Cash_Flow!F103 -> #REF! | I50: =H50-Cash_Flow!G88-Cash_Flow!G103 -> #REF! | J50: =I50-Cash_Flow!H88-Cash_Flow!H103 -> #REF! | K50: =J50-Cash_Flow!I88-Cash_Flow!I103 -> #REF! | L50: =K50-Cash_Flow!J88-Cash_Flow!J103 -> #REF! | M50: =L50-Cash_Flow!K88-Cash_Flow!K103 -> #REF! | ... O50: =N50-Cash_Flow!M88-Cash_Flow!M103 -> #REF!
A51: =Input!A31 -> Subordinated Notes | C51: 0 | D51: =Input!C31 -> 40000 | E51: =SUM(C51:D51) -> 40000 | F51: =E51+Cash_Flow!D15-Cash_Flow!D89-Cash_Flow!D104 -> #REF! | G51: =F51+Cash_Flow!E15-Cash_Flow!E89-Cash_Flow!E104 -> #REF! | H51: =G51+Cash_Flow!F15-Cash_Flow!F89-Cash_Flow!F104 -> #REF! | I51: =H51+Cash_Flow!G15-Cash_Flow!G89-Cash_Flow!G104 -> #REF! | J51: =I51+Cash_Flow!H15-Cash_Flow!H89-Cash_Flow!H104 -> #REF! | K51: =J51+Cash_Flow!I15-Cash_Flow!I89-Cash_Flow!I104 -> #REF! | L51: =K51+Cash_Flow!J15-Cash_Flow!J89-Cash_Flow!J104 -> #REF! | M51: =L51+Cash_Flow!K15-Cash_Flow!K89-Cash_Flow!K104 -> #REF! | ... O51: =N51+Cash_Flow!M15-Cash_Flow!M89-Cash_Flow!M104 -> #REF!
A52: =Input!A32 -> Mezzanine Debt | C52: 0 | D52: =Input!C32 -> 70000 | E52: =SUM(C52:D52) -> 70000 | F52: =E52+Cash_Flow!D16-Cash_Flow!D90-Cash_Flow!D105 -> #REF! | G52: =F52+Cash_Flow!E16-Cash_Flow!E90-Cash_Flow!E105 -> #REF! | H52: =G52+Cash_Flow!F16-Cash_Flow!F90-Cash_Flow!F105 -> #REF! | I52: =H52+Cash_Flow!G16-Cash_Flow!G90-Cash_Flow!G105 -> #REF! | J52: =I52+Cash_Flow!H16-Cash_Flow!H90-Cash_Flow!H105 -> #REF! | K52: =J52+Cash_Flow!I16-Cash_Flow!I90-Cash_Flow!I105 -> #REF! | L52: =K52+Cash_Flow!J16-Cash_Flow!J90-Cash_Flow!J105 -> #REF! | M52: =L52+Cash_Flow!K16-Cash_Flow!K90-Cash_Flow!K105 -> #REF! | ... O52: =N52+Cash_Flow!M16-Cash_Flow!M90-Cash_Flow!M105 -> #REF!
A53: =Input!A33 -> Seller Notes | C53: 0 | D53: =Input!C33 -> 25000 | E53: =SUM(C53:D53) -> 25000 | F53: =E53+Cash_Flow!D17-Cash_Flow!D91-Cash_Flow!D106 -> #REF! | G53: =F53+Cash_Flow!E17-Cash_Flow!E91-Cash_Flow!E106 -> #REF! | H53: =G53+Cash_Flow!F17-Cash_Flow!F91-Cash_Flow!F106 -> #REF! | I53: =H53+Cash_Flow!G17-Cash_Flow!G91-Cash_Flow!G106 -> #REF! | J53: =I53+Cash_Flow!H17-Cash_Flow!H91-Cash_Flow!H106 -> #REF! | K53: =J53+Cash_Flow!I17-Cash_Flow!I91-Cash_Flow!I106 -> #REF! | L53: =K53+Cash_Flow!J17-Cash_Flow!J91-Cash_Flow!J106 -> #REF! | M53: =L53+Cash_Flow!K17-Cash_Flow!K91-Cash_Flow!K106 -> #REF! | ... O53: =N53+Cash_Flow!M17-Cash_Flow!M91-Cash_Flow!M106 -> #REF!
...

Sheet Cash_Flow
A2: Cash Flows
A4: Year | D4: 2016 | E4: =D4+1 -> 2017 | F4: =E4+1 -> 2018 | G4: =F4+1 -> 2019 | H4: =G4+1 -> 2020 | I4: =H4+1 -> 2021 | J4: =I4+1 -> 2022 | K4: =J4+1 -> 2023 | L4: =K4+1 -> 2024 | M4: =L4+1 -> 2025
A5: Year No. | D5: 1 | E5: =D5+1 -> 2 | F5: =E5+1 -> 3 | G5: =F5+1 -> 4 | H5: =G5+1 -> 5 | I5: =H5+1 -> 6 | J5: =I5+1 -> 7 | K5: =J5+1 -> 8 | L5: =K5+1 -> 9 | M5: =L5+1 -> 10
A7: Cash flows from operating activities
A9: =Inc_St!A49 -> Net Income to Common Shareholders | D9: =Inc_St!D49 -> #REF! | E9: =Inc_St!E49 -> #REF! | F9: =Inc_St!F49 -> #REF! | G9: =Inc_St!G49 -> #REF! | H9: =Inc_St!H49 -> #REF! | I9: =Inc_St!I49 -> #REF! | J9: =Inc_St!J49 -> #REF! | K9: =Inc_St!K49 -> #REF! | ... M9: =Inc_St!M49 -> #REF!
A11: Non-cash adjustments:
A12: Depreciation and amortization | D12: =Inc_St!D20 -> 72924.167 | E12: =Inc_St!E20 -> 85024.167 | F12: =Inc_St!F20 -> 93897.5 | G12: =Inc_St!G20 -> 104355.36 | H12: =Inc_St!H20 -> 117776.27 | I12: =Inc_St!I20 -> 128848.53 | J12: =Inc_St!J20 -> 101531.64 | K12: =Inc_St!K20 -> 115822.24 | ... M12: =Inc_St!M20 -> 149661.32
A13: Amortization of Capitalized Financing Costs | D13: =Inc_St!D36 -> #REF! | E13: =Inc_St!E36 -> #REF! | F13: =Inc_St!F36 -> #REF! | G13: =Inc_St!G36 -> #REF! | H13: =Inc_St!H36 -> #REF! | I13: =Inc_St!I36 -> #REF! | J13: =Inc_St!J36 -> #REF! | K13: =Inc_St!K36 -> #REF! | ... M13: =Inc_St!M36 -> #REF!
A14: Increase (Decrease) in Deferred Tax Liability | D14: =Income_Tax!D30 -> #REF! | E14: =Income_Tax!E30 -> #REF! | F14: =Income_Tax!F30 -> #REF! | G14: =Income_Tax!G30 -> #REF! | H14: =Income_Tax!H30 -> #REF! | I14: =Income_Tax!I30 -> #REF! | J14: =Income_Tax!J30 -> #REF! | K14: =Income_Tax!K30 -> #REF! | ... M14: =Income_Tax!M30 -> #REF!
A15: ="Accrued Interest "&Bal_Sheet!A51 -> Accrued Interest Subordinated Notes | D15: =IF(sub_notes_years_PIK>=D$5,Inc_St!D30,0) -> 1800 | E15: =IF(sub_notes_years_PIK>=E5,Inc_St!E30,0) -> #REF! | F15: =IF(sub_notes_years_PIK>=F5,Inc_St!F30,0) -> #REF! | G15: =IF(sub_notes_years_PIK>=G5,Inc_St!G30,0) -> #REF! | H15: =IF(sub_notes_years_PIK>=H5,Inc_St!H30,0) -> #REF! | I15: =IF(sub_notes_years_PIK>=I5,Inc_St!I30,0) -> 0 | J15: =IF(sub_notes_years_PIK>=J5,Inc_St!J30,0) -> 0 | K15: =IF(sub_notes_years_PIK>=K5,Inc_St!K30,0) -> 0 | L15: =IF(sub_notes_years_PIK>=L5,Inc_St!L30,0) -> 0 | M15: =IF(sub_notes_years_PIK>=M5,Inc_St!M30,0) -> 0
A16: ="Accrued Interest "&Bal_Sheet!A52 -> Accrued Interest Mezzanine Debt | D16: =IF(mezzdebt_years_PIK>=D$5,Inc_St!D31,0) -> 3150 | E16: =IF(mezzdebt_years_PIK>=E$5,Inc_St!E31,0) -> #REF! | F16: =IF(mezzdebt_years_PIK>=F$5,Inc_St!F31,0) -> #REF! | G16: =IF(mezzdebt_years_PIK>=G$5,Inc_St!G31,0) -> #REF! | H16: =IF(mezzdebt_years_PIK>=H$5,Inc_St!H31,0) -> #REF! | I16: =IF(mezzdebt_years_PIK>=I$5,Inc_St!I31,0) -> 0 | J16: =IF(mezzdebt_years_PIK>=J$5,Inc_St!J31,0) -> 0 | K16: =IF(mezzdebt_years_PIK>=K$5,Inc_St!K31,0) -> 0 | ... M16: =IF(mezzdebt_years_PIK>=M$5,Inc_St!M31,0) -> 0
A17: ="Accrued Interest "&Bal_Sheet!A53 -> Accrued Interest Seller Notes | D17: =IF(seller_notes_years_PIK>=D$5,Inc_St!D32,0) -> #REF! | E17: =IF(seller_notes_years_PIK>=E$5,Inc_St!E32,0) -> #REF! | F17: =IF(seller_notes_years_PIK>=F$5,Inc_St!F32,0) -> #REF! | G17: =IF(seller_notes_years_PIK>=G$5,Inc_St!G32,0) -> #REF! | H17: =IF(seller_notes_years_PIK>=H$5,Inc_St!H32,0) -> #REF! | I17: =IF(seller_notes_years_PIK>=I$5,Inc_St!I32,0) -> 0 | J17: =IF(seller_notes_years_PIK>=J$5,Inc_St!J32,0) -> 0 | K17: =IF(seller_notes_years_PIK>=K$5,Inc_St!K32,0) -> 0 | ... M17: =IF(seller_notes_years_PIK>=M$5,Inc_St!M32,0) -> 0
A18: ="Accrued Interest "&Bal_Sheet!A61 -> Accrued Interest Preferred Stock | D18: =IF(pref_stock_years_PIK>=D$5,Inc_St!D46,0) -> 4200 | E18: =IF(pref_stock_years_PIK>=E$5,Inc_St!E46,0) -> 4494 | F18: =IF(pref_stock_years_PIK>=F$5,Inc_St!F46,0) -> 4808.58 | G18: =IF(pref_stock_years_PIK>=G$5,Inc_St!G46,0) -> 5145.1806 | H18: =IF(pref_stock_years_PIK>=H$5,Inc_St!H46,0) -> 5505.3432 | I18: =IF(pref_stock_years_PIK>=I$5,Inc_St!I46,0) -> 0 | J18: =IF(pref_stock_years_PIK>=J$5,Inc_St!J46,0) -> 0 | K18: =IF(pref_stock_years_PIK>=K$5,Inc_St!K46,0) -> 0 | ... M18: =IF(pref_stock_years_PIK>=M$5,Inc_St!M46,0) -> 0
A20: Changes in operating assets and liabilities:
A21: (Increase) decrease in accounts receivable | D21: =-(Bal_Sheet!F11-Bal_Sheet!E11) -> -113000 | E21: =-(Bal_Sheet!G11-Bal_Sheet!F11) -> -30690 | F21: =-(Bal_Sheet!H11-Bal_Sheet!G11) -> -35446.95 | G21: =-(Bal_Sheet!I11-Bal_Sheet!H11) -> -40941.227 | H21: =-(Bal_Sheet!J11-Bal_Sheet!I11) -> -47287.117 | I21: =-(Bal_Sheet!K11-Bal_Sheet!J11) -> -54616.621 | J21: =-(Bal_Sheet!L11-Bal_Sheet!K11) -> -63082.197 | K21: =-(Bal_Sheet!M11-Bal_Sheet!L11) -> -72859.937 | ... M21: =-(Bal_Sheet!O11-Bal_Sheet!N11) -> -97196.978
A22: (Increase) decrease in inventories | D22: =-(Bal_Sheet!F12-Bal_Sheet!E12) -> -3001 | E22: =-(Bal_Sheet!G12-Bal_Sheet!F12) -> -14539.14 | F22: =-(Bal_Sheet!H12-Bal_Sheet!G12) -> -16674.358 | G22: =-(Bal_Sheet!I12-Bal_Sheet!H12) -> -19123.154 | H22: =-(Bal_Sheet!J12-Bal_Sheet!I12) -> -21931.581 | I22: =-(Bal_Sheet!K12-Bal_Sheet!J12) -> -25152.453 | J22: =-(Bal_Sheet!L12-Bal_Sheet!K12) -> -28846.342 | K22: =-(Bal_Sheet!M12-Bal_Sheet!L12) -> -33082.716 | ... M22: =-(Bal_Sheet!O12-Bal_Sheet!N12) -> -43513.294
A23: (Increase) decrease in prepaids & other assets | D23: =-(Bal_Sheet!F13-Bal_Sheet!E13)-(Bal_Sheet!F14-Bal_Sheet!E14) -> -114500 | E23: =-(Bal_Sheet!G13-Bal_Sheet!F13)-(Bal_Sheet!G14-Bal_Sheet!F14) -> -22869 | F23: =-(Bal_Sheet!H13-Bal_Sheet!G13)-(Bal_Sheet!H14-Bal_Sheet!G14) -> -25751.583 | G23: =-(Bal_Sheet!I13-Bal_Sheet!H13)-(Bal_Sheet!I14-Bal_Sheet!H14) -> -28997.643 | H23: =-(Bal_Sheet!J13-Bal_Sheet!I13)-(Bal_Sheet!J14-Bal_Sheet!I14) -> -32653.029 | I23: =-(Bal_Sheet!K13-Bal_Sheet!J13)-(Bal_Sheet!K14-Bal_Sheet!J14) -> -36769.376 | J23: =-(Bal_Sheet!L13-Bal_Sheet!K13)-(Bal_Sheet!L14-Bal_Sheet!K14) -> -41404.834 | K23: =-(Bal_Sheet!M13-Bal_Sheet!L13)-(Bal_Sheet!M14-Bal_Sheet!L14) -> -46624.89 | ... M23: =-(Bal_Sheet!O13-Bal_Sheet!N13)-(Bal_Sheet!O14-Bal_Sheet!N14) -> -59123.12
A24: Increase (decrease) in accounts payable | D24: =Bal_Sheet!F38-Bal_Sheet!E38 -> 22900.15 | E24: =Bal_Sheet!G38-Bal_Sheet!F38 -> 11041.11 | F24: =Bal_Sheet!H38-Bal_Sheet!G38 -> 10801.023 | G24: =Bal_Sheet!I38-Bal_Sheet!H38 -> 12166.038 | H24: =Bal_Sheet!J38-Bal_Sheet!I38 -> 13704.3 | I24: =Bal_Sheet!K38-Bal_Sheet!J38 -> 15437.921 | J24: =Bal_Sheet!L38-Bal_Sheet!K38 -> 17391.854 | K24: =Bal_Sheet!M38-Bal_Sheet!L38 -> 19594.267 | ... M24: =Bal_Sheet!O38-Bal_Sheet!N38 -> 24875.818
A25: Increase (decrease) in accrued exp & other liabilities | D25: =(Bal_Sheet!F39-Bal_Sheet!E39)+(Bal_Sheet!F40-Bal_Sheet!E40) -> 108000 | E25: =(Bal_Sheet!G39-Bal_Sheet!F39)+(Bal_Sheet!G40-Bal_Sheet!F40) -> 17457 | F25: =(Bal_Sheet!H39-Bal_Sheet!G39)+(Bal_Sheet!H40-Bal_Sheet!G40) -> 19437.017 | G25: =(Bal_Sheet!I39-Bal_Sheet!H39)+(Bal_Sheet!I40-Bal_Sheet!H40) -> 21641.742 | H25: =(Bal_Sheet!J39-Bal_Sheet!I39)+(Bal_Sheet!J40-Bal_Sheet!I40) -> 24096.692 | I25: =(Bal_Sheet!K39-Bal_Sheet!J39)+(Bal_Sheet!K40-Bal_Sheet!J40) -> 26830.283 | J25: =(Bal_Sheet!L39-Bal_Sheet!K39)+(Bal_Sheet!L40-Bal_Sheet!K40) -> 29874.16 | K25: =(Bal_Sheet!M39-Bal_Sheet!L39)+(Bal_Sheet!M40-Bal_Sheet!L40) -> 33263.563 | ... M25: =(Bal_Sheet!O39-Bal_Sheet!N39)+(Bal_Sheet!O40-Bal_Sheet!N40) -> 41240.389
A27: Net cash provided by (used in) operating activities | D27: =SUM(D9:D26) -> #REF! | E27: =SUM(E9:E26) -> #REF! | F27: =SUM(F9:F26) -> #REF! | G27: =SUM(G9:G26) -> #REF! | H27: =SUM(H9:H26) -> #REF! | I27: =SUM(I9:I26) -> #REF! | J27: =SUM(J9:J26) -> #REF! | K27: =SUM(K9:K26) -> #REF! | ... M27: =SUM(M9:M26) -> #REF!
A29: Cash flows from investing activities
A30: Purchase of property & equipment | D30: =-Bal_Sheet!F25 -> -110000 | E30: =-Bal_Sheet!G25 -> -121000 | F30: =-Bal_Sheet!H25 -> -133100 | G30: =-Bal_Sheet!I25 -> -146410 | H30: =-Bal_Sheet!J25 -> -161051 | I30: =-Bal_Sheet!K25 -> -177156.1 | J30: =-Bal_Sheet!L25 -> -194871.71 | K30: =-Bal_Sheet!M25 -> -214358.88 | ... M30: =-Bal_Sheet!O25 -> -259374.25
A31: (Increase) decrease in other long-term assets | D31: =-(Bal_Sheet!F22-Bal_Sheet!E22) -> -29000 | E31: =-(Bal_Sheet!G22-Bal_Sheet!F22) -> -4642 | F31: =-(Bal_Sheet!H22-Bal_Sheet!G22) -> -5131.731 | G31: =-(Bal_Sheet!I22-Bal_Sheet!H22) -> -5673.1286 | H31: =-(Bal_Sheet!J22-Bal_Sheet!I22) -> -6271.6437 | I31: =-(Bal_Sheet!K22-Bal_Sheet!J22) -> -6933.3021 | J31: =-(Bal_Sheet!L22-Bal_Sheet!K22) -> -7664.7655 | K31: =-(Bal_Sheet!M22-Bal_Sheet!L22) -> -8473.3982 | ... M31: =-(Bal_Sheet!O22-Bal_Sheet!N22) -> -10355.596
A33: Net cash provided by (used in) investing activities | D33: =SUM(D30:D32) -> -139000 | E33: =SUM(E30:E32) -> -125642 | F33: =SUM(F30:F32) -> -138231.73 | G33: =SUM(G30:G32) -> -152083.13 | H33: =SUM(H30:H32) -> -167322.64 | I33: =SUM(I30:I32) -> -184089.4 | J33: =SUM(J30:J32) -> -202536.48 | K33: =SUM(K30:K32) -> -222832.28 | ... M33: =SUM(M30:M32) -> -269729.84
A35: Cash flows from financing activities
A36: ="Increase (decrease) in "&Bal_Sheet!A46 -> Increase (decrease) in Existing Debt | D36: =-D85-D100 -> #REF! | E36: =-E85-E100 -> #REF! | F36: =-F85-F100 -> #REF! | G36: =-G85-G100 -> #REF! | H36: =-H85-H100 -> #REF! | I36: =-I85-I100 -> #REF! | J36: =-J85-J100 -> #REF! | K36: =-K85-K100 -> #REF! | ... M36: =-M85-M100 -> 0
A37: ="Increase (decrease) in "&Bal_Sheet!A48 -> Increase (decrease) in Term Loan "A" | D37: =-D86-D101 -> #REF! | E37: =-E86-E101 -> #REF! | F37: =-F86-F101 -> #REF! | G37: =-G86-G101 -> #REF! | H37: =-H86-H101 -> #REF! | I37: =-I86-I101 -> #REF! | J37: =-J86-J101 -> #REF! | K37: =-K86-K101 -> #REF! | ... M37: =-M86-M101 -> 0
A38: ="Increase (decrease) in "&Bal_Sheet!A49 -> Increase (decrease) in Term Loan "B" | D38: =-D87-D102 -> #REF! | E38: =-E87-E102 -> #REF! | F38: =-F87-F102 -> #REF! | G38: =-G87-G102 -> #REF! | H38: =-H87-H102 -> #REF! | I38: =-I87-I102 -> #REF! | J38: =-J87-J102 -> #REF! | K38: =-K87-K102 -> #REF! | ... M38: =-M87-M102 -> #REF!
A39: ="Increase (decrease) in "&Bal_Sheet!A50 -> Increase (decrease) in Senior Notes | D39: =-D88-D103 -> #REF! | E39: =-E88-E103 -> #REF! | F39: =-F88-F103 -> #REF! | G39: =-G88-G103 -> #REF! | H39: =-H88-H103 -> #REF! | I39: =-I88-I103 -> #REF! | J39: =-J88-J103 -> #REF! | K39: =-K88-K103 -> #REF! | ... M39: =-M88-M103 -> 0
A40: ="Increase (decrease) in "&Bal_Sheet!A51 -> Increase (decrease) in Subordinated Notes | D40: =-D89-D104 -> #REF! | E40: =-E89-E104 -> #REF! | F40: =-F89-F104 -> #REF! | G40: =-G89-G104 -> #REF! | H40: =-H89-H104 -> #REF! | I40: =-I89-I104 -> #REF! | J40: =-J89-J104 -> #REF! | K40: =-K89-K104 -> #REF! | ... M40: =-M89-M104 -> #REF!
A41: ="Increase (decrease) in "&Bal_Sheet!A52 -> Increase (decrease) in Mezzanine Debt | D41: =-D90-D105 -> #REF! | E41: =-E90-E105 -> #REF! | F41: =-F90-F105 -> #REF! | G41: =-G90-G105 -> #REF! | H41: =-H90-H105 -> #REF! | I41: =-I90-I105 -> #REF! | J41: =-J90-J105 -> #REF! | K41: =-K90-K105 -> #REF! | ... M41: =-M90-M105 -> #REF!
A42: ="Increase (decrease) in "&Bal_Sheet!A53 -> Increase (decrease) in Seller Notes | D42: =-D91-D106 -> #REF! | E42: =-E91-E106 -> #REF! | F42: =-F91-F106 -> #REF! | G42: =-G91-G106 -> #REF! | H42: =-H91-H106 -> #REF! | I42: =-I91-I106 -> #REF! | J42: =-J91-J106 -> #REF! | K42: =-K91-K106 -> 0 | ... M42: =-M91-M106 -> 0
A43: ="Increase (decrease) in "&Bal_Sheet!A61 -> Increase (decrease) in Preferred Stock | D43: =-D92 -> 0 | E43: =-E92 -> 0 | F43: =-F92 -> 0 | G43: =-G92 -> 0 | H43: =-H92 -> 0 | I43: =-I92 -> 0 | J43: =-J92 -> 0 | K43: =-K92 -> 0 | ... M43: =-M92 -> 0
A45: Net cash provided by (used in) financing activities | D45: =SUM(D36:D44) -> #REF! | E45: =SUM(E36:E44) -> #REF! | F45: =SUM(F36:F44) -> #REF! | G45: =SUM(G36:G44) -> #REF! | H45: =SUM(H36:H44) -> #REF! | I45: =SUM(I36:I44) -> #REF! | J45: =SUM(J36:J44) -> #REF! | K45: =SUM(K36:K44) -> #REF! | ... M45: =SUM(M36:M44) -> #REF!
A47: Net increase (decrease) in cash | D47: =D27+D33+D45 -> #REF! | E47: =E27+E33+E45 -> #REF! | F47: =F27+F33+F45 -> #REF! | G47: =G27+G33+G45 -> #REF! | H47: =H27+H33+H45 -> #REF! | I47: =I27+I33+I45 -> #REF! | J47: =J27+J33+J45 -> #REF! | K47: =K27+K33+K45 -> #REF! | ... M47: =M27+M33+M45 -> #REF!
A49: Cash at beginning of year | D49: =Bal_Sheet!E10 -> 77500 | E49: =D55 -> #REF! | F49: =E55 -> #REF! | G49: =F55 -> #REF! | H49: =G55 -> #REF! | I49: =H55 -> #REF! | J49: =I55 -> #REF! | K49: =J55 -> #REF! | L49: =K55 -> #REF! | M49: =L55 -> #REF!
A51: ="Cash available for "&Bal_Sheet!A47 -> Cash available for Bank Revolver | D51: =D47+D49 -> #REF! | E51: =E47+E49 -> #REF! | F51: =F47+F49 -> #REF! | G51: =G47+G49 -> #REF! | H51: =H47+H49 -> #REF! | I51: =I47+I49 -> #REF! | J51: =J47+J49 -> #REF! | K51: =K47+K49 -> #REF! | ... M51: =M47+M49 -> #REF!
A53: ="Added (retired) "&Bal_Sheet!A47 -> Added (retired) Bank Revolver | D53: =IF(cash_min=1,MIN(-MIN(Bal_Sheet!E47,D51-cash_min_amt),(revolver_limit-Bal_Sheet!E47)),MIN(-MIN(Bal_Sheet!E47,D51),(revolver_limit-Bal_Sheet!E47))) -> #REF! | E53: =IF(cash_min=1,MIN(-MIN(Bal_Sheet!F47,E51-cash_min_amt),(revolver_limit-Bal_Sheet!F47)),MIN(-MIN(Bal_Sheet!F47,E51),(revolver_limit-Bal_Sheet!F47))) -> #REF! | F53: =IF(cash_min=1,MIN(-MIN(Bal_Sheet!G47,F51-cash_min_amt),(revolver_limit-Bal_Sheet!G47)),MIN(-MIN(Bal_Sheet!G47,F51),(revolver_limit-Bal_Sheet!G47))) -> #REF! | G53: =IF(cash_min=1,MIN(-MIN(Bal_Sheet!H47,G51-cash_min_amt),(revolver_limit-Bal_Sheet!H47)),MIN(-MIN(Bal_Sheet!H47,G51),(revolver_limit-Bal_Sheet!H47))) -> #REF! | H53: =IF(cash_min=1,MIN(-MIN(Bal_Sheet!I47,H51-cash_min_amt),(revolver_limit-Bal_Sheet!I47)),MIN(-MIN(Bal_Sheet!I47,H51),(revolver_limit-Bal_Sheet!I47))) -> #REF! | I53: =IF(cash_min=1,MIN(-MIN(Bal_Sheet!J47,I51-cash_min_amt),(revolver_limit-Bal_Sheet!J47)),MIN(-MIN(Bal_Sheet!J47,I51),(revolver_limit-Bal_Sheet!J47))) -> #REF! | J53: =IF(cash_min=1,MIN(-MIN(Bal_Sheet!K47,J51-cash_min_amt),(revolver_limit-Bal_Sheet!K47)),MIN(-MIN(Bal_Sheet!K47,J51),(revolver_limit-Bal_Sheet!K47))) -> #REF! | K53: =IF(cash_min=1,MIN(-MIN(Bal_Sheet!L47,K51-cash_min_amt),(revolver_limit-Bal_Sheet!L47)),MIN(-MIN(Bal_Sheet!L47,K51),(revolver_limit-Bal_Sheet!L47))) -> #REF! | ... M53: =IF(cash_min=1,MIN(-MIN(Bal_Sheet!N47,M51-cash_min_amt),(revolver_limit-Bal_Sheet!N47)),MIN(-MIN(Bal_Sheet!N47,M51),(revolver_limit-Bal_Sheet!N47))) -> #REF!
A55: Cash at end of year | D55: =D51+D53 -> #REF! | E55: =E51+E53 -> #REF! | F55: =F51+F53 -> #REF! | G55: =G51+G53 -> #REF! | H55: =H51+H53 -> #REF! | I55: =I51+I53 -> #REF! | J55: =J51+J53 -> #REF! | K55: =K51+K53 -> #REF! | ... M55: =M51+M53 -> #REF!
A59: Free Cash Flows
...

Sheet Depr_Amort
A2: Depreciation & Amortization
A4: Book Depreciation & Amortization: | F4: =Bal_Sheet!A24 -> Gross PP&E | H4: =Bal_Sheet!C24 -> 500000 | J4: Depreciation Method | N4: Goodwill & Intangibles Amortization
F5: PP&E Write-up | H5: =Input!C49 -> 2450 | J5: 0 | K5: 0=SLN 1=Sum of Years | N5: 0=Not Deductible 1=Tax Deductible
F6: Fair Value PP&E | H6: =SUM(H4:H5) -> 502450 | N6: 1 | O6: =IF(N6=1,"Tax Deductible","Not Deductible") -> Tax Deductible
F7: Accumulated Depreciation | H7: =Bal_Sheet!C27 -> 25000 | J7: Manual or Computed Depreciation
F8: Net PP&E | H8: =H6-H7 -> 477450 | J8: 1 | K8: 0=Manual 1=Computed
A11: Year | F11: 2016 | G11: =F11+1 -> 2017 | H11: =G11+1 -> 2018 | I11: =H11+1 -> 2019 | J11: =I11+1 -> 2020 | K11: =J11+1 -> 2021 | L11: =K11+1 -> 2022 | M11: =L11+1 -> 2023 | N11: =M11+1 -> 2024 | O11: =N11+1 -> 2025
A12: Year No. | F12: 1 | G12: =F12+1 -> 2 | H12: =G12+1 -> 3 | I12: =H12+1 -> 4 | J12: =I12+1 -> 5 | K12: =J12+1 -> 6 | L12: =K12+1 -> 7 | M12: =L12+1 -> 8 | N12: =M12+1 -> 9 | O12: =N12+1 -> 10
A14: Existing PP&E (incl Write-up)
B15: Beginning Amt | C15: Remaining Life | D15: Salvage
A16: Class 1 | B16: 90000 | C16: 12 | D16: 900 | F16: =IF(F$12>$C16,0,IF($J$5=1,SYD($B16,$D16,$C16,F$12),SLN($B16,$D16,$C16))) -> 7425 | G16: =IF(G$12>$C16,0,IF($J$5=1,SYD($B16,$D16,$C16,G$12),SLN($B16,$D16,$C16))) -> 7425 | H16: =IF(H$12>$C16,0,IF($J$5=1,SYD($B16,$D16,$C16,H$12),SLN($B16,$D16,$C16))) -> 7425 | I16: =IF(I$12>$C16,0,IF($J$5=1,SYD($B16,$D16,$C16,I$12),SLN($B16,$D16,$C16))) -> 7425 | J16: =IF(J$12>$C16,0,IF($J$5=1,SYD($B16,$D16,$C16,J$12),SLN($B16,$D16,$C16))) -> 7425 | K16: =IF(K$12>$C16,0,IF($J$5=1,SYD($B16,$D16,$C16,K$12),SLN($B16,$D16,$C16))) -> 7425 | L16: =IF(L$12>$C16,0,IF($J$5=1,SYD($B16,$D16,$C16,L$12),SLN($B16,$D16,$C16))) -> 7425 | M16: =IF(M$12>$C16,0,IF($J$5=1,SYD($B16,$D16,$C16,M$12),SLN($B16,$D16,$C16))) -> 7425 | ... O16: =IF(O$12>$C16,0,IF($J$5=1,SYD($B16,$D16,$C16,O$12),SLN($B16,$D16,$C16))) -> 7425
A17: Class 2 | B17: 85000 | C17: 10 | D17: 800 | F17: =IF(F$12>$C17,0,IF($J$5=1,SYD($B17,$D17,$C17,F$12),SLN($B17,$D17,$C17))) -> 8420 | G17: =IF(G$12>$C17,0,IF($J$5=1,SYD($B17,$D17,$C17,G$12),SLN($B17,$D17,$C17))) -> 8420 | H17: =IF(H$12>$C17,0,IF($J$5=1,SYD($B17,$D17,$C17,H$12),SLN($B17,$D17,$C17))) -> 8420 | I17: =IF(I$12>$C17,0,IF($J$5=1,SYD($B17,$D17,$C17,I$12),SLN($B17,$D17,$C17))) -> 8420 | J17: =IF(J$12>$C17,0,IF($J$5=1,SYD($B17,$D17,$C17,J$12),SLN($B17,$D17,$C17))) -> 8420 | K17: =IF(K$12>$C17,0,IF($J$5=1,SYD($B17,$D17,$C17,K$12),SLN($B17,$D17,$C17))) -> 8420 | L17: =IF(L$12>$C17,0,IF($J$5=1,SYD($B17,$D17,$C17,L$12),SLN($B17,$D17,$C17))) -> 8420 | M17: =IF(M$12>$C17,0,IF($J$5=1,SYD($B17,$D17,$C17,M$12),SLN($B17,$D17,$C17))) -> 8420 | ... O17: =IF(O$12>$C17,0,IF($J$5=1,SYD($B17,$D17,$C17,O$12),SLN($B17,$D17,$C17))) -> 8420
