Workbook

Sheet Assumptions
B2: LBO MODEL ASSUMPTIONS
B4: TRANSACTION ASSUMPTIONS
B5: Target Company Revenue (LTM) | C5: 500 | D5: $ millions
B6: Target EBITDA Margin (LTM) | C6: 0.2
B7: Target EBITDA (LTM) | C7: =C5*C6 -> 100 | D7: $ millions
B8: Purchase Price Multiple (EV/EBITDA) | C8: 10 | D8: x
B9: Enterprise Value | C9: =C7*C8 -> 1000 | D9: $ millions
B10: Less: Existing Debt | C10: 150 | D10: $ millions
B11: Plus: Cash | C11: 50 | D11: $ millions
B12: Equity Value | C12: =C9-C10+C11 -> 900 | D12: $ millions
B13: Transaction Fees (% of EV) | C13: 0.02
B14: Transaction Fees ($) | C14: =C9*C13 -> 20 | D14: $ millions
B15: Financing Fees (% of Debt) | C15: 0.03
B17: OPERATING ASSUMPTIONS
B18: Revenue Growth - Year 1 | C18: 0.1
B19: Revenue Growth - Year 2 | C19: 0.09
B20: Revenue Growth - Year 3 | C20: 0.08
B21: Revenue Growth - Year 4 | C21: 0.08
B22: Revenue Growth - Year 5 | C22: 0.08
B23: EBITDA Margin - Year 1 | C23: 0.2
B24: EBITDA Margin - Year 2 | C24: 0.21
B25: EBITDA Margin - Year 3 | C25: 0.21
B26: EBITDA Margin - Year 4 | C26: 0.22
B27: EBITDA Margin - Year 5 | C27: 0.22
B28: CapEx (% of Revenue) | C28: 0.03
B29: Net Working Capital (% of Revenue) | C29: 0.1
... B31: D&A (% of Revenue) | C31: 0.04
B33: DEBT STRUCTURE
B34: Revolver (% of EV) | C34: 0.05
B35: Revolver Interest Rate | C35: 0.055
B36: Term Loan A (% of EV) | C36: 0.2
B37: TLA Interest Rate | C37: 0.065
B38: TLA Amortization (% per year) | C38: 0.05
B39: Term Loan B (% of EV) | C39: 0.3
B40: TLB Interest Rate | C40: 0.075
B41: TLB Amortization (% per year) | C41: 0.01
B42: Subordinated Debt (% of EV) | C42: 0.1
B43: Sub Debt Interest Rate | C43: 0.095
B44: Sub Debt Amortization | C44: 0 | D44: Bullet at exit
B45: Total Debt (% of EV) | C45: =C34+C36+C39+C42 -> 0.65
...

Sheet Calcs
B2: SOURCES & USES
B4: SOURCES | C4: $M | D4: %
B5: Revolver | C5: =Assumptions!C9*Assumptions!C34 -> 50 | D5: =C5/C10 -> 0.045892611
B6: Term Loan A | C6: =Assumptions!C9*Assumptions!C36 -> 200 | D6: =C6/C10 -> 0.18357045
B7: Term Loan B | C7: =Assumptions!C9*Assumptions!C39 -> 300 | D7: =C7/C10 -> 0.27535567
B8: Subordinated Debt | C8: =Assumptions!C9*Assumptions!C42 -> 100 | D8: =C8/C10 -> 0.091785223
B9: Sponsor Equity | C9: =C17-C5-C6-C7-C8 -> 439.5 | D9: =C9/C10 -> 0.40339605
B10: Total Sources | C10: =SUM(C5:C9) -> 1089.5 | D10: =SUM(D5:D9) -> 1
B12: USES
B13: Cash to Target Equity Holders | C13: {=Assumptions!C12} -> 900 | D13: =C13/C17 -> 0.826067
B14: Refinance Existing Debt | C14: {=Assumptions!C10} -> 150 | D14: =C14/C17 -> 0.13767783
B15: Transaction Fees | C15: {=Assumptions!C14} -> 20 | D15: =C15/C17 -> 0.018357045
B16: Financing Fees | C16: =(C5+C6+C7+C8)*Assumptions!C15 -> 19.5 | D16: =C16/C17 -> 0.017898118
B17: Total Uses | C17: =SUM(C13:C16) -> 1089.5 | D17: =SUM(D13:D16) -> 1
B19: Sources - Uses | C19: =C10-C17 -> 0
B22: PROFIT & LOSS PROJECTION
B24: ($M) | C24: Year 0 | D24: Year 1 | E24: Year 2 | F24: Year 3 | G24: Year 4 | H24: Year 5
B25: Revenue | C25: {=Assumptions!C5} -> 500 | D25: =C25*(1+Assumptions!C18) -> 550 | E25: =D25*(1+Assumptions!C19) -> 599.5 | F25: =E25*(1+Assumptions!C20) -> 647.46 | G25: =F25*(1+Assumptions!C21) -> 699.2568 | H25: =G25*(1+Assumptions!C22) -> 755.19734
B26: EBITDA | C26: {=Assumptions!C7} -> 100 | D26: =D25*Assumptions!C23 -> 110 | E26: =E25*Assumptions!C24 -> 125.895 | F26: =F25*Assumptions!C25 -> 135.9666 | G26: =G25*Assumptions!C26 -> 153.8365 | H26: =H25*Assumptions!C27 -> 166.14342
B27: Less: D&A | C27: =C25*Assumptions!C31 -> 20 | D27: =D25*Assumptions!C31 -> 22 | E27: =E25*Assumptions!C31 -> 23.98 | F27: =F25*Assumptions!C31 -> 25.8984 | G27: =G25*Assumptions!C31 -> 27.970272 | H27: =H25*Assumptions!C31 -> 30.207894
B28: EBIT | C28: =C26-C27 -> 80 | D28: =D26-D27 -> 88 | E28: =E26-E27 -> 101.915 | F28: =F26-F27 -> 110.0682 | G28: =G26-G27 -> 125.86622 | H28: =H26-H27 -> 135.93552
B29: Less: Interest Expense | C29: 0 | D29: {=D54} -> 47.75 | E29: {=E54} -> 47.75 | F29: {=F54} -> 46.875 | G29: {=G54} -> 46 | H29: {=H54} -> 45.125
B30: EBT | C30: =C28-C29 -> 80 | D30: =D28-D29 -> 40.25 | E30: =E28-E29 -> 54.165 | F30: =F28-F29 -> 63.1932 | G30: =G28-G29 -> 79.866224 | H30: =H28-H29 -> 90.810522
B31: Less: Tax | C31: =C30*Assumptions!C30 -> 20 | D31: =D30*Assumptions!C30 -> 10.0625 | E31: =E30*Assumptions!C30 -> 13.54125 | F31: =F30*Assumptions!C30 -> 15.7983 | G31: =G30*Assumptions!C30 -> 19.966556 | H31: =H30*Assumptions!C30 -> 22.70263
B32: Net Income | C32: =C30-C31 -> 60 | D32: =D30-D31 -> 30.1875 | E32: =E30-E31 -> 40.62375 | F32: =F30-F31 -> 47.3949 | G32: =G30-G31 -> 59.899668 | H32: =H30-H31 -> 68.107891
B35: DEBT SCHEDULE
B37: ($M) | C37: Year 0 | D37: Year 1 | E37: Year 2 | F37: Year 3 | G37: Year 4 | H37: Year 5
B38: Revolver - Beginning | C38: {=C5} -> 50 | D38: {=C38} -> 50 | E38: {=D38} -> 50 | F38: {=E38} -> 50 | G38: {=F38} -> 50 | H38: {=G38} -> 50
B39: Revolver - Interest | C39: 0 | D39: =C38*Assumptions!C35 -> 2.75 | E39: =D38*Assumptions!C35 -> 2.75 | F39: =E38*Assumptions!C35 -> 2.75 | G39: =F38*Assumptions!C35 -> 2.75 | H39: =G38*Assumptions!C35 -> 2.75
B40: Revolver - Ending | C40: {=C38} -> 50 | D40: {=D38} -> 50 | E40: {=E38} -> 50 | F40: {=F38} -> 50 | G40: {=G38} -> 50 | H40: {=H38} -> 50
B41: TLA - Beginning | C41: {=C6} -> 200 | D41: {=C44} -> 200 | E41: {=D44} -> 190 | F41: {=E44} -> 180 | G41: {=F44} -> 170 | H41: {=G44} -> 160
B42: TLA - Amortization | C42: 0 | D42: =C6*Assumptions!C38 -> 10 | E42: =C6*Assumptions!C38 -> 10 | F42: =C6*Assumptions!C38 -> 10 | G42: =C6*Assumptions!C38 -> 10 | H42: =C6*Assumptions!C38 -> 10
B43: TLA - Interest | C43: 0 | D43: =C41*Assumptions!C37 -> 13 | E43: =D41*Assumptions!C37 -> 13 | F43: =E41*Assumptions!C37 -> 12.35 | G43: =F41*Assumptions!C37 -> 11.7 | H43: =G41*Assumptions!C37 -> 11.05
B44: TLA - Ending | C44: {=C41} -> 200 | D44: =D41-D42 -> 190 | E44: =E41-E42 -> 180 | F44: =F41-F42 -> 170 | G44: =G41-G42 -> 160 | H44: =H41-H42 -> 150
B45: TLB - Beginning | C45: {=C7} -> 300 | D45: {=C48} -> 300 | E45: {=D48} -> 297 | F45: {=E48} -> 294 | G45: {=F48} -> 291 | H45: {=G48} -> 288
B46: TLB - Amortization | C46: 0 | D46: =C7*Assumptions!C41 -> 3 | E46: =C7*Assumptions!C41 -> 3 | F46: =C7*Assumptions!C41 -> 3 | G46: =C7*Assumptions!C41 -> 3 | H46: =C7*Assumptions!C41 -> 3
B47: TLB - Interest | C47: 0 | D47: =C45*Assumptions!C40 -> 22.5 | E47: =D45*Assumptions!C40 -> 22.5 | F47: =E45*Assumptions!C40 -> 22.275 | G47: =F45*Assumptions!C40 -> 22.05 | H47: =G45*Assumptions!C40 -> 21.825
B48: TLB - Ending | C48: {=C45} -> 300 | D48: =D45-D46 -> 297 | E48: =E45-E46 -> 294 | F48: =F45-F46 -> 291 | G48: =G45-G46 -> 288 | H48: =H45-H46 -> 285
B49: Sub Debt - Beginning | C49: {=C8} -> 100 | D49: {=C51} -> 100 | E49: {=D51} -> 100 | F49: {=E51} -> 100 | G49: {=F51} -> 100 | H49: {=G51} -> 100
B50: Sub Debt - Interest | C50: 0 | D50: =C49*Assumptions!C43 -> 9.5 | E50: =D49*Assumptions!C43 -> 9.5 | F50: =E49*Assumptions!C43 -> 9.5 | G50: =F49*Assumptions!C43 -> 9.5 | H50: =G49*Assumptions!C43 -> 9.5
...

Sheet Dashboard
B2: LBO MODEL DASHBOARD
B5: PURCHASE PRICE | F5: MODEL CHECKS
B6: Enterprise Value | C6: {=Assumptions!C9} -> 1000 | F6: Sources = Uses? | G6: =IF(ABS(C30)<0.01,"PASS","FAIL") -> PASS
B7: Less: Existing Debt | C7: {=Assumptions!C10} -> 150 | F7: Initial Debt Balance | G7: {=C39} -> 637
B8: Plus: Cash | C8: {=Assumptions!C11} -> 50 | F8: Debt Paydown (5 yrs) | G8: =C39-G39 -> 52
B9: Equity Value | C9: {=Assumptions!C12} -> 900 | F9: % Debt Reduction | G9: =G8/C39 -> 0.081632653
B11: Purchase Multiple (EV/EBITDA) | C11: {=Assumptions!C8} -> 10
B14: SOURCES & USES | F14: TRANSACTION SUMMARY
B15: SOURCES | C15: $M | D15: % | F15: Target LTM Revenue | G15: {=Assumptions!C5} -> 500
B16: Revolver | C16: {=Calcs!C5} -> 50 | D16: {=Calcs!D5} -> 0.045892611 | F16: Target LTM EBITDA | G16: {=Assumptions!C7} -> 100
B17: Term Loan A | C17: {=Calcs!C6} -> 200 | D17: {=Calcs!D6} -> 0.18357045 | F17: Purchase Multiple | G17: {=Assumptions!C8} -> 10
B18: Term Loan B | C18: {=Calcs!C7} -> 300 | D18: {=Calcs!D7} -> 0.27535567 | F18: Total Debt / EBITDA | G18: =C39/Assumptions!C7 -> 6.37
B19: Subordinated Debt | C19: {=Calcs!C8} -> 100 | D19: {=Calcs!D8} -> 0.091785223 | F19: Equity / Total Capital | G19: =C20/C21 -> 0.40339605
B20: Sponsor Equity | C20: {=Calcs!C9} -> 439.5 | D20: {=Calcs!D9} -> 0.40339605
B21: Total Sources | C21: {=Calcs!C10} -> 1089.5 | D21: {=Calcs!D10} -> 1
B23: USES | C23: $M | D23: %
B24: Cash to Target Equity | C24: {=Calcs!C13} -> 900 | D24: {=Calcs!D13} -> 0.826067
B25: Refinance Existing Debt | C25: {=Calcs!C14} -> 150 | D25: {=Calcs!D14} -> 0.13767783
B26: Transaction Fees | C26: {=Calcs!C15} -> 20 | D26: {=Calcs!D15} -> 0.018357045
B27: Financing Fees | C27: {=Calcs!C16} -> 19.5 | D27: {=Calcs!D16} -> 0.017898118
B28: Total Uses | C28: {=Calcs!C17} -> 1089.5 | D28: {=Calcs!D17} -> 1
B30: Sources - Uses | C30: =C21-C28 -> 0
B33: 5-YEAR FORECAST
B34: ($M) | C34: 2023F | D34: 2024F | E34: 2025F | F34: 2026F | G34: 2027F | J34: Year | K34: Total Debt | L34: EBITDA
B35: Revenue | C35: {=Calcs!D25} -> 550 | D35: {=Calcs!E25} -> 599.5 | E35: {=Calcs!F25} -> 647.46 | F35: {=Calcs!G25} -> 699.2568 | G35: {=Calcs!H25} -> 755.19734 | J35: 2023 | K35: {=C39} -> 637 | L35: {=C36} -> 110
B36: EBITDA | C36: {=Calcs!D26} -> 110 | D36: {=Calcs!E26} -> 125.895 | E36: {=Calcs!F26} -> 135.9666 | F36: {=Calcs!G26} -> 153.8365 | G36: {=Calcs!H26} -> 166.14342 | J36: 2024 | K36: {=D39} -> 624 | L36: {=D36} -> 125.895
B37: EBITDA Margin | C37: =C36/C35 -> 0.2 | D37: =D36/D35 -> 0.21 | E37: =E36/E35 -> 0.21 | F37: =F36/F35 -> 0.22 | G37: =G36/G35 -> 0.22 | J37: 2025 | K37: {=E39} -> 611 | L37: {=E36} -> 135.9666
B38: Free Cash Flow | C38: {=Calcs!D65} -> 47.1875 | D38: {=Calcs!E65} -> 64.60375 | E38: {=Calcs!F65} -> 73.2933 | F38: {=Calcs!G65} -> 87.86994 | G38: {=Calcs!H65} -> 98.315785 | J38: 2026 | K38: {=F39} -> 598 | L38: {=F36} -> 153.8365
B39: Total Debt | C39: {=Calcs!D53} -> 637 | D39: {=Calcs!E53} -> 624 | E39: {=Calcs!F53} -> 611 | F39: {=Calcs!G53} -> 598 | G39: {=Calcs!H53} -> 585 | J39: 2027 | K39: {=G39} -> 585 | L39: {=G36} -> 166.14342
B40: Net Debt / EBITDA | C40: {=Calcs!D70} -> 5.7909091 | D40: {=Calcs!E70} -> 4.9565114 | E40: {=Calcs!F70} -> 4.4937507 | F40: {=Calcs!G70} -> 3.887244 | G40: {=Calcs!H70} -> 3.5210544
B41: DSCR | C41: {=Calcs!D71} -> 2.3036649 | D41: {=Calcs!E71} -> 2.6365445 | E41: {=Calcs!F71} -> 2.9006208 | F41: {=Calcs!G71} -> 3.3442717 | G41: {=Calcs!H71} -> 3.6818485
J42: Year | K42: Net Debt/EBITDA | L42: DSCR
J43: 2023 | K43: {=C40} -> 5.7909091 | L43: {=C41} -> 2.3036649
B44: SPONSOR RETURNS | J44: 2024 | K44: {=D40} -> 4.9565114 | L44: {=D41} -> 2.6365445
B45: Initial Equity Investment | C45: {=Calcs!C80} -> 439.5 | J45: 2025 | K45: {=E40} -> 4.4937507 | L45: {=E41} -> 2.9006208
B46: Exit Equity Value | C46: {=Calcs!C79} -> 1076.4342 | J46: 2026 | K46: {=F40} -> 3.887244 | L46: {=F41} -> 3.3442717
B47: Cash-on-Cash Multiple | C47: {=Calcs!C81} -> 2.4492245 | J47: 2027 | K47: {=G40} -> 3.5210544 | L47: {=G41} -> 3.6818485
B48: Implied IRR (approx) | C48: =(C47^(1/5))-1 -> 0.19620529
