Workbook

Sheet Cover_Assumptions
B2: DCF VALUATION MODEL
B3: Mid-Cap SaaS Company
B4: As of 2025-11-19
B6: OPERATING ASSUMPTIONS
B7: Revenue Growth Rate (Historical)
C8: 2020 | D8: 2021 | E8: 2022 | F8: 2023 | G8: 2024
C9: 0.2 | D9: 0.19 | E9: 0.17 | F9: 0.15 | G9: 0.14
B11: Revenue Growth Rate (Forecast)
C12: 2025 | D12: 2026 | E12: 2027 | F12: 2028 | G12: 2029 | H12: 2030 | I12: 2031 | J12: 2032 | K12: 2033 | L12: 2034
C13: 0.18 | D13: 0.16 | E13: 0.14 | F13: 0.12 | G13: 0.1 | H13: 0.09 | I13: 0.08 | J13: 0.07 | K13: 0.06 | L13: 0.05
B15: EBITDA Margin | C15: 0.3
B16: D&A % of Revenue | C16: 0.02
B17: Capex % of Revenue | C17: 0.03
B18: NWC % of Revenue | C18: 0.01
B20: WACC COMPONENTS
B21: Risk-Free Rate | C21: 0.04
B22: Beta | C22: 1.2
B23: Market Return | C23: 0.1
B24: Size Premium | C24: 0.02
B25: Country Risk Premium | C25: 0
B27: TERMINAL VALUE ASSUMPTIONS
B28: Terminal Growth Rate | C28: 0.025
B29: Exit EBITDA Multiple | C29: 15
B31: CAPITAL STRUCTURE & TAX
B32: Tax Rate | C32: 0.25
B33: Interest Rate on Debt | C33: 0.05
B34: Shares Outstanding (mm) | C34: 50
B36: BASE YEAR (2024)
B37: Revenue ($ millions) | C37: 250

Sheet Income_Statement
B2: INCOME STATEMENT
B3: ($ millions)
C5: 2020 | D5: 2021 | E5: 2022 | F5: 2023 | G5: 2024 | H5: 2025 | I5: 2026 | J5: 2027 | K5: 2028 | L5: 2029 | M5: 2030 | N5: 2031 | O5: 2032 | P5: 2033 | Q5: 2034
B7: Revenue | C7: =D7/(1+Cover_Assumptions!C9) -> 130.11522 | D7: =E7/(1+Cover_Assumptions!D9) -> 156.13826 | E7: =F7/(1+Cover_Assumptions!E9) -> 185.80453 | F7: =G7/(1+Cover_Assumptions!F9) -> 217.3913 | G7: {=Cover_Assumptions!C37} -> 250 | H7: =G7*(1+Cover_Assumptions!C13) -> 295 | I7: =H7*(1+Cover_Assumptions!D13) -> 342.2 | J7: =I7*(1+Cover_Assumptions!E13) -> 390.108 | K7: =J7*(1+Cover_Assumptions!F13) -> 436.92096 | L7: =K7*(1+Cover_Assumptions!G13) -> 480.61306 | M7: =L7*(1+Cover_Assumptions!H13) -> 523.86823 | N7: =M7*(1+Cover_Assumptions!I13) -> 565.77769 | O7: =N7*(1+Cover_Assumptions!J13) -> 605.38213 | ... Q7: =P7*(1+Cover_Assumptions!L13) -> 673.79031
B8: Growth Rate % | C8: {=Cover_Assumptions!C9} -> 0.2 | D8: {=Cover_Assumptions!D9} -> 0.19 | E8: {=Cover_Assumptions!E9} -> 0.17 | F8: {=Cover_Assumptions!F9} -> 0.15 | G8: {=Cover_Assumptions!G9} -> 0.14 | H8: {=Cover_Assumptions!C13} -> 0.18 | I8: {=Cover_Assumptions!D13} -> 0.16 | J8: {=Cover_Assumptions!E13} -> 0.14 | K8: {=Cover_Assumptions!F13} -> 0.12 | L8: {=Cover_Assumptions!G13} -> 0.1 | M8: {=Cover_Assumptions!H13} -> 0.09 | N8: {=Cover_Assumptions!I13} -> 0.08 | O8: {=Cover_Assumptions!J13} -> 0.07 | ... Q8: {=Cover_Assumptions!L13} -> 0.05
B10: EBITDA | C10: =C7*Cover_Assumptions!$C$15 -> 39.034566 | D10: =D7*Cover_Assumptions!$C$15 -> 46.841479 | E10: =E7*Cover_Assumptions!$C$15 -> 55.74136 | F10: =F7*Cover_Assumptions!$C$15 -> 65.217391 | G10: =G7*Cover_Assumptions!$C$15 -> 75 | H10: =H7*Cover_Assumptions!$C$15 -> 88.5 | I10: =I7*Cover_Assumptions!$C$15 -> 102.66 | J10: =J7*Cover_Assumptions!$C$15 -> 117.0324 | ... Q10: =Q7*Cover_Assumptions!$C$15 -> 202.13709
B11: EBITDA Margin % | C11: =C10/C7 -> 0.3 | D11: =D10/D7 -> 0.3 | E11: =E10/E7 -> 0.3 | F11: =F10/F7 -> 0.3 | G11: =G10/G7 -> 0.3 | H11: =H10/H7 -> 0.3 | I11: =I10/I7 -> 0.3 | J11: =J10/J7 -> 0.3 | ... Q11: =Q10/Q7 -> 0.3
B13: Depreciation & Amortization | C13: =C7*Cover_Assumptions!$C$16 -> 2.6023044 | D13: =D7*Cover_Assumptions!$C$16 -> 3.1227653 | E13: =E7*Cover_Assumptions!$C$16 -> 3.7160907 | F13: =F7*Cover_Assumptions!$C$16 -> 4.3478261 | G13: =G7*Cover_Assumptions!$C$16 -> 5 | H13: =H7*Cover_Assumptions!$C$16 -> 5.9 | I13: =I7*Cover_Assumptions!$C$16 -> 6.844 | J13: =J7*Cover_Assumptions!$C$16 -> 7.80216 | ... Q13: =Q7*Cover_Assumptions!$C$16 -> 13.475806
B15: EBIT | C15: =C10-C13 -> 36.432261 | D15: =D10-D13 -> 43.718714 | E15: =E10-E13 -> 52.025269 | F15: =F10-F13 -> 60.869565 | G15: =G10-G13 -> 70 | H15: =H10-H13 -> 82.6 | I15: =I10-I13 -> 95.816 | J15: =J10-J13 -> 109.23024 | ... Q15: =Q10-Q13 -> 188.66129
B17: Interest Expense | C17: {=Debt_Schedule!C14} -> 2.5 | D17: {=Debt_Schedule!D14} -> 2.5 | E17: {=Debt_Schedule!E14} -> 2.5 | F17: {=Debt_Schedule!F14} -> 2.5 | G17: {=Debt_Schedule!G14} -> 2.5 | H17: {=Debt_Schedule!H14} -> 2.5 | I17: {=Debt_Schedule!I14} -> 2.5 | J17: {=Debt_Schedule!J14} -> 2.5 | ... Q17: {=Debt_Schedule!Q14} -> 2.5
B19: EBT | C19: =C15-C17 -> 33.932261 | D19: =D15-D17 -> 41.218714 | E19: =E15-E17 -> 49.525269 | F19: =F15-F17 -> 58.369565 | G19: =G15-G17 -> 67.5 | H19: =H15-H17 -> 80.1 | I19: =I15-I17 -> 93.316 | J19: =J15-J17 -> 106.73024 | ... Q19: =Q15-Q17 -> 186.16129
B21: Tax Expense | C21: {=Tax_Schedule!C9} -> 8.4830654 | D21: {=Tax_Schedule!D9} -> 10.304678 | E21: {=Tax_Schedule!E9} -> 12.381317 | F21: {=Tax_Schedule!F9} -> 14.592391 | G21: {=Tax_Schedule!G9} -> 16.875 | H21: {=Tax_Schedule!H9} -> 20.025 | I21: {=Tax_Schedule!I9} -> 23.329 | J21: {=Tax_Schedule!J9} -> 26.68256 | ... Q21: {=Tax_Schedule!Q9} -> 46.540322
B23: Net Income | C23: =C19-C21 -> 25.449196 | D23: =D19-D21 -> 30.914035 | E23: =E19-E21 -> 37.143952 | F23: =F19-F21 -> 43.777174 | G23: =G19-G21 -> 50.625 | H23: =H19-H21 -> 60.075 | I23: =I19-I21 -> 69.987 | J23: =J19-J21 -> 80.04768 | ... Q23: =Q19-Q21 -> 139.62096

Sheet Balance_Sheet
B2: BALANCE SHEET
B3: ($ millions)
C5: 2020 | D5: 2021 | E5: 2022 | F5: 2023 | G5: 2024 | H5: 2025 | I5: 2026 | J5: 2027 | K5: 2028 | L5: 2029 | M5: 2030 | N5: 2031 | O5: 2032 | P5: 2033 | Q5: 2034
B7: ASSETS
B8: Cash | C8: 104 | D8: =C8+Cash_Flow!D23 -> 133.09242 | E8: =D8+Cash_Flow!E23 -> 168.08167 | F8: =E8+Cash_Flow!F23 -> 209.36906 | G8: =F8+Cash_Flow!G23 -> 257.16797 | H8: =G8+Cash_Flow!H23 -> 313.84297 | I8: =H8+Cash_Flow!I23 -> 379.93597 | J8: =I8+Cash_Flow!J23 -> 455.60349 | K8: =J8+Cash_Flow!K23 -> 540.64455 | ... Q8: =P8+Cash_Flow!Q23 -> 1225.2532
B9: Accounts Receivable | C9: {=Working_Capital!C9} -> 0.6505761 | D9: {=Working_Capital!D9} -> 0.78069132 | E9: {=Working_Capital!E9} -> 0.92902267 | F9: {=Working_Capital!F9} -> 1.0869565 | G9: {=Working_Capital!G9} -> 1.25 | H9: {=Working_Capital!H9} -> 1.475 | I9: {=Working_Capital!I9} -> 1.711 | J9: {=Working_Capital!J9} -> 1.95054 | ... Q9: {=Working_Capital!Q9} -> 3.3689515
B10: Inventory | C10: {=Working_Capital!C10} -> 0.39034566 | D10: {=Working_Capital!D10} -> 0.46841479 | E10: {=Working_Capital!E10} -> 0.5574136 | F10: {=Working_Capital!F10} -> 0.65217391 | G10: {=Working_Capital!G10} -> 0.75 | H10: {=Working_Capital!H10} -> 0.885 | I10: {=Working_Capital!I10} -> 1.0266 | J10: {=Working_Capital!J10} -> 1.170324 | ... Q10: {=Working_Capital!Q10} -> 2.0213709
B11: PP&E, Net | C11: {=Depreciation_Capex!C10} -> 20.818435 | D11: {=Depreciation_Capex!D10} -> 22.379818 | E11: {=Depreciation_Capex!E10} -> 24.237863 | F11: {=Depreciation_Capex!F10} -> 26.411776 | G11: {=Depreciation_Capex!G10} -> 28.911776 | H11: {=Depreciation_Capex!H10} -> 31.861776 | I11: {=Depreciation_Capex!I10} -> 35.283776 | J11: {=Depreciation_Capex!J10} -> 39.184856 | ... Q11: {=Depreciation_Capex!Q10} -> 78.46543
B12: Total Assets | C12: =C8+C9+C10+C11 -> 125.85936 | D12: =D8+D9+D10+D11 -> 156.72135 | E12: =E8+E9+E10+E11 -> 193.80597 | F12: =F8+F9+F10+F11 -> 237.51997 | G12: =G8+G9+G10+G11 -> 288.07975 | H12: =H8+H9+H10+H11 -> 348.06475 | I12: =I8+I9+I10+I11 -> 417.95735 | J12: =J8+J9+J10+J11 -> 497.90921 | ... Q12: =Q8+Q9+Q10+Q11 -> 1309.1089
B14: LIABILITIES
B15: Accounts Payable | C15: {=Working_Capital!C11} -> -0.26023044 | D15: {=Working_Capital!D11} -> -0.31227653 | E15: {=Working_Capital!E11} -> -0.37160907 | F15: {=Working_Capital!F11} -> -0.43478261 | G15: {=Working_Capital!G11} -> -0.5 | H15: {=Working_Capital!H11} -> -0.59 | I15: {=Working_Capital!I11} -> -0.6844 | J15: {=Working_Capital!J11} -> -0.780216 | ... Q15: {=Working_Capital!Q11} -> -1.3475806
B16: Debt | C16: {=Debt_Schedule!C10} -> 50 | D16: {=Debt_Schedule!D10} -> 50 | E16: {=Debt_Schedule!E10} -> 50 | F16: {=Debt_Schedule!F10} -> 50 | G16: {=Debt_Schedule!G10} -> 50 | H16: {=Debt_Schedule!H10} -> 50 | I16: {=Debt_Schedule!I10} -> 50 | J16: {=Debt_Schedule!J10} -> 50 | ... Q16: {=Debt_Schedule!Q10} -> 50
B17: Total Liabilities | C17: =C15+C16 -> 49.73977 | D17: =D15+D16 -> 49.687723 | E17: =E15+E16 -> 49.628391 | F17: =F15+F16 -> 49.565217 | G17: =G15+G16 -> 49.5 | H17: =H15+H16 -> 49.41 | I17: =I15+I16 -> 49.3156 | J17: =J15+J16 -> 49.219784 | ... Q17: =Q15+Q16 -> 48.652419
B19: EQUITY
B20: Shareholders' Equity | C20: =C12-C17 -> 76.119587 | D20: =D12-D17 -> 107.03362 | E20: =E12-E17 -> 144.17757 | F20: =F12-F17 -> 187.95475 | G20: =G12-G17 -> 238.57975 | H20: =H12-H17 -> 298.65475 | I20: =I12-I17 -> 368.64175 | J20: =J12-J17 -> 448.68943 | ... Q20: =Q12-Q17 -> 1260.4565
B22: Balance Check (Assets - Liabilities - Equity) | C22: =C12-C17-C20 -> 0 | D22: =D12-D17-D20 -> 0 | E22: =E12-E17-E20 -> 0 | F22: =F12-F17-F20 -> 0 | G22: =G12-G17-G20 -> 0 | H22: =H12-H17-H20 -> 0 | I22: =I12-I17-I20 -> 0 | J22: =J12-J17-J20 -> 0 | ... Q22: =Q12-Q17-Q20 -> 0

Sheet Cash_Flow
B2: CASH FLOW STATEMENT (Indirect Method)
B3: ($ millions)
C5: 2020 | D5: 2021 | E5: 2022 | F5: 2023 | G5: 2024 | H5: 2025 | I5: 2026 | J5: 2027 | K5: 2028 | L5: 2029 | M5: 2030 | N5: 2031 | O5: 2032 | P5: 2033 | Q5: 2034
B7: OPERATING ACTIVITIES
B8: Net Income | C8: {=Income_Statement!C23} -> 25.449196 | D8: {=Income_Statement!D23} -> 30.914035 | E8: {=Income_Statement!E23} -> 37.143952 | F8: {=Income_Statement!F23} -> 43.777174 | G8: {=Income_Statement!G23} -> 50.625 | H8: {=Income_Statement!H23} -> 60.075 | I8: {=Income_Statement!I23} -> 69.987 | J8: {=Income_Statement!J23} -> 80.04768 | ... Q8: {=Income_Statement!Q23} -> 139.62096
B9: (+) Depreciation & Amortization | C9: {=Depreciation_Capex!C9} -> 2.6023044 | D9: {=Depreciation_Capex!D9} -> 3.1227653 | E9: {=Depreciation_Capex!E9} -> 3.7160907 | F9: {=Depreciation_Capex!F9} -> 4.3478261 | G9: {=Depreciation_Capex!G9} -> 5 | H9: {=Depreciation_Capex!H9} -> 5.9 | I9: {=Depreciation_Capex!I9} -> 6.844 | J9: {=Depreciation_Capex!J9} -> 7.80216 | ... Q9: {=Depreciation_Capex!Q9} -> 13.475806
B10: (-) Change in Net Working Capital | C10: {=Working_Capital!C16} -> 0 | D10: {=Working_Capital!D16} -> 0.26023044 | E10: {=Working_Capital!E16} -> 0.2966627 | F10: {=Working_Capital!F16} -> 0.31586771 | G10: {=Working_Capital!G16} -> 0.32608696 | H10: {=Working_Capital!H16} -> 0.45 | I10: {=Working_Capital!I16} -> 0.472 | J10: {=Working_Capital!J16} -> 0.47908 | ... Q10: {=Working_Capital!Q16} -> 0.32085253
B11: Cash from Operations | C11: =C8+C9-C10 -> 28.051501 | D11: =D8+D9-D10 -> 33.77657 | E11: =E8+E9-E10 -> 40.56338 | F11: =F8+F9-F10 -> 47.809132 | G11: =G8+G9-G10 -> 55.298913 | H11: =H8+H9-H10 -> 65.525 | I11: =I8+I9-I10 -> 76.359 | J11: =J8+J9-J10 -> 87.37076 | ... Q11: =Q8+Q9-Q10 -> 152.77592
B13: INVESTING ACTIVITIES
B14: (-) Capital Expenditures | C14: =-Depreciation_Capex!C8 -> -3.9034566 | D14: =-Depreciation_Capex!D8 -> -4.6841479 | E14: =-Depreciation_Capex!E8 -> -5.574136 | F14: =-Depreciation_Capex!F8 -> -6.5217391 | G14: =-Depreciation_Capex!G8 -> -7.5 | H14: =-Depreciation_Capex!H8 -> -8.85 | I14: =-Depreciation_Capex!I8 -> -10.266 | J14: =-Depreciation_Capex!J8 -> -11.70324 | ... Q14: =-Depreciation_Capex!Q8 -> -20.213709
B15: Cash from Investing | C15: {=C14} -> -3.9034566 | D15: {=D14} -> -4.6841479 | E15: {=E14} -> -5.574136 | F15: {=F14} -> -6.5217391 | G15: {=G14} -> -7.5 | H15: {=H14} -> -8.85 | I15: {=I14} -> -10.266 | J15: {=J14} -> -11.70324 | ... Q15: {=Q14} -> -20.213709
B17: FINANCING ACTIVITIES
B18: (+) Debt Issuance | C18: {=Debt_Schedule!C8} -> 0 | D18: {=Debt_Schedule!D8} -> 0 | E18: {=Debt_Schedule!E8} -> 0 | F18: {=Debt_Schedule!F8} -> 0 | G18: {=Debt_Schedule!G8} -> 0 | H18: {=Debt_Schedule!H8} -> 0 | I18: {=Debt_Schedule!I8} -> 0 | J18: {=Debt_Schedule!J8} -> 0 | ... Q18: {=Debt_Schedule!Q8} -> 0
B19: (-) Debt Repayment | C19: =-Debt_Schedule!C9 -> 0 | D19: =-Debt_Schedule!D9 -> 0 | E19: =-Debt_Schedule!E9 -> 0 | F19: =-Debt_Schedule!F9 -> 0 | G19: =-Debt_Schedule!G9 -> 0 | H19: =-Debt_Schedule!H9 -> 0 | I19: =-Debt_Schedule!I9 -> 0 | J19: =-Debt_Schedule!J9 -> 0 | ... Q19: =-Debt_Schedule!Q9 -> 0
B20: (-) Dividends | C20: 0 | D20: 0 | E20: 0 | F20: 0 | G20: 0 | H20: 0 | I20: 0 | J20: 0 | K20: 0 | L20: 0 | M20: 0 | N20: 0 | O20: 0 | P20: 0 | Q20: 0
B21: Cash from Financing | C21: =C18+C19+C20 -> 0 | D21: =D18+D19+D20 -> 0 | E21: =E18+E19+E20 -> 0 | F21: =F18+F19+F20 -> 0 | G21: =G18+G19+G20 -> 0 | H21: =H18+H19+H20 -> 0 | I21: =I18+I19+I20 -> 0 | J21: =J18+J19+J20 -> 0 | ... Q21: =Q18+Q19+Q20 -> 0
B23: Net Change in Cash | C23: =C11+C15+C21 -> 24.148044 | D23: =D11+D15+D21 -> 29.092422 | E23: =E11+E15+E21 -> 34.989244 | F23: =F11+F15+F21 -> 41.287393 | G23: =G11+G15+G21 -> 47.798913 | H23: =H11+H15+H21 -> 56.675 | I23: =I11+I15+I21 -> 66.093 | J23: =J11+J15+J21 -> 75.66752 | ... Q23: =Q11+Q15+Q21 -> 132.56221
B24: Cash, Beginning | C24: =C27-C23 -> 79.851956 | D24: {=C25} -> 104 | E24: {=D25} -> 133.09242 | F24: {=E25} -> 168.08167 | G24: {=F25} -> 209.36906 | H24: {=G25} -> 257.16797 | I24: {=H25} -> 313.84297 | J24: {=I25} -> 379.93597 | K24: {=J25} -> 455.60349 | ... Q24: {=P25} -> 1092.6909
B25: Cash, Ending | C25: =C24+C23 -> 104 | D25: =D24+D23 -> 133.09242 | E25: =E24+E23 -> 168.08167 | F25: =F24+F23 -> 209.36906 | G25: =G24+G23 -> 257.16797 | H25: =H24+H23 -> 313.84297 | I25: =I24+I23 -> 379.93597 | J25: =J24+J23 -> 455.60349 | ... Q25: =Q24+Q23 -> 1225.2532
B27: Check: Ending Cash from Balance Sheet | C27: {=Balance_Sheet!C8} -> 104 | D27: {=Balance_Sheet!D8} -> 133.09242 | E27: {=Balance_Sheet!E8} -> 168.08167 | F27: {=Balance_Sheet!F8} -> 209.36906 | G27: {=Balance_Sheet!G8} -> 257.16797 | H27: {=Balance_Sheet!H8} -> 313.84297 | I27: {=Balance_Sheet!I8} -> 379.93597 | J27: {=Balance_Sheet!J8} -> 455.60349 | ... Q27: {=Balance_Sheet!Q8} -> 1225.2532
B28: Cash Flow Check (CF - BS Change) | C28: =C25-C27 -> 0 | D28: =D25-D27 -> 0 | E28: =E25-E27 -> 0 | F28: =F25-F27 -> 0 | G28: =G25-G27 -> 0 | H28: =H25-H27 -> 0 | I28: =I25-I27 -> 0 | J28: =J25-J27 -> 0 | ... Q28: =Q25-Q27 -> 0

Sheet Working_Capital
B2: WORKING CAPITAL SCHEDULE
B3: ($ millions)
C5: 2020 | D5: 2021 | E5: 2022 | F5: 2023 | G5: 2024 | H5: 2025 | I5: 2026 | J5: 2027 | K5: 2028 | L5: 2029 | M5: 2030 | N5: 2031 | O5: 2032 | P5: 2033 | Q5: 2034
B7: Revenue (reference) | C7: {=Income_Statement!C7} -> 130.11522 | D7: {=Income_Statement!D7} -> 156.13826 | E7: {=Income_Statement!E7} -> 185.80453 | F7: {=Income_Statement!F7} -> 217.3913 | G7: {=Income_Statement!G7} -> 250 | H7: {=Income_Statement!H7} -> 295 | I7: {=Income_Statement!I7} -> 342.2 | J7: {=Income_Statement!J7} -> 390.108 | ... Q7: {=Income_Statement!Q7} -> 673.79031
B9: Accounts Receivable | C9: =C13*0.5 -> 0.6505761 | D9: =D13*0.5 -> 0.78069132 | E9: =E13*0.5 -> 0.92902267 | F9: =F13*0.5 -> 1.0869565 | G9: =G13*0.5 -> 1.25 | H9: =H13*0.5 -> 1.475 | I9: =I13*0.5 -> 1.711 | J9: =J13*0.5 -> 1.95054 | ... Q9: =Q13*0.5 -> 3.3689515
B10: Inventory | C10: =C13*0.3 -> 0.39034566 | D10: =D13*0.3 -> 0.46841479 | E10: =E13*0.3 -> 0.5574136 | F10: =F13*0.3 -> 0.65217391 | G10: =G13*0.3 -> 0.75 | H10: =H13*0.3 -> 0.885 | I10: =I13*0.3 -> 1.0266 | J10: =J13*0.3 -> 1.170324 | ... Q10: =Q13*0.3 -> 2.0213709
B11: Accounts Payable | C11: =-C13*0.2 -> -0.26023044 | D11: =-D13*0.2 -> -0.31227653 | E11: =-E13*0.2 -> -0.37160907 | F11: =-F13*0.2 -> -0.43478261 | G11: =-G13*0.2 -> -0.5 | H11: =-H13*0.2 -> -0.59 | I11: =-I13*0.2 -> -0.6844 | J11: =-J13*0.2 -> -0.780216 | ... Q11: =-Q13*0.2 -> -1.3475806
B13: Net Working Capital | C13: =C7*Cover_Assumptions!$C$18 -> 1.3011522 | D13: =D7*Cover_Assumptions!$C$18 -> 1.5613826 | E13: =E7*Cover_Assumptions!$C$18 -> 1.8580453 | F13: =F7*Cover_Assumptions!$C$18 -> 2.173913 | G13: =G7*Cover_Assumptions!$C$18 -> 2.5 | H13: =H7*Cover_Assumptions!$C$18 -> 2.95 | I13: =I7*Cover_Assumptions!$C$18 -> 3.422 | J13: =J7*Cover_Assumptions!$C$18 -> 3.90108 | ... Q13: =Q7*Cover_Assumptions!$C$18 -> 6.7379031
B14: NWC % of Revenue | C14: =C13/C7 -> 0.01 | D14: =D13/D7 -> 0.01 | E14: =E13/E7 -> 0.01 | F14: =F13/F7 -> 0.01 | G14: =G13/G7 -> 0.01 | H14: =H13/H7 -> 0.01 | I14: =I13/I7 -> 0.01 | J14: =J13/J7 -> 0.01 | ... Q14: =Q13/Q7 -> 0.01
B16: Change in NWC | C16: 0 | D16: =D13-C13 -> 0.26023044 | E16: =E13-D13 -> 0.2966627 | F16: =F13-E13 -> 0.31586771 | G16: =G13-F13 -> 0.32608696 | H16: =H13-G13 -> 0.45 | I16: =I13-H13 -> 0.472 | J16: =J13-I13 -> 0.47908 | K16: =K13-J13 -> 0.4681296 | ... Q16: =Q13-P13 -> 0.32085253

Sheet Depreciation_Capex
B2: DEPRECIATION & CAPEX SCHEDULE
B3: ($ millions)
C5: 2020 | D5: 2021 | E5: 2022 | F5: 2023 | G5: 2024 | H5: 2025 | I5: 2026 | J5: 2027 | K5: 2028 | L5: 2029 | M5: 2030 | N5: 2031 | O5: 2032 | P5: 2033 | Q5: 2034
B7: PP&E, Beginning | C7: =C8*5 -> 19.517283 | D7: {=C10} -> 20.818435 | E7: {=D10} -> 22.379818 | F7: {=E10} -> 24.237863 | G7: {=F10} -> 26.411776 | H7: {=G10} -> 28.911776 | I7: {=H10} -> 31.861776 | J7: {=I10} -> 35.283776 | K7: {=J10} -> 39.184856 | ... Q7: {=P10} -> 71.727527
B8: (+) Capex | C8: =C14*Cover_Assumptions!$C$17 -> 3.9034566 | D8: =D14*Cover_Assumptions!$C$17 -> 4.6841479 | E8: =E14*Cover_Assumptions!$C$17 -> 5.574136 | F8: =F14*Cover_Assumptions!$C$17 -> 6.5217391 | G8: =G14*Cover_Assumptions!$C$17 -> 7.5 | H8: =H14*Cover_Assumptions!$C$17 -> 8.85 | I8: =I14*Cover_Assumptions!$C$17 -> 10.266 | J8: =J14*Cover_Assumptions!$C$17 -> 11.70324 | ... Q8: =Q14*Cover_Assumptions!$C$17 -> 20.213709
B9: (-) Depreciation & Amortization | C9: =C14*Cover_Assumptions!$C$16 -> 2.6023044 | D9: =D14*Cover_Assumptions!$C$16 -> 3.1227653 | E9: =E14*Cover_Assumptions!$C$16 -> 3.7160907 | F9: =F14*Cover_Assumptions!$C$16 -> 4.3478261 | G9: =G14*Cover_Assumptions!$C$16 -> 5 | H9: =H14*Cover_Assumptions!$C$16 -> 5.9 | I9: =I14*Cover_Assumptions!$C$16 -> 6.844 | J9: =J14*Cover_Assumptions!$C$16 -> 7.80216 | ... Q9: =Q14*Cover_Assumptions!$C$16 -> 13.475806
B10: PP&E, Ending | C10: =C7+C8-C9 -> 20.818435 | D10: =D7+D8-D9 -> 22.379818 | E10: =E7+E8-E9 -> 24.237863 | F10: =F7+F8-F9 -> 26.411776 | G10: =G7+G8-G9 -> 28.911776 | H10: =H7+H8-H9 -> 31.861776 | I10: =I7+I8-I9 -> 35.283776 | J10: =J7+J8-J9 -> 39.184856 | ... Q10: =Q7+Q8-Q9 -> 78.46543
B12: Check: Beginning + Capex - D&A | C12: =C7+C8-C9 -> 20.818435 | D12: =D7+D8-D9 -> 22.379818 | E12: =E7+E8-E9 -> 24.237863 | F12: =F7+F8-F9 -> 26.411776 | G12: =G7+G8-G9 -> 28.911776 | H12: =H7+H8-H9 -> 31.861776 | I12: =I7+I8-I9 -> 35.283776 | J12: =J7+J8-J9 -> 39.184856 | ... Q12: =Q7+Q8-Q9 -> 78.46543
B14: Revenue (reference) | C14: {=Income_Statement!C7} -> 130.11522 | D14: {=Income_Statement!D7} -> 156.13826 | E14: {=Income_Statement!E7} -> 185.80453 | F14: {=Income_Statement!F7} -> 217.3913 | G14: {=Income_Statement!G7} -> 250 | H14: {=Income_Statement!H7} -> 295 | I14: {=Income_Statement!I7} -> 342.2 | J14: {=Income_Statement!J7} -> 390.108 | ... Q14: {=Income_Statement!Q7} -> 673.79031

Sheet Debt_Schedule
B2: DEBT SCHEDULE
B3: ($ millions)
C5: 2020 | D5: 2021 | E5: 2022 | F5: 2023 | G5: 2024 | H5: 2025 | I5: 2026 | J5: 2027 | K5: 2028 | L5: 2029 | M5: 2030 | N5: 2031 | O5: 2032 | P5: 2033 | Q5: 2034
B7: Debt, Beginning | C7: 50 | D7: {=C10} -> 50 | E7: {=D10} -> 50 | F7: {=E10} -> 50 | G7: {=F10} -> 50 | H7: {=G10} -> 50 | I7: {=H10} -> 50 | J7: {=I10} -> 50 | K7: {=J10} -> 50 | ... Q7: {=P10} -> 50
B8: (+) Debt Issuance | C8: 0 | D8: 0 | E8: 0 | F8: 0 | G8: 0 | H8: 0 | I8: 0 | J8: 0 | K8: 0 | L8: 0 | M8: 0 | N8: 0 | O8: 0 | P8: 0 | Q8: 0
B9: (-) Debt Repayment | C9: 0 | D9: 0 | E9: 0 | F9: 0 | G9: 0 | H9: 0 | I9: 0 | J9: 0 | K9: 0 | L9: 0 | M9: 0 | N9: 0 | O9: 0 | P9: 0 | Q9: 0
B10: Debt, Ending | C10: =C7+C8-C9 -> 50 | D10: =D7+D8-D9 -> 50 | E10: =E7+E8-E9 -> 50 | F10: =F7+F8-F9 -> 50 | G10: =G7+G8-G9 -> 50 | H10: =H7+H8-H9 -> 50 | I10: =I7+I8-I9 -> 50 | J10: =J7+J8-J9 -> 50 | ... Q10: =Q7+Q8-Q9 -> 50
B12: Average Debt Balance | C12: =(C7+C10)/2 -> 50 | D12: =(D7+D10)/2 -> 50 | E12: =(E7+E10)/2 -> 50 | F12: =(F7+F10)/2 -> 50 | G12: =(G7+G10)/2 -> 50 | H12: =(H7+H10)/2 -> 50 | I12: =(I7+I10)/2 -> 50 | J12: =(J7+J10)/2 -> 50 | ... Q12: =(Q7+Q10)/2 -> 50
B13: Interest Rate | C13: {=Cover_Assumptions!$C$33} -> 0.05 | D13: {=Cover_Assumptions!$C$33} -> 0.05 | E13: {=Cover_Assumptions!$C$33} -> 0.05 | F13: {=Cover_Assumptions!$C$33} -> 0.05 | G13: {=Cover_Assumptions!$C$33} -> 0.05 | H13: {=Cover_Assumptions!$C$33} -> 0.05 | I13: {=Cover_Assumptions!$C$33} -> 0.05 | J13: {=Cover_Assumptions!$C$33} -> 0.05 | ... Q13: {=Cover_Assumptions!$C$33} -> 0.05
B14: Interest Expense | C14: =C12*C13 -> 2.5 | D14: =D12*D13 -> 2.5 | E14: =E12*E13 -> 2.5 | F14: =F12*F13 -> 2.5 | G14: =G12*G13 -> 2.5 | H14: =H12*H13 -> 2.5 | I14: =I12*I13 -> 2.5 | J14: =J12*J13 -> 2.5 | ... Q14: =Q12*Q13 -> 2.5

Sheet Tax_Schedule
B2: TAX SCHEDULE
B3: ($ millions)
C5: 2020 | D5: 2021 | E5: 2022 | F5: 2023 | G5: 2024 | H5: 2025 | I5: 2026 | J5: 2027 | K5: 2028 | L5: 2029 | M5: 2030 | N5: 2031 | O5: 2032 | P5: 2033 | Q5: 2034
B7: EBT | C7: {=Income_Statement!C19} -> 33.932261 | D7: {=Income_Statement!D19} -> 41.218714 | E7: {=Income_Statement!E19} -> 49.525269 | F7: {=Income_Statement!F19} -> 58.369565 | G7: {=Income_Statement!G19} -> 67.5 | H7: {=Income_Statement!H19} -> 80.1 | I7: {=Income_Statement!I19} -> 93.316 | J7: {=Income_Statement!J19} -> 106.73024 | ... Q7: {=Income_Statement!Q19} -> 186.16129
B8: Tax Rate | C8: {=Cover_Assumptions!$C$32} -> 0.25 | D8: {=Cover_Assumptions!$C$32} -> 0.25 | E8: {=Cover_Assumptions!$C$32} -> 0.25 | F8: {=Cover_Assumptions!$C$32} -> 0.25 | G8: {=Cover_Assumptions!$C$32} -> 0.25 | H8: {=Cover_Assumptions!$C$32} -> 0.25 | I8: {=Cover_Assumptions!$C$32} -> 0.25 | J8: {=Cover_Assumptions!$C$32} -> 0.25 | ... Q8: {=Cover_Assumptions!$C$32} -> 0.25
B9: Tax Expense | C9: =IF(C7>0,C7*C8,0) -> 8.4830654 | D9: =IF(D7>0,D7*D8,0) -> 10.304678 | E9: =IF(E7>0,E7*E8,0) -> 12.381317 | F9: =IF(F7>0,F7*F8,0) -> 14.592391 | G9: =IF(G7>0,G7*G8,0) -> 16.875 | H9: =IF(H7>0,H7*H8,0) -> 20.025 | I9: =IF(I7>0,I7*I8,0) -> 23.329 | J9: =IF(J7>0,J7*J8,0) -> 26.68256 | ... Q9: =IF(Q7>0,Q7*Q8,0) -> 46.540322

Sheet FCFF
B2: FREE CASH FLOW TO FIRM (FCFF)
B3: ($ millions)
C5: 2025 | D5: 2026 | E5: 2027 | F5: 2028 | G5: 2029 | H5: 2030 | I5: 2031 | J5: 2032 | K5: 2033 | L5: 2034
B7: EBIT | C7: {=Income_Statement!H15} -> 82.6 | D7: {=Income_Statement!I15} -> 95.816 | E7: {=Income_Statement!J15} -> 109.23024 | F7: {=Income_Statement!K15} -> 122.33787 | G7: {=Income_Statement!L15} -> 134.57166 | H7: {=Income_Statement!M15} -> 146.6831 | I7: {=Income_Statement!N15} -> 158.41775 | J7: {=Income_Statement!O15} -> 169.507 | ... L7: {=Income_Statement!Q15} -> 188.66129
B8: Tax Rate | C8: {=Cover_Assumptions!$C$32} -> 0.25 | D8: {=Cover_Assumptions!$C$32} -> 0.25 | E8: {=Cover_Assumptions!$C$32} -> 0.25 | F8: {=Cover_Assumptions!$C$32} -> 0.25 | G8: {=Cover_Assumptions!$C$32} -> 0.25 | H8: {=Cover_Assumptions!$C$32} -> 0.25 | I8: {=Cover_Assumptions!$C$32} -> 0.25 | J8: {=Cover_Assumptions!$C$32} -> 0.25 | ... L8: {=Cover_Assumptions!$C$32} -> 0.25
B9: NOPAT (EBIT × (1 - Tax Rate)) | C9: =C7*(1-C8) -> 61.95 | D9: =D7*(1-D8) -> 71.862 | E9: =E7*(1-E8) -> 81.92268 | F9: =F7*(1-F8) -> 91.753402 | G9: =G7*(1-G8) -> 100.92874 | H9: =H7*(1-H8) -> 110.01233 | I9: =I7*(1-I8) -> 118.81331 | J9: =J7*(1-J8) -> 127.13025 | ... L9: =L7*(1-L8) -> 141.49596
B11: (+) Depreciation & Amortization | C11: {=Depreciation_Capex!H9} -> 5.9 | D11: {=Depreciation_Capex!I9} -> 6.844 | E11: {=Depreciation_Capex!J9} -> 7.80216 | F11: {=Depreciation_Capex!K9} -> 8.7384192 | G11: {=Depreciation_Capex!L9} -> 9.6122611 | H11: {=Depreciation_Capex!M9} -> 10.477365 | I11: {=Depreciation_Capex!N9} -> 11.315554 | J11: {=Depreciation_Capex!O9} -> 12.107643 | ... L11: {=Depreciation_Capex!Q9} -> 13.475806
B12: (-) Capital Expenditures | C12: {=Depreciation_Capex!H8} -> 8.85 | D12: {=Depreciation_Capex!I8} -> 10.266 | E12: {=Depreciation_Capex!J8} -> 11.70324 | F12: {=Depreciation_Capex!K8} -> 13.107629 | G12: {=Depreciation_Capex!L8} -> 14.418392 | H12: {=Depreciation_Capex!M8} -> 15.716047 | I12: {=Depreciation_Capex!N8} -> 16.973331 | J12: {=Depreciation_Capex!O8} -> 18.161464 | ... L12: {=Depreciation_Capex!Q8} -> 20.213709
B13: (-) Change in NWC | C13: {=Working_Capital!H16} -> 0.45 | D13: {=Working_Capital!I16} -> 0.472 | E13: {=Working_Capital!J16} -> 0.47908 | F13: {=Working_Capital!K16} -> 0.4681296 | G13: {=Working_Capital!L16} -> 0.43692096 | H13: {=Working_Capital!M16} -> 0.43255175 | I13: {=Working_Capital!N16} -> 0.41909458 | J13: {=Working_Capital!O16} -> 0.39604438 | ... L13: {=Working_Capital!Q16} -> 0.32085253
B15: Unlevered Free Cash Flow | C15: =C9+C11-C12-C13 -> 58.55 | D15: =D9+D11-D12-D13 -> 67.968 | E15: =E9+E11-E12-E13 -> 77.54252 | F15: =F9+F11-F12-F13 -> 86.916062 | G15: =G9+G11-G12-G13 -> 95.68569 | H15: =H9+H11-H12-H13 -> 104.34109 | I15: =I9+I11-I12-I13 -> 112.73644 | J15: =J9+J11-J12-J13 -> 120.68038 | ... L15: =L9+L11-L12-L13 -> 134.43721
B17: Discount Period | C17: 1 | D17: 2 | E17: 3 | F17: 4 | G17: 5 | H17: 6 | I17: 7 | J17: 8 | K17: 9 | L17: 10
B18: WACC (from WACC_Valuation) | C18: {=WACC_Valuation!$C$28} -> 0.12340909 | D18: {=WACC_Valuation!$C$28} -> 0.12340909 | E18: {=WACC_Valuation!$C$28} -> 0.12340909 | F18: {=WACC_Valuation!$C$28} -> 0.12340909 | G18: {=WACC_Valuation!$C$28} -> 0.12340909 | H18: {=WACC_Valuation!$C$28} -> 0.12340909 | I18: {=WACC_Valuation!$C$28} -> 0.12340909 | J18: {=WACC_Valuation!$C$28} -> 0.12340909 | ... L18: {=WACC_Valuation!$C$28} -> 0.12340909
B19: Discount Factor | C19: =1/(1+C18)^C17 -> 0.89014768 | D19: =1/(1+D18)^D17 -> 0.7923629 | E19: =1/(1+E18)^E17 -> 0.70532 | F19: =1/(1+F18)^F17 -> 0.62783896 | G19: =1/(1+G18)^G17 -> 0.5588694 | H19: =1/(1+H18)^H17 -> 0.4974763 | I19: =1/(1+I18)^I17 -> 0.44282738 | J19: =1/(1+J18)^J17 -> 0.39418176 | ... L19: =1/(1+L18)^L17 -> 0.312335
B20: Present Value of FCF | C20: =C15*C19 -> 52.118147 | D20: =D15*D19 -> 53.855321 | E20: =E15*E19 -> 54.69229 | F20: =F15*F19 -> 54.56929 | G20: =G15*G19 -> 53.475804 | H20: =H15*H19 -> 51.907222 | I20: =I15*I19 -> 49.922783 | J20: =J15*J19 -> 47.570005 | ... L20: =L15*L19 -> 41.989446

Sheet WACC_Valuation
B2: WACC & VALUATION
B4: COST OF EQUITY (CAPM)
B5: Risk-Free Rate | C5: {=Cover_Assumptions!C21} -> 0.04
B6: Beta | C6: {=Cover_Assumptions!C22} -> 1.2
B7: Market Return | C7: {=Cover_Assumptions!C23} -> 0.1
B8: Market Risk Premium | C8: =C7-C5 -> 0.06
B9: Size Premium | C9: {=Cover_Assumptions!C24} -> 0.02
B10: Country Risk Premium | C10: {=Cover_Assumptions!C25} -> 0 | E10: WACC (for FCFF reference) | F10: {=C28} -> 0.12340909
B11: Cost of Equity | C11: =C5+C6*C8+C9+C10 -> 0.132
B13: COST OF DEBT
B14: Interest Expense (2024) | C14: {=Debt_Schedule!G14} -> 2.5
B15: Average Debt (2024) | C15: {=Debt_Schedule!G12} -> 50
B16: Pre-tax Cost of Debt | C16: =IF(C15>0,C14/C15,0) -> 0.05
B17: Tax Rate | C17: {=Cover_Assumptions!C32} -> 0.25
B18: After-tax Cost of Debt | C18: =C16*(1-C17) -> 0.0375
B20: CAPITAL STRUCTURE
B21: Market Value of Equity (assumed) | C21: 500
B22: Market Value of Debt | C22: {=Debt_Schedule!G10} -> 50
B23: Total Capital (Enterprise Value) | C23: =C21+C22 -> 550
B24: Weight of Equity (E/V) | C24: =C21/C23 -> 0.90909091
B25: Weight of Debt (D/V) | C25: =C22/C23 -> 0.090909091
B27: WEIGHTED AVERAGE COST OF CAPITAL
B28: WACC | C28: =C11*C24+C18*C25 -> 0.12340909
B30: VALUATION
B31: Sum of PV of FCF (2025-2034) | C31: =SUM(FCFF!C20:L20) -> 505.00515
B33: TERMINAL VALUE - GORDON GROWTH
B34: Terminal Year FCF (2034) | C34: {=FCFF!L15} -> 134.43721
B35: Terminal Growth Rate | C35: {=Cover_Assumptions!C28} -> 0.025
B36: WACC | C36: {=C28} -> 0.12340909
B37: Terminal Value (Gordon Growth) | C37: =C34*(1+C35)/(C36-C35) -> 1400.2582
B38: PV of Terminal Value | C38: =C37/(1+C36)^10 -> 437.34966
B40: TERMINAL VALUE - EXIT MULTIPLE
B41: Terminal Year EBITDA (2034) | C41: {=Income_Statement!Q10} -> 202.13709
B42: Exit EBITDA Multiple | C42: {=Cover_Assumptions!C29} -> 15
B43: Terminal Value (Exit Multiple) | C43: =C41*C42 -> 3032.0564
B44: PV of Terminal Value | C44: =C43/(1+C36)^10 -> 947.01735
B46: ENTERPRISE VALUE (Gordon Growth) | C46: =C31+C38 -> 942.35481
B47: Less: Net Debt (2024) | C47: =Debt_Schedule!G10-Balance_Sheet!G8 -> -207.16797
B48: Equity Value | C48: =C46-C47 -> 1149.5228
B49: Shares Outstanding (mm) | C49: {=Cover_Assumptions!C34} -> 50
...

Sheet Sensitivity
B2: SENSITIVITY ANALYSIS
B4: EQUITY VALUE PER SHARE: WACC vs Terminal Growth Rate
D5: 1.5% | E5: 2.0% | F5: 2.5% | G5: 3.0% | H5: 3.5%
C6: {=WACC_Valuation!C50} -> 22.990456
C7: 6.0% | D7: =($C$21+$C$22*(1+D$5)/(C7-D$5)/(1+C7)^10-$C$23)/$C$24 -> 48.107938 | E7: =($C$21+$C$22*(1+E$5)/(C7-E$5)/(1+C7)^10-$C$23)/$C$24 -> 52.528671 | F7: =($C$21+$C$22*(1+F$5)/(C7-F$5)/(1+C7)^10-$C$23)/$C$24 -> 58.212469 | G7: =($C$21+$C$22*(1+G$5)/(C7-G$5)/(1+C7)^10-$C$23)/$C$24 -> 65.790867 | H7: =($C$21+$C$22*(1+H$5)/(C7-H$5)/(1+C7)^10-$C$23)/$C$24 -> 76.400624
C8: 7.0% | D8: =($C$21+$C$22*(1+D$5)/(C8-D$5)/(1+C8)^10-$C$23)/$C$24 -> 39.467526 | E8: =($C$21+$C$22*(1+E$5)/(C8-E$5)/(1+C8)^10-$C$23)/$C$24 -> 42.126615 | F8: =($C$21+$C$22*(1+F$5)/(C8-F$5)/(1+C8)^10-$C$23)/$C$24 -> 45.376612 | G8: =($C$21+$C$22*(1+G$5)/(C8-G$5)/(1+C8)^10-$C$23)/$C$24 -> 49.439108 | H8: =($C$21+$C$22*(1+H$5)/(C8-H$5)/(1+C8)^10-$C$23)/$C$24 -> 54.662318
C9: 8.0% | D9: =($C$21+$C$22*(1+D$5)/(C9-D$5)/(1+C9)^10-$C$23)/$C$24 -> 33.691 | E9: =($C$21+$C$22*(1+E$5)/(C9-E$5)/(1+C9)^10-$C$23)/$C$24 -> 35.415412 | F9: =($C$21+$C$22*(1+F$5)/(C9-F$5)/(1+C9)^10-$C$23)/$C$24 -> 37.453354 | G9: =($C$21+$C$22*(1+G$5)/(C9-G$5)/(1+C9)^10-$C$23)/$C$24 -> 39.898884 | H9: =($C$21+$C$22*(1+H$5)/(C9-H$5)/(1+C9)^10-$C$23)/$C$24 -> 42.887865
C10: 9.0% | D10: =($C$21+$C$22*(1+D$5)/(C10-D$5)/(1+C10)^10-$C$23)/$C$24 -> 29.614008 | E10: =($C$21+$C$22*(1+E$5)/(C10-E$5)/(1+C10)^10-$C$23)/$C$24 -> 30.79303 | F10: =($C$21+$C$22*(1+F$5)/(C10-F$5)/(1+C10)^10-$C$23)/$C$24 -> 32.153439 | G10: =($C$21+$C$22*(1+G$5)/(C10-G$5)/(1+C10)^10-$C$23)/$C$24 -> 33.740583 | H10: =($C$21+$C$22*(1+H$5)/(C10-H$5)/(1+C10)^10-$C$23)/$C$24 -> 35.616299
C11: 10.0% | D11: =($C$21+$C$22*(1+D$5)/(C11-D$5)/(1+C11)^10-$C$23)/$C$24 -> 26.622012 | E11: =($C$21+$C$22*(1+E$5)/(C11-E$5)/(1+C11)^10-$C$23)/$C$24 -> 27.46046 | F11: =($C$21+$C$22*(1+F$5)/(C11-F$5)/(1+C11)^10-$C$23)/$C$24 -> 28.410702 | G11: =($C$21+$C$22*(1+G$5)/(C11-G$5)/(1+C11)^10-$C$23)/$C$24 -> 29.496692 | H11: =($C$21+$C$22*(1+H$5)/(C11-H$5)/(1+C11)^10-$C$23)/$C$24 -> 30.749758
C12: 11.0% | D12: =($C$21+$C$22*(1+D$5)/(C12-D$5)/(1+C12)^10-$C$23)/$C$24 -> 24.360704 | E12: =($C$21+$C$22*(1+E$5)/(C12-E$5)/(1+C12)^10-$C$23)/$C$24 -> 24.975381 | F12: =($C$21+$C$22*(1+F$5)/(C12-F$5)/(1+C12)^10-$C$23)/$C$24 -> 25.662372 | G12: =($C$21+$C$22*(1+G$5)/(C12-G$5)/(1+C12)^10-$C$23)/$C$24 -> 26.435237 | H12: =($C$21+$C$22*(1+H$5)/(C12-H$5)/(1+C12)^10-$C$23)/$C$24 -> 27.311151
C13: 12.0% | D13: =($C$21+$C$22*(1+D$5)/(C13-D$5)/(1+C13)^10-$C$23)/$C$24 -> 22.611931 | E13: =($C$21+$C$22*(1+E$5)/(C13-E$5)/(1+C13)^10-$C$23)/$C$24 -> 23.07364 | F13: =($C$21+$C$22*(1+F$5)/(C13-F$5)/(1+C13)^10-$C$23)/$C$24 -> 23.583949 | G13: =($C$21+$C$22*(1+G$5)/(C13-G$5)/(1+C13)^10-$C$23)/$C$24 -> 24.15096 | H13: =($C$21+$C$22*(1+H$5)/(C13-H$5)/(1+C13)^10-$C$23)/$C$24 -> 24.784678
B15: Sensitivity Inputs:
B16: WACC Input | C16: {=WACC_Valuation!C28} -> 0.12340909
B17: Terminal Growth Input | C17: {=Cover_Assumptions!C28} -> 0.025
B20: Helper Calculations:
B21: Sum PV FCF | C21: {=WACC_Valuation!C31} -> 505.00515
B22: Terminal FCF | C22: {=WACC_Valuation!C34} -> 134.43721
B23: Net Debt | C23: {=WACC_Valuation!C47} -> -207.16797
B24: Shares Outstanding | C24: {=WACC_Valuation!C49} -> 50
B26: EQUITY VALUE PER SHARE: WACC vs Exit EBITDA Multiple
D27: 12 | E27: 13 | F27: 14 | G27: 15 | H27: 16 | I27: 17 | J27: 18
C28: {=WACC_Valuation!C56} -> 33.183809
C29: 6.0% | D29: =($C$21+$C$37*D$27/(1+C29)^10-$C$23)/$C$24 -> 41.332814 | E29: =($C$21+$C$37*E$27/(1+C29)^10-$C$23)/$C$24 -> 43.59026 | F29: =($C$21+$C$37*F$27/(1+C29)^10-$C$23)/$C$24 -> 45.847706 | G29: =($C$21+$C$37*G$27/(1+C29)^10-$C$23)/$C$24 -> 48.105151 | H29: =($C$21+$C$37*H$27/(1+C29)^10-$C$23)/$C$24 -> 50.362597 | I29: =($C$21+$C$37*I$27/(1+C29)^10-$C$23)/$C$24 -> 52.620043 | J29: =($C$21+$C$37*J$27/(1+C29)^10-$C$23)/$C$24 -> 54.877489
C30: 7.0% | D30: =($C$21+$C$37*D$27/(1+C30)^10-$C$23)/$C$24 -> 38.904962 | E30: =($C$21+$C$37*E$27/(1+C30)^10-$C$23)/$C$24 -> 40.960087 | F30: =($C$21+$C$37*F$27/(1+C30)^10-$C$23)/$C$24 -> 43.015212 | G30: =($C$21+$C$37*G$27/(1+C30)^10-$C$23)/$C$24 -> 45.070337 | H30: =($C$21+$C$37*H$27/(1+C30)^10-$C$23)/$C$24 -> 47.125462 | I30: =($C$21+$C$37*I$27/(1+C30)^10-$C$23)/$C$24 -> 49.180587 | J30: =($C$21+$C$37*J$27/(1+C30)^10-$C$23)/$C$24 -> 51.235712
C31: 8.0% | D31: =($C$21+$C$37*D$27/(1+C31)^10-$C$23)/$C$24 -> 36.714323 | E31: =($C$21+$C$37*E$27/(1+C31)^10-$C$23)/$C$24 -> 38.586895 | F31: =($C$21+$C$37*F$27/(1+C31)^10-$C$23)/$C$24 -> 40.459466 | G31: =($C$21+$C$37*G$27/(1+C31)^10-$C$23)/$C$24 -> 42.332038 | H31: =($C$21+$C$37*H$27/(1+C31)^10-$C$23)/$C$24 -> 44.20461 | I31: =($C$21+$C$37*I$27/(1+C31)^10-$C$23)/$C$24 -> 46.077181 | J31: =($C$21+$C$37*J$27/(1+C31)^10-$C$23)/$C$24 -> 47.949753
C32: 9.0% | D32: =($C$21+$C$37*D$27/(1+C32)^10-$C$23)/$C$24 -> 34.735837 | E32: =($C$21+$C$37*E$27/(1+C32)^10-$C$23)/$C$24 -> 36.443534 | F32: =($C$21+$C$37*F$27/(1+C32)^10-$C$23)/$C$24 -> 38.151232 | G32: =($C$21+$C$37*G$27/(1+C32)^10-$C$23)/$C$24 -> 39.85893 | H32: =($C$21+$C$37*H$27/(1+C32)^10-$C$23)/$C$24 -> 41.566628 | I32: =($C$21+$C$37*I$27/(1+C32)^10-$C$23)/$C$24 -> 43.274326 | J32: =($C$21+$C$37*J$27/(1+C32)^10-$C$23)/$C$24 -> 44.982024
C33: 10.0% | D33: =($C$21+$C$37*D$27/(1+C33)^10-$C$23)/$C$24 -> 32.947286 | E33: =($C$21+$C$37*E$27/(1+C33)^10-$C$23)/$C$24 -> 34.505938 | F33: =($C$21+$C$37*F$27/(1+C33)^10-$C$23)/$C$24 -> 36.06459 | G33: =($C$21+$C$37*G$27/(1+C33)^10-$C$23)/$C$24 -> 37.623242 | H33: =($C$21+$C$37*H$27/(1+C33)^10-$C$23)/$C$24 -> 39.181894 | I33: =($C$21+$C$37*I$27/(1+C33)^10-$C$23)/$C$24 -> 40.740546 | J33: =($C$21+$C$37*J$27/(1+C33)^10-$C$23)/$C$24 -> 42.299198
C34: 11.0% | D34: =($C$21+$C$37*D$27/(1+C34)^10-$C$23)/$C$24 -> 31.328954 | E34: =($C$21+$C$37*E$27/(1+C34)^10-$C$23)/$C$24 -> 32.752745 | F34: =($C$21+$C$37*F$27/(1+C34)^10-$C$23)/$C$24 -> 34.176536 | G34: =($C$21+$C$37*G$27/(1+C34)^10-$C$23)/$C$24 -> 35.600326 | H34: =($C$21+$C$37*H$27/(1+C34)^10-$C$23)/$C$24 -> 37.024117 | I34: =($C$21+$C$37*I$27/(1+C34)^10-$C$23)/$C$24 -> 38.447908 | J34: =($C$21+$C$37*J$27/(1+C34)^10-$C$23)/$C$24 -> 39.871699
C35: 12.0% | D35: =($C$21+$C$37*D$27/(1+C35)^10-$C$23)/$C$24 -> 29.863319 | E35: =($C$21+$C$37*E$27/(1+C35)^10-$C$23)/$C$24 -> 31.164973 | F35: =($C$21+$C$37*F$27/(1+C35)^10-$C$23)/$C$24 -> 32.466628 | G35: =($C$21+$C$37*G$27/(1+C35)^10-$C$23)/$C$24 -> 33.768283 | H35: =($C$21+$C$37*H$27/(1+C35)^10-$C$23)/$C$24 -> 35.069937 | I35: =($C$21+$C$37*I$27/(1+C35)^10-$C$23)/$C$24 -> 36.371592 | J35: =($C$21+$C$37*J$27/(1+C35)^10-$C$23)/$C$24 -> 37.673247
B37: Terminal EBITDA | C37: {=WACC_Valuation!C41} -> 202.13709

Sheet Audit_Checks
B2: AUDIT CHECKS
B3: All checks should equal 0 for model to pass
B5: CHECK 1: BALANCE SHEET
B6: Balance Check (2020) | C6: {=Balance_Sheet!C22} -> 0 | D6: =IF(ABS(C6)<0.1,"PASS","FAIL") -> PASS
B7: Balance Check (2024) | C7: {=Balance_Sheet!G22} -> 0 | D7: =IF(ABS(C7)<0.1,"PASS","FAIL") -> PASS
B8: Balance Check (2034) | C8: {=Balance_Sheet!Q22} -> 0 | D8: =IF(ABS(C8)<0.1,"PASS","FAIL") -> PASS
B10: CHECK 2: CASH FLOW STATEMENT
B11: CF Check (2020) | C11: {=Cash_Flow!C28} -> 0 | D11: =IF(ABS(C11)<0.1,"PASS","FAIL") -> PASS
B12: CF Check (2024) | C12: {=Cash_Flow!G28} -> 0 | D12: =IF(ABS(C12)<0.1,"PASS","FAIL") -> PASS
B13: CF Check (2034) | C13: {=Cash_Flow!Q28} -> 0 | D13: =IF(ABS(C13)<0.1,"PASS","FAIL") -> PASS
B15: CHECK 3: PP&E ROLL-FORWARD
B16: PP&E Check (2024) | C16: =Depreciation_Capex!G12-Depreciation_Capex!G10 -> 0 | D16: =IF(ABS(C16)<0.1,"PASS","FAIL") -> PASS
B17: PP&E Check (2034) | C17: =Depreciation_Capex!Q12-Depreciation_Capex!Q10 -> 0 | D17: =IF(ABS(C17)<0.1,"PASS","FAIL") -> PASS
B19: CHECK 4: EBITDA MARGIN
B20: EBITDA Margin vs Assumption (2024) | C20: =Income_Statement!G11-Cover_Assumptions!C15 -> 0 | D20: =IF(ABS(C20)<0.001,"PASS","FAIL") -> PASS
B21: EBITDA Margin vs Assumption (2034) | C21: =Income_Statement!Q11-Cover_Assumptions!C15 -> 0 | D21: =IF(ABS(C21)<0.001,"PASS","FAIL") -> PASS
B24: ERROR SUMMARY DASHBOARD
B25: Total Errors | C25: =COUNTIF(D6:D21,"FAIL") -> 0 | D25: =IF(C25=0,"✓ MODEL PASS","✗ MODEL FAIL") -> ✓ MODEL PASS
B27: Individual Check Results:
B28: Balance Sheet Checks | C28: =COUNTIF(D6:D8,"FAIL") -> 0
B29: Cash Flow Checks | C29: =COUNTIF(D11:D13,"FAIL") -> 0
B30: PP&E Roll-forward Checks | C30: =COUNTIF(D16:D17,"FAIL") -> 0
B31: EBITDA Margin Checks | C31: =COUNTIF(D20:D21,"FAIL") -> 0
